Workbook
Name Week1Start: 대시보드!$C$8
Name AsOf: 대시보드!$C$7

Sheet 대시보드
B2: Signal Guard 계획·진행 대시보드
B3: 출처: 백로그WBS.md v1.0 · 분석 10인일 완료 · 구현 Must 96SP = 6주 × 16SP
B5: 프로젝트 | C5: 실시간 교통신호 상태정보 오류검지 시스템 | F5: S6 Must 잔여 ≈ 29SP (용량 16을 초과). 1순위: MON-02, CTL-05, CTL-01, CTL-02, CTL-03 3순위 커트: RPT-02, ADM-02, CTL-04, PLN-02
B6: 팀 | C6: 조찬희 (기획·FE·PM) / 기경현 (BE·데이터)
B7: 기준일 | C7: 46277
B8: 1주차 시작일 | C8: 46266 | F8: 노란 칸만 수정 → 현재 주차·간트 날짜가 따라갑니다.
B9: 현재 주차 | C9: =MAX(1,MIN(15,INT((C7-C8)/7)+1))
B10: 현재 단계 | C10: =IF(C9<=3,"분석 (S0)",IF(C9<=5,"설계 (S-D1/D2)",IF(C9<=11,"구현 (S1–S6)",IF(C9<=13,"테스트 (S-T)","안정화 (S-R)"))))
B12: 핵심 지표 (수식 · WBS/백로그와 연동)
C13: 전체 인일 진척 | D13: 분석 | E13: 설계 | F13: 구현(제외 제외) | G13: 테스트 | H13: 인도 | I13: Must SP | J13: Must 완료
B14: 진척 | C14: =집계!C20 | D14: =집계!D10 | E14: =집계!D11 | F14: =집계!D12 | G14: =집계!D13 | H14: =집계!D14 | I14: =집계!C16 | J14: =TEXT(집계!B16,"0")&" / "&TEXT(집계!A16,"0")&" SP"
C15: =TEXT(집계!B20,"0.0")&" / "&TEXT(집계!A20,"0.0")&"인일" | D15: =TEXT(집계!C10,"0.0")&"/"&TEXT(집계!B10,"0.0") | E15: =TEXT(집계!C11,"0.0")&"/"&TEXT(집계!B11,"0.0") | F15: =TEXT(집계!C12,"0.0")&"/"&TEXT(집계!B12,"0.0") | G15: =TEXT(집계!C13,"0.0")&"/"&TEXT(집계!B13,"0.0") | H15: =TEXT(집계!C14,"0.0")&"/"&TEXT(집계!B14,"0.0") | I15: Must 완료율 | J15: 완료 SP / 계획 SP
B17: 단계별 인일 (계획 vs 획득) | G17: 구현 스프린트 Must SP
B19: 이번 주 초점
B20: =IF(C9<=3,"분석 산출물은 완료(M1)입니다. 남은 분석 주가 있으면 미결 목록만 정리하고, 주 4 설계 게이트(스택·표본 수·계획 대체·임계 기본값) 안건을 미리 적으세요.",IF(C9=4,"S-D1: 스택·화면 IA 6개·ERD 초안. 조찬희=와이어, 기경현=아키텍처·용량.",IF(C9=5,"S-D2 게이트: API·규칙 R01–R12·프로토타입 3화면. 미결 1~7을 닫아야 S1을 시작합니다.",IF(C9=6,"S1 데모: 관리자/운영자 로그인, 운영자는 설정 메뉴 없음. EN 기반+US-ADM-01.",IF(C9=7,"S2 데모: 인천 표본 상태가 쌓이고 쿼터 숫자가 보이며 원본이 별도 저장된다.",IF(C9=8,"S3 데모: 시드 계획이 붙은 교차로에서 엔진이 등급을 남긴다.",IF(C9=9,"S4 데모: 급변·중복·계획 불일치가 이슈/보정으로 갈리고 원본은 그대로다.",IF(C9=10,"S5 데모: 대시보드에 오류 수·자동보정·미처리 이슈, 목록에서 ACK.",IF(C9=11,"S6 통합+커트. 시연 Must(상세·정보/계획 통제·현장 요청·원본 병기)를 남기고 금요일 기능 동결.",IF(C9=12,"S-T1: 테스트 계획·규칙 단위·API 권한·원본 불변·E2E 착수.",IF(C9=13,"S-T2: 성능 3초·보안 점검·치명/주요 0. M6 게이트.",IF(C9=14,"S-R1: 잔여 결함, 매뉴얼, 설치 가이드. 신규 Must 없음.","S-R2: 시연 대본 5.1~5.4, 발표, 재설치 검증. M7 인도."))))))))))))
B24: 마일스톤
B25: ID | C25: 주 | D25: 이름 | E25: 통과 조건 | F25: 상태 | G25: 실적일 | I25: 용량 메모 · 분석 12 / 설계 8 / 구현 36 / 테스트 8 / 안정화 8 ≈ 72인일 · 구현 속도 16 SP/주 × 6주 = 96 SP (Must와 동일) · S5는 17SP(1점 초과) → ISS 화면 축소 · S6는 29SP → 통합+커트. 시연 Must 5개는 남김 · US-PLN-02는 승인 전 커밋하지 않음
B26: =마일스톤!A2 | C26: =마일스톤!B2 | D26: =마일스톤!C2 | E26: =마일스톤!D2 | G26: =마일스톤!E2 | H26: =마일스톤!F2
B27: =마일스톤!A3 | C27: =마일스톤!B3 | D27: =마일스톤!C3 | E27: =마일스톤!D3 | G27: =마일스톤!E3 | H27: =마일스톤!F3
B28: =마일스톤!A4 | C28: =마일스톤!B4 | D28: =마일스톤!C4 | E28: =마일스톤!D4 | G28: =마일스톤!E4 | H28: =마일스톤!F4
B29: =마일스톤!A5 | C29: =마일스톤!B5 | D29: =마일스톤!C5 | E29: =마일스톤!D5 | G29: =마일스톤!E5 | H29: =마일스톤!F5
B30: =마일스톤!A6 | C30: =마일스톤!B6 | D30: =마일스톤!C6 | E30: =마일스톤!D6 | G30: =마일스톤!E6 | H30: =마일스톤!F6
B31: =마일스톤!A7 | C31: =마일스톤!B7 | D31: =마일스톤!C7 | E31: =마일스톤!D7 | G31: =마일스톤!E7 | H31: =마일스톤!F7
B32: =마일스톤!A8 | C32: =마일스톤!B8 | D32: =마일스톤!C8 | E32: =마일스톤!D8 | G32: =마일스톤!E8 | H32: =마일스톤!F8
B34: 역할별 구현 주 부하 (백로그 주 담당 기준, Must+EN)
B45: 차트 출처: 집계 시트 (WBS 인일 · 제품백로그 SP). 완료로 바꾸면 주황/획득 막대가 올라갑니다. 가로 점선 용량 16SP는 S2–S6 기준.
B46: 주간 갱신 체크
B47: □ | C47: WBS에서 이번 주 패키지 상태를 진행중/완료로 바꾼다
B48: □ | C48: 제품백로그에서 닫은 US/EN을 완료로 바꾸고 진행률 100%를 넣는다
B49: □ | C49: 스프린트 시트의 실제완료SP와 상태를 맞춘다
B50: □ | C50: 마일스톤 게이트를 통과했으면 상태와 실적일을 적는다
B51: □ | C51: 위험 시트에 UTIC 승인·쿼터 소진을 한 줄 갱신한다
B52: □ | C52: 대시보드 현재 주차·진척률이 직관과 맞는지 확인한다

Sheet 사용안내
B2: Signal Guard 계획·진행 표
B3: 실시간 교통신호 상태정보 오류검지 시스템 · 15주 수업 MVP
B5: 근거 | C5: 백로그WBS.md v1.0 (2026-09-12), 프로젝트정의서 12장
B6: 작성 | C6: 조찬희 (기획·FE·PM), 기경현 (BE·데이터)
B7: 기준일 | C7: 2026-09-12 — 분석 산출물 완료(M1). 설계(주 4) 미착수
B8: 쓰는 법 | C8: 매주 리뷰에서 WBS·백로그의 상태/진행률만 고치면 대시보드·간트가 수식으로 갱신됩니다.
B10: 시트 구성
B11: 시트 | C11: 역할
B12: 대시보드 | C12: 전체 진척·단계별 인일·Must SP·마일스톤. 숫자 칸은 수식이므로 직접 고치지 마세요.
B13: 주차별계획 | C13: 15주 간트. 상태 열만 고치면 막대 색이 바뀝니다. 1주차 시작일은 대시보드 C8에서 바꿉니다.
B14: WBS | C14: 작업 패키지 단위 진행. 주간 리뷰의 주 입력 시트입니다.
B15: 제품백로그 | C15: EN + US 33건. Must 96SP가 용량(6주×16)과 같습니다.
B16: 스프린트 | C16: S0 ~ S-R2 목표·담당·완료 시 데모·커밋 목록.
B17: 마일스톤 | C17: M1–M7 게이트. M1은 분석 산출물 완료로 표시했습니다.
B18: 위험 | C18: UTIC·쿼터·S6 용량 등 버퍼와 완화.
B19: 집계 | C19: 차트·대시보드용 피벗. 편집하지 마세요.
B22: 상태 값 (드롭다운)
B23: 상태 | C23: 의미
B24: 완료 | C24: 수용 기준·산출물이 DoD를 만족. FE+BE 스토리는 둘 다 Done.
B25: 진행중 | C25: 이번 스프린트에서 작업 중. 진행률(0~100%)을 같이 적습니다.
B26: 대기 | C26: 아직 스프린트에 넣지 않았거나 선행이 안 끝남.
B27: 보류 | C27: Should/조건부. 승인·여유 주가 생기면 대기→진행중으로 바꿉니다.
B28: 제외 | C28: Could 또는 커트. 대시보드 분모에서 빠집니다. 결함이 아닙니다.
B31: 용량이 넘칠 때 자르는 순서 (위일수록 시연에 덜 치명적)
B32: 1. US-MON-05, US-MON-04 (선택 — 이미 백로그 밖 취급 가능)
B33: 2. US-PLN-02 (UTIC 승인 없으면 자동 제외)
B34: 3. US-CTL-04 감시 제외
B35: 4. US-ADM-02 계정 CRUD (시드 계정 2개로 시연 가능)
B36: 5. US-RPT-02 CSV (화면 조회만으로 발표 가능)
B37: 6. US-PLN-04 ID 매핑 (시드에서 미리 매핑하면 대조 가능)
B39: 자르지 않는 것: 수집, 시드 계획, 규칙 엔진, 자동보정/이슈 분기, 대시보드, 이슈 생명주기, 정보·계획 통제, 현장 요청 기록, 원본 불변, 로그인 RBAC, 쿼터.
B42: DoD 요약: 수용 기준 확인, FE는 API 연동, 권한 일치, 원본 수신을 덮어쓰는 경로 없음, PR 리뷰 1회 이상 메인 병합, 시크릿 없음. 분석·설계는 산출물이 저장소에 있고 팀 리뷰를 통과하면 Done.

Sheet 주차별계획
A1: 구분 | B1: 항목 | C1: 담당 | D1: 시작주 | E1: 종료주 | F1: 상태 | G1: 비고 | H1: 1 | I1: 2 | J1: 3 | K1: 4 | L1: 5 | M1: 6 | N1: 7 | O1: 8 | P1: 9 | Q1: 10 | R1: 11 | S1: 12 | T1: 13 | U1: 14 | V1: 15
A2: 계획 기간 | H2: =대시보드!$C$8+7*(1-1) | I2: =대시보드!$C$8+7*(2-1) | J2: =대시보드!$C$8+7*(3-1) | K2: =대시보드!$C$8+7*(4-1) | L2: =대시보드!$C$8+7*(5-1) | M2: =대시보드!$C$8+7*(6-1) | N2: =대시보드!$C$8+7*(7-1) | O2: =대시보드!$C$8+7*(8-1) | P2: =대시보드!$C$8+7*(9-1) | Q2: =대시보드!$C$8+7*(10-1) | R2: =대시보드!$C$8+7*(11-1) | S2: =대시보드!$C$8+7*(12-1) | T2: =대시보드!$C$8+7*(13-1) | U2: =대시보드!$C$8+7*(14-1) | V2: =대시보드!$C$8+7*(15-1)
A3: 단계 | B3: 분석 | C3: 공동 | D3: 1 | E3: 3 | F3: 완료 | G3: 산출물 5종 | H3: =IF(AND(1>=$D3,1<=$E3),IF($F3="완료","●",IF($F3="진행중","▶",IF($F3="제외",".",IF($F3="보류","◇","■")))),"") | I3: =IF(AND(2>=$D3,2<=$E3),IF($F3="완료","●",IF($F3="진행중","▶",IF($F3="제외",".",IF($F3="보류","◇","■")))),"") | J3: =IF(AND(3>=$D3,3<=$E3),IF($F3="완료","●",IF($F3="진행중","▶",IF($F3="제외",".",IF($F3="보류","◇","■")))),"") | K3: =IF(AND(4>=$D3,4<=$E3),IF($F3="완료","●",IF($F3="진행중","▶",IF($F3="제외",".",IF($F3="보류","◇","■")))),"") | L3: =IF(AND(5>=$D3,5<=$E3),IF($F3="완료","●",IF($F3="진행중","▶",IF($F3="제외",".",IF($F3="보류","◇","■")))),"") | M3: =IF(AND(6>=$D3,6<=$E3),IF($F3="완료","●",IF($F3="진행중","▶",IF($F3="제외",".",IF($F3="보류","◇","■")))),"") | N3: =IF(AND(7>=$D3,7<=$E3),IF($F3="완료","●",IF($F3="진행중","▶",IF($F3="제외",".",IF($F3="보류","◇","■")))),"") | O3: =IF(AND(8>=$D3,8<=$E3),IF($F3="완료","●",IF($F3="진행중","▶",IF($F3="제외",".",IF($F3="보류","◇","■")))),"") | P3: =IF(AND(9>=$D3,9<=$E3),IF($F3="완료","●",IF($F3="진행중","▶",IF($F3="제외",".",IF($F3="보류","◇","■")))),"") | Q3: =IF(AND(10>=$D3,10<=$E3),IF($F3="완료","●",IF($F3="진행중","▶",IF($F3="제외",".",IF($F3="보류","◇","■")))),"") | R3: =IF(AND(11>=$D3,11<=$E3),IF($F3="완료","●",IF($F3="진행중","▶",IF($F3="제외",".",IF($F3="보류","◇","■")))),"") | S3: =IF(AND(12>=$D3,12<=$E3),IF($F3="완료","●",IF($F3="진행중","▶",IF($F3="제외",".",IF($F3="보류","◇","■")))),"") | T3: =IF(AND(13>=$D3,13<=$E3),IF($F3="완료","●",IF($F3="진행중","▶",IF($F3="제외",".",IF($F3="보류","◇","■")))),"") | U3: =IF(AND(14>=$D3,14<=$E3),IF($F3="완료","●",IF($F3="진행중","▶",IF($F3="제외",".",IF($F3="보류","◇","■")))),"") | V3: =IF(AND(15>=$D3,15<=$E3),IF($F3="완료","●",IF($F3="진행중","▶",IF($F3="제외",".",IF($F3="보류","◇","■")))),"")
A4: 단계 | B4: 설계 | C4: 공동 | D4: 4 | E4: 5 | F4: 대기 | G4: 주 5 말 게이트 | H4: =IF(AND(1>=$D4,1<=$E4),IF($F4="완료","●",IF($F4="진행중","▶",IF($F4="제외",".",IF($F4="보류","◇","■")))),"") | I4: =IF(AND(2>=$D4,2<=$E4),IF($F4="완료","●",IF($F4="진행중","▶",IF($F4="제외",".",IF($F4="보류","◇","■")))),"") | J4: =IF(AND(3>=$D4,3<=$E4),IF($F4="완료","●",IF($F4="진행중","▶",IF($F4="제외",".",IF($F4="보류","◇","■")))),"") | K4: =IF(AND(4>=$D4,4<=$E4),IF($F4="완료","●",IF($F4="진행중","▶",IF($F4="제외",".",IF($F4="보류","◇","■")))),"") | L4: =IF(AND(5>=$D4,5<=$E4),IF($F4="완료","●",IF($F4="진행중","▶",IF($F4="제외",".",IF($F4="보류","◇","■")))),"") | M4: =IF(AND(6>=$D4,6<=$E4),IF($F4="완료","●",IF($F4="진행중","▶",IF($F4="제외",".",IF($F4="보류","◇","■")))),"") | N4: =IF(AND(7>=$D4,7<=$E4),IF($F4="완료","●",IF($F4="진행중","▶",IF($F4="제외",".",IF($F4="보류","◇","■")))),"") | O4: =IF(AND(8>=$D4,8<=$E4),IF($F4="완료","●",IF($F4="진행중","▶",IF($F4="제외",".",IF($F4="보류","◇","■")))),"") | P4: =IF(AND(9>=$D4,9<=$E4),IF($F4="완료","●",IF($F4="진행중","▶",IF($F4="제외",".",IF($F4="보류","◇","■")))),"") | Q4: =IF(AND(10>=$D4,10<=$E4),IF($F4="완료","●",IF($F4="진행중","▶",IF($F4="제외",".",IF($F4="보류","◇","■")))),"") | R4: =IF(AND(11>=$D4,11<=$E4),IF($F4="완료","●",IF($F4="진행중","▶",IF($F4="제외",".",IF($F4="보류","◇","■")))),"") | S4: =IF(AND(12>=$D4,12<=$E4),IF($F4="완료","●",IF($F4="진행중","▶",IF($F4="제외",".",IF($F4="보류","◇","■")))),"") | T4: =IF(AND(13>=$D4,13<=$E4),IF($F4="완료","●",IF($F4="진행중","▶",IF($F4="제외",".",IF($F4="보류","◇","■")))),"") | U4: =IF(AND(14>=$D4,14<=$E4),IF($F4="완료","●",IF($F4="진행중","▶",IF($F4="제외",".",IF($F4="보류","◇","■")))),"") | V4: =IF(AND(15>=$D4,15<=$E4),IF($F4="완료","●",IF($F4="진행중","▶",IF($F4="제외",".",IF($F4="보류","◇","■")))),"")
A5: 단계 | B5: 구현 (S1–S6) | C5: 공동 | D5: 6 | E5: 11 | F5: 대기 | G5: 11주 말 기능 동결 | H5: =IF(AND(1>=$D5,1<=$E5),IF($F5="완료","●",IF($F5="진행중","▶",IF($F5="제외",".",IF($F5="보류","◇","■")))),"") | I5: =IF(AND(2>=$D5,2<=$E5),IF($F5="완료","●",IF($F5="진행중","▶",IF($F5="제외",".",IF($F5="보류","◇","■")))),"") | J5: =IF(AND(3>=$D5,3<=$E5),IF($F5="완료","●",IF($F5="진행중","▶",IF($F5="제외",".",IF($F5="보류","◇","■")))),"") | K5: =IF(AND(4>=$D5,4<=$E5),IF($F5="완료","●",IF($F5="진행중","▶",IF($F5="제외",".",IF($F5="보류","◇","■")))),"") | L5: =IF(AND(5>=$D5,5<=$E5),IF($F5="완료","●",IF($F5="진행중","▶",IF($F5="제외",".",IF($F5="보류","◇","■")))),"") | M5: =IF(AND(6>=$D5,6<=$E5),IF($F5="완료","●",IF($F5="진행중","▶",IF($F5="제외",".",IF($F5="보류","◇","■")))),"") | N5: =IF(AND(7>=$D5,7<=$E5),IF($F5="완료","●",IF($F5="진행중","▶",IF($F5="제외",".",IF($F5="보류","◇","■")))),"") | O5: =IF(AND(8>=$D5,8<=$E5),IF($F5="완료","●",IF($F5="진행중","▶",IF($F5="제외",".",IF($F5="보류","◇","■")))),"") | P5: =IF(AND(9>=$D5,9<=$E5),IF($F5="완료","●",IF($F5="진행중","▶",IF($F5="제외",".",IF($F5="보류","◇","■")))),"") | Q5: =IF(AND(10>=$D5,10<=$E5),IF($F5="완료","●",IF($F5="진행중","▶",IF($F5="제외",".",IF($F5="보류","◇","■")))),"") | R5: =IF(AND(11>=$D5,11<=$E5),IF($F5="완료","●",IF($F5="진행중","▶",IF($F5="제외",".",IF($F5="보류","◇","■")))),"") | S5: =IF(AND(12>=$D5,12<=$E5),IF($F5="완료","●",IF($F5="진행중","▶",IF($F5="제외",".",IF($F5="보류","◇","■")))),"") | T5: =IF(AND(13>=$D5,13<=$E5),IF($F5="완료","●",IF($F5="진행중","▶",IF($F5="제외",".",IF($F5="보류","◇","■")))),"") | U5: =IF(AND(14>=$D5,14<=$E5),IF($F5="완료","●",IF($F5="진행중","▶",IF($F5="제외",".",IF($F5="보류","◇","■")))),"") | V5: =IF(AND(15>=$D5,15<=$E5),IF($F5="완료","●",IF($F5="진행중","▶",IF($F5="제외",".",IF($F5="보류","◇","■")))),"")
A6: 단계 | B6: 테스트 | C6: 공동 | D6: 12 | E6: 13 | F6: 대기 | G6: 필수 100% · 치명/주요 0 | H6: =IF(AND(1>=$D6,1<=$E6),IF($F6="완료","●",IF($F6="진행중","▶",IF($F6="제외",".",IF($F6="보류","◇","■")))),"") | I6: =IF(AND(2>=$D6,2<=$E6),IF($F6="완료","●",IF($F6="진행중","▶",IF($F6="제외",".",IF($F6="보류","◇","■")))),"") | J6: =IF(AND(3>=$D6,3<=$E6),IF($F6="완료","●",IF($F6="진행중","▶",IF($F6="제외",".",IF($F6="보류","◇","■")))),"") | K6: =IF(AND(4>=$D6,4<=$E6),IF($F6="완료","●",IF($F6="진행중","▶",IF($F6="제외",".",IF($F6="보류","◇","■")))),"") | L6: =IF(AND(5>=$D6,5<=$E6),IF($F6="완료","●",IF($F6="진행중","▶",IF($F6="제외",".",IF($F6="보류","◇","■")))),"") | M6: =IF(AND(6>=$D6,6<=$E6),IF($F6="완료","●",IF($F6="진행중","▶",IF($F6="제외",".",IF($F6="보류","◇","■")))),"") | N6: =IF(AND(7>=$D6,7<=$E6),IF($F6="완료","●",IF($F6="진행중","▶",IF($F6="제외",".",IF($F6="보류","◇","■")))),"") | O6: =IF(AND(8>=$D6,8<=$E6),IF($F6="완료","●",IF($F6="진행중","▶",IF($F6="제외",".",IF($F6="보류","◇","■")))),"") | P6: =IF(AND(9>=$D6,9<=$E6),IF($F6="완료","●",IF($F6="진행중","▶",IF($F6="제외",".",IF($F6="보류","◇","■")))),"") | Q6: =IF(AND(10>=$D6,10<=$E6),IF($F6="완료","●",IF($F6="진행중","▶",IF($F6="제외",".",IF($F6="보류","◇","■")))),"") | R6: =IF(AND(11>=$D6,11<=$E6),IF($F6="완료","●",IF($F6="진행중","▶",IF($F6="제외",".",IF($F6="보류","◇","■")))),"") | S6: =IF(AND(12>=$D6,12<=$E6),IF($F6="완료","●",IF($F6="진행중","▶",IF($F6="제외",".",IF($F6="보류","◇","■")))),"") | T6: =IF(AND(13>=$D6,13<=$E6),IF($F6="완료","●",IF($F6="진행중","▶",IF($F6="제외",".",IF($F6="보류","◇","■")))),"") | U6: =IF(AND(14>=$D6,14<=$E6),IF($F6="완료","●",IF($F6="진행중","▶",IF($F6="제외",".",IF($F6="보류","◇","■")))),"") | V6: =IF(AND(15>=$D6,15<=$E6),IF($F6="완료","●",IF($F6="진행중","▶",IF($F6="제외",".",IF($F6="보류","◇","■")))),"")
A7: 단계 | B7: 안정화·인도 | C7: 공동 | D7: 14 | E7: 15 | F7: 대기 | G7: 시연·발표 | H7: =IF(AND(1>=$D7,1<=$E7),IF($F7="완료","●",IF($F7="진행중","▶",IF($F7="제외",".",IF($F7="보류","◇","■")))),"") | I7: =IF(AND(2>=$D7,2<=$E7),IF($F7="완료","●",IF($F7="진행중","▶",IF($F7="제외",".",IF($F7="보류","◇","■")))),"") | J7: =IF(AND(3>=$D7,3<=$E7),IF($F7="완료","●",IF($F7="진행중","▶",IF($F7="제외",".",IF($F7="보류","◇","■")))),"") | K7: =IF(AND(4>=$D7,4<=$E7),IF($F7="완료","●",IF($F7="진행중","▶",IF($F7="제외",".",IF($F7="보류","◇","■")))),"") | L7: =IF(AND(5>=$D7,5<=$E7),IF($F7="완료","●",IF($F7="진행중","▶",IF($F7="제외",".",IF($F7="보류","◇","■")))),"") | M7: =IF(AND(6>=$D7,6<=$E7),IF($F7="완료","●",IF($F7="진행중","▶",IF($F7="제외",".",IF($F7="보류","◇","■")))),"") | N7: =IF(AND(7>=$D7,7<=$E7),IF($F7="완료","●",IF($F7="진행중","▶",IF($F7="제외",".",IF($F7="보류","◇","■")))),"") | O7: =IF(AND(8>=$D7,8<=$E7),IF($F7="완료","●",IF($F7="진행중","▶",IF($F7="제외",".",IF($F7="보류","◇","■")))),"") | P7: =IF(AND(9>=$D7,9<=$E7),IF($F7="완료","●",IF($F7="진행중","▶",IF($F7="제외",".",IF($F7="보류","◇","■")))),"") | Q7: =IF(AND(10>=$D7,10<=$E7),IF($F7="완료","●",IF($F7="진행중","▶",IF($F7="제외",".",IF($F7="보류","◇","■")))),"") | R7: =IF(AND(11>=$D7,11<=$E7),IF($F7="완료","●",IF($F7="진행중","▶",IF($F7="제외",".",IF($F7="보류","◇","■")))),"") | S7: =IF(AND(12>=$D7,12<=$E7),IF($F7="완료","●",IF($F7="진행중","▶",IF($F7="제외",".",IF($F7="보류","◇","■")))),"") | T7: =IF(AND(13>=$D7,13<=$E7),IF($F7="완료","●",IF($F7="진행중","▶",IF($F7="제외",".",IF($F7="보류","◇","■")))),"") | U7: =IF(AND(14>=$D7,14<=$E7),IF($F7="완료","●",IF($F7="진행중","▶",IF($F7="제외",".",IF($F7="보류","◇","■")))),"") | V7: =IF(AND(15>=$D7,15<=$E7),IF($F7="완료","●",IF($F7="진행중","▶",IF($F7="제외",".",IF($F7="보류","◇","■")))),"")
A8: 관리 | B8: 주간 스프린트 리뷰 | C8: 조찬희 | D8: 1 | E8: 15 | F8: 진행중 | G8: 주 1회 | H8: =IF(AND(1>=$D8,1<=$E8),IF($F8="완료","●",IF($F8="진행중","▶",IF($F8="제외",".",IF($F8="보류","◇","■")))),"") | I8: =IF(AND(2>=$D8,2<=$E8),IF($F8="완료","●",IF($F8="진행중","▶",IF($F8="제외",".",IF($F8="보류","◇","■")))),"") | J8: =IF(AND(3>=$D8,3<=$E8),IF($F8="완료","●",IF($F8="진행중","▶",IF($F8="제외",".",IF($F8="보류","◇","■")))),"") | K8: =IF(AND(4>=$D8,4<=$E8),IF($F8="완료","●",IF($F8="진행중","▶",IF($F8="제외",".",IF($F8="보류","◇","■")))),"") | L8: =IF(AND(5>=$D8,5<=$E8),IF($F8="완료","●",IF($F8="진행중","▶",IF($F8="제외",".",IF($F8="보류","◇","■")))),"") | M8: =IF(AND(6>=$D8,6<=$E8),IF($F8="완료","●",IF($F8="진행중","▶",IF($F8="제외",".",IF($F8="보류","◇","■")))),"") | N8: =IF(AND(7>=$D8,7<=$E8),IF($F8="완료","●",IF($F8="진행중","▶",IF($F8="제외",".",IF($F8="보류","◇","■")))),"") | O8: =IF(AND(8>=$D8,8<=$E8),IF($F8="완료","●",IF($F8="진행중","▶",IF($F8="제외",".",IF($F8="보류","◇","■")))),"") | P8: =IF(AND(9>=$D8,9<=$E8),IF($F8="완료","●",IF($F8="진행중","▶",IF($F8="제외",".",IF($F8="보류","◇","■")))),"") | Q8: =IF(AND(10>=$D8,10<=$E8),IF($F8="완료","●",IF($F8="진행중","▶",IF($F8="제외",".",IF($F8="보류","◇","■")))),"") | R8: =IF(AND(11>=$D8,11<=$E8),IF($F8="완료","●",IF($F8="진행중","▶",IF($F8="제외",".",IF($F8="보류","◇","■")))),"") | S8: =IF(AND(12>=$D8,12<=$E8),IF($F8="완료","●",IF($F8="진행중","▶",IF($F8="제외",".",IF($F8="보류","◇","■")))),"") | T8: =IF(AND(13>=$D8,13<=$E8),IF($F8="완료","●",IF($F8="진행중","▶",IF($F8="제외",".",IF($F8="보류","◇","■")))),"") | U8: =IF(AND(14>=$D8,14<=$E8),IF($F8="완료","●",IF($F8="진행중","▶",IF($F8="제외",".",IF($F8="보류","◇","■")))),"") | V8: =IF(AND(15>=$D8,15<=$E8),IF($F8="완료","●",IF($F8="진행중","▶",IF($F8="제외",".",IF($F8="보류","◇","■")))),"")
A9: 관리 | B9: 위험·UTIC/쿼터 추적 | C9: 조찬희 | D9: 1 | E9: 15 | F9: 진행중 | H9: =IF(AND(1>=$D9,1<=$E9),IF($F9="완료","●",IF($F9="진행중","▶",IF($F9="제외",".",IF($F9="보류","◇","■")))),"") | I9: =IF(AND(2>=$D9,2<=$E9),IF($F9="완료","●",IF($F9="진행중","▶",IF($F9="제외",".",IF($F9="보류","◇","■")))),"") | J9: =IF(AND(3>=$D9,3<=$E9),IF($F9="완료","●",IF($F9="진행중","▶",IF($F9="제외",".",IF($F9="보류","◇","■")))),"") | K9: =IF(AND(4>=$D9,4<=$E9),IF($F9="완료","●",IF($F9="진행중","▶",IF($F9="제외",".",IF($F9="보류","◇","■")))),"") | L9: =IF(AND(5>=$D9,5<=$E9),IF($F9="완료","●",IF($F9="진행중","▶",IF($F9="제외",".",IF($F9="보류","◇","■")))),"") | M9: =IF(AND(6>=$D9,6<=$E9),IF($F9="완료","●",IF($F9="진행중","▶",IF($F9="제외",".",IF($F9="보류","◇","■")))),"") | N9: =IF(AND(7>=$D9,7<=$E9),IF($F9="완료","●",IF($F9="진행중","▶",IF($F9="제외",".",IF($F9="보류","◇","■")))),"") | O9: =IF(AND(8>=$D9,8<=$E9),IF($F9="완료","●",IF($F9="진행중","▶",IF($F9="제외",".",IF($F9="보류","◇","■")))),"") | P9: =IF(AND(9>=$D9,9<=$E9),IF($F9="완료","●",IF($F9="진행중","▶",IF($F9="제외",".",IF($F9="보류","◇","■")))),"") | Q9: =IF(AND(10>=$D9,10<=$E9),IF($F9="완료","●",IF($F9="진행중","▶",IF($F9="제외",".",IF($F9="보류","◇","■")))),"") | R9: =IF(AND(11>=$D9,11<=$E9),IF($F9="완료","●",IF($F9="진행중","▶",IF($F9="제외",".",IF($F9="보류","◇","■")))),"") | S9: =IF(AND(12>=$D9,12<=$E9),IF($F9="완료","●",IF($F9="진행중","▶",IF($F9="제외",".",IF($F9="보류","◇","■")))),"") | T9: =IF(AND(13>=$D9,13<=$E9),IF($F9="완료","●",IF($F9="진행중","▶",IF($F9="제외",".",IF($F9="보류","◇","■")))),"") | U9: =IF(AND(14>=$D9,14<=$E9),IF($F9="완료","●",IF($F9="진행중","▶",IF($F9="제외",".",IF($F9="보류","◇","■")))),"") | V9: =IF(AND(15>=$D9,15<=$E9),IF($F9="완료","●",IF($F9="진행중","▶",IF($F9="제외",".",IF($F9="보류","◇","■")))),"")
A10: 스프린트 | B10: S0 분석 산출물 고정 | C10: 조찬희 | D10: 1 | E10: 3 | F10: 완료 | H10: =IF(AND(1>=$D10,1<=$E10),IF($F10="완료","●",IF($F10="진행중","▶",IF($F10="제외",".",IF($F10="보류","◇","■")))),"") | I10: =IF(AND(2>=$D10,2<=$E10),IF($F10="완료","●",IF($F10="진행중","▶",IF($F10="제외",".",IF($F10="보류","◇","■")))),"") | J10: =IF(AND(3>=$D10,3<=$E10),IF($F10="완료","●",IF($F10="진행중","▶",IF($F10="제외",".",IF($F10="보류","◇","■")))),"") | K10: =IF(AND(4>=$D10,4<=$E10),IF($F10="완료","●",IF($F10="진행중","▶",IF($F10="제외",".",IF($F10="보류","◇","■")))),"") | L10: =IF(AND(5>=$D10,5<=$E10),IF($F10="완료","●",IF($F10="진행중","▶",IF($F10="제외",".",IF($F10="보류","◇","■")))),"") | M10: =IF(AND(6>=$D10,6<=$E10),IF($F10="완료","●",IF($F10="진행중","▶",IF($F10="제외",".",IF($F10="보류","◇","■")))),"") | N10: =IF(AND(7>=$D10,7<=$E10),IF($F10="완료","●",IF($F10="진행중","▶",IF($F10="제외",".",IF($F10="보류","◇","■")))),"") | O10: =IF(AND(8>=$D10,8<=$E10),IF($F10="완료","●",IF($F10="진행중","▶",IF($F10="제외",".",IF($F10="보류","◇","■")))),"") | P10: =IF(AND(9>=$D10,9<=$E10),IF($F10="완료","●",IF($F10="진행중","▶",IF($F10="제외",".",IF($F10="보류","◇","■")))),"") | Q10: =IF(AND(10>=$D10,10<=$E10),IF($F10="완료","●",IF($F10="진행중","▶",IF($F10="제외",".",IF($F10="보류","◇","■")))),"") | R10: =IF(AND(11>=$D10,11<=$E10),IF($F10="완료","●",IF($F10="진행중","▶",IF($F10="제외",".",IF($F10="보류","◇","■")))),"") | S10: =IF(AND(12>=$D10,12<=$E10),IF($F10="완료","●",IF($F10="진행중","▶",IF($F10="제외",".",IF($F10="보류","◇","■")))),"") | T10: =IF(AND(13>=$D10,13<=$E10),IF($F10="완료","●",IF($F10="진행중","▶",IF($F10="제외",".",IF($F10="보류","◇","■")))),"") | U10: =IF(AND(14>=$D10,14<=$E10),IF($F10="완료","●",IF($F10="진행중","▶",IF($F10="제외",".",IF($F10="보류","◇","■")))),"") | V10: =IF(AND(15>=$D10,15<=$E10),IF($F10="완료","●",IF($F10="진행중","▶",IF($F10="제외",".",IF($F10="보류","◇","■")))),"")
A11: 스프린트 | B11: S-D1 스택·IA·ERD | C11: 공동 | D11: 4 | E11: 4 | F11: 대기 | H11: =IF(AND(1>=$D11,1<=$E11),IF($F11="완료","●",IF($F11="진행중","▶",IF($F11="제외",".",IF($F11="보류","◇","■")))),"") | I11: =IF(AND(2>=$D11,2<=$E11),IF($F11="완료","●",IF($F11="진행중","▶",IF($F11="제외",".",IF($F11="보류","◇","■")))),"") | J11: =IF(AND(3>=$D11,3<=$E11),IF($F11="완료","●",IF($F11="진행중","▶",IF($F11="제외",".",IF($F11="보류","◇","■")))),"") | K11: =IF(AND(4>=$D11,4<=$E11),IF($F11="완료","●",IF($F11="진행중","▶",IF($F11="제외",".",IF($F11="보류","◇","■")))),"") | L11: =IF(AND(5>=$D11,5<=$E11),IF($F11="완료","●",IF($F11="진행중","▶",IF($F11="제외",".",IF($F11="보류","◇","■")))),"") | M11: =IF(AND(6>=$D11,6<=$E11),IF($F11="완료","●",IF($F11="진행중","▶",IF($F11="제외",".",IF($F11="보류","◇","■")))),"") | N11: =IF(AND(7>=$D11,7<=$E11),IF($F11="완료","●",IF($F11="진행중","▶",IF($F11="제외",".",IF($F11="보류","◇","■")))),"") | O11: =IF(AND(8>=$D11,8<=$E11),IF($F11="완료","●",IF($F11="진행중","▶",IF($F11="제외",".",IF($F11="보류","◇","■")))),"") | P11: =IF(AND(9>=$D11,9<=$E11),IF($F11="완료","●",IF($F11="진행중","▶",IF($F11="제외",".",IF($F11="보류","◇","■")))),"") | Q11: =IF(AND(10>=$D11,10<=$E11),IF($F11="완료","●",IF($F11="진행중","▶",IF($F11="제외",".",IF($F11="보류","◇","■")))),"") | R11: =IF(AND(11>=$D11,11<=$E11),IF($F11="완료","●",IF($F11="진행중","▶",IF($F11="제외",".",IF($F11="보류","◇","■")))),"") | S11: =IF(AND(12>=$D11,12<=$E11),IF($F11="완료","●",IF($F11="진행중","▶",IF($F11="제외",".",IF($F11="보류","◇","■")))),"") | T11: =IF(AND(13>=$D11,13<=$E11),IF($F11="완료","●",IF($F11="진행중","▶",IF($F11="제외",".",IF($F11="보류","◇","■")))),"") | U11: =IF(AND(14>=$D11,14<=$E11),IF($F11="완료","●",IF($F11="진행중","▶",IF($F11="제외",".",IF($F11="보류","◇","■")))),"") | V11: =IF(AND(15>=$D11,15<=$E11),IF($F11="완료","●",IF($F11="진행중","▶",IF($F11="제외",".",IF($F11="보류","◇","■")))),"")
A12: 스프린트 | B12: S-D2 API·규칙·프로토타입 | C12: 공동 | D12: 5 | E12: 5 | F12: 대기 | H12: =IF(AND(1>=$D12,1<=$E12),IF($F12="완료","●",IF($F12="진행중","▶",IF($F12="제외",".",IF($F12="보류","◇","■")))),"") | I12: =IF(AND(2>=$D12,2<=$E12),IF($F12="완료","●",IF($F12="진행중","▶",IF($F12="제외",".",IF($F12="보류","◇","■")))),"") | J12: =IF(AND(3>=$D12,3<=$E12),IF($F12="완료","●",IF($F12="진행중","▶",IF($F12="제외",".",IF($F12="보류","◇","■")))),"") | K12: =IF(AND(4>=$D12,4<=$E12),IF($F12="완료","●",IF($F12="진행중","▶",IF($F12="제외",".",IF($F12="보류","◇","■")))),"") | L12: =IF(AND(5>=$D12,5<=$E12),IF($F12="완료","●",IF($F12="진행중","▶",IF($F12="제외",".",IF($F12="보류","◇","■")))),"") | M12: =IF(AND(6>=$D12,6<=$E12),IF($F12="완료","●",IF($F12="진행중","▶",IF($F12="제외",".",IF($F12="보류","◇","■")))),"") | N12: =IF(AND(7>=$D12,7<=$E12),IF($F12="완료","●",IF($F12="진행중","▶",IF($F12="제외",".",IF($F12="보류","◇","■")))),"") | O12: =IF(AND(8>=$D12,8<=$E12),IF($F12="완료","●",IF($F12="진행중","▶",IF($F12="제외",".",IF($F12="보류","◇","■")))),"") | P12: =IF(AND(9>=$D12,9<=$E12),IF($F12="완료","●",IF($F12="진행중","▶",IF($F12="제외",".",IF($F12="보류","◇","■")))),"") | Q12: =IF(AND(10>=$D12,10<=$E12),IF($F12="완료","●",IF($F12="진행중","▶",IF($F12="제외",".",IF($F12="보류","◇","■")))),"") | R12: =IF(AND(11>=$D12,11<=$E12),IF($F12="완료","●",IF($F12="진행중","▶",IF($F12="제외",".",IF($F12="보류","◇","■")))),"") | S12: =IF(AND(12>=$D12,12<=$E12),IF($F12="완료","●",IF($F12="진행중","▶",IF($F12="제외",".",IF($F12="보류","◇","■")))),"") | T12: =IF(AND(13>=$D12,13<=$E12),IF($F12="완료","●",IF($F12="진행중","▶",IF($F12="제외",".",IF($F12="보류","◇","■")))),"") | U12: =IF(AND(14>=$D12,14<=$E12),IF($F12="완료","●",IF($F12="진행중","▶",IF($F12="제외",".",IF($F12="보류","◇","■")))),"") | V12: =IF(AND(15>=$D12,15<=$E12),IF($F12="완료","●",IF($F12="진행중","▶",IF($F12="제외",".",IF($F12="보류","◇","■")))),"")
A13: 스프린트 | B13: S1 기동·로그인 | C13: 공동 | D13: 6 | E13: 6 | F13: 대기 | G13: Must 3SP | H13: =IF(AND(1>=$D13,1<=$E13),IF($F13="완료","●",IF($F13="진행중","▶",IF($F13="제외",".",IF($F13="보류","◇","■")))),"") | I13: =IF(AND(2>=$D13,2<=$E13),IF($F13="완료","●",IF($F13="진행중","▶",IF($F13="제외",".",IF($F13="보류","◇","■")))),"") | J13: =IF(AND(3>=$D13,3<=$E13),IF($F13="완료","●",IF($F13="진행중","▶",IF($F13="제외",".",IF($F13="보류","◇","■")))),"") | K13: =IF(AND(4>=$D13,4<=$E13),IF($F13="완료","●",IF($F13="진행중","▶",IF($F13="제외",".",IF($F13="보류","◇","■")))),"") | L13: =IF(AND(5>=$D13,5<=$E13),IF($F13="완료","●",IF($F13="진행중","▶",IF($F13="제외",".",IF($F13="보류","◇","■")))),"") | M13: =IF(AND(6>=$D13,6<=$E13),IF($F13="완료","●",IF($F13="진행중","▶",IF($F13="제외",".",IF($F13="보류","◇","■")))),"") | N13: =IF(AND(7>=$D13,7<=$E13),IF($F13="완료","●",IF($F13="진행중","▶",IF($F13="제외",".",IF($F13="보류","◇","■")))),"") | O13: =IF(AND(8>=$D13,8<=$E13),IF($F13="완료","●",IF($F13="진행중","▶",IF($F13="제외",".",IF($F13="보류","◇","■")))),"") | P13: =IF(AND(9>=$D13,9<=$E13),IF($F13="완료","●",IF($F13="진행중","▶",IF($F13="제외",".",IF($F13="보류","◇","■")))),"") | Q13: =IF(AND(10>=$D13,10<=$E13),IF($F13="완료","●",IF($F13="진행중","▶",IF($F13="제외",".",IF($F13="보류","◇","■")))),"") | R13: =IF(AND(11>=$D13,11<=$E13),IF($F13="완료","●",IF($F13="진행중","▶",IF($F13="제외",".",IF($F13="보류","◇","■")))),"") | S13: =IF(AND(12>=$D13,12<=$E13),IF($F13="완료","●",IF($F13="진행중","▶",IF($F13="제외",".",IF($F13="보류","◇","■")))),"") | T13: =IF(AND(13>=$D13,13<=$E13),IF($F13="완료","●",IF($F13="진행중","▶",IF($F13="제외",".",IF($F13="보류","◇","■")))),"") | U13: =IF(AND(14>=$D13,14<=$E13),IF($F13="완료","●",IF($F13="진행중","▶",IF($F13="제외",".",IF($F13="보류","◇","■")))),"") | V13: =IF(AND(15>=$D13,15<=$E13),IF($F13="완료","●",IF($F13="진행중","▶",IF($F13="제외",".",IF($F13="보류","◇","■")))),"")
A14: 스프린트 | B14: S2 인천 수집 | C14: 기경현 | D14: 7 | E14: 7 | F14: 대기 | G14: Must 16SP | H14: =IF(AND(1>=$D14,1<=$E14),IF($F14="완료","●",IF($F14="진행중","▶",IF($F14="제외",".",IF($F14="보류","◇","■")))),"") | I14: =IF(AND(2>=$D14,2<=$E14),IF($F14="완료","●",IF($F14="진행중","▶",IF($F14="제외",".",IF($F14="보류","◇","■")))),"") | J14: =IF(AND(3>=$D14,3<=$E14),IF($F14="완료","●",IF($F14="진행중","▶",IF($F14="제외",".",IF($F14="보류","◇","■")))),"") | K14: =IF(AND(4>=$D14,4<=$E14),IF($F14="완료","●",IF($F14="진행중","▶",IF($F14="제외",".",IF($F14="보류","◇","■")))),"") | L14: =IF(AND(5>=$D14,5<=$E14),IF($F14="완료","●",IF($F14="진행중","▶",IF($F14="제외",".",IF($F14="보류","◇","■")))),"") | M14: =IF(AND(6>=$D14,6<=$E14),IF($F14="완료","●",IF($F14="진행중","▶",IF($F14="제외",".",IF($F14="보류","◇","■")))),"") | N14: =IF(AND(7>=$D14,7<=$E14),IF($F14="완료","●",IF($F14="진행중","▶",IF($F14="제외",".",IF($F14="보류","◇","■")))),"") | O14: =IF(AND(8>=$D14,8<=$E14),IF($F14="완료","●",IF($F14="진행중","▶",IF($F14="제외",".",IF($F14="보류","◇","■")))),"") | P14: =IF(AND(9>=$D14,9<=$E14),IF($F14="완료","●",IF($F14="진행중","▶",IF($F14="제외",".",IF($F14="보류","◇","■")))),"") | Q14: =IF(AND(10>=$D14,10<=$E14),IF($F14="완료","●",IF($F14="진행중","▶",IF($F14="제외",".",IF($F14="보류","◇","■")))),"") | R14: =IF(AND(11>=$D14,11<=$E14),IF($F14="완료","●",IF($F14="진행중","▶",IF($F14="제외",".",IF($F14="보류","◇","■")))),"") | S14: =IF(AND(12>=$D14,12<=$E14),IF($F14="완료","●",IF($F14="진행중","▶",IF($F14="제외",".",IF($F14="보류","◇","■")))),"") | T14: =IF(AND(13>=$D14,13<=$E14),IF($F14="완료","●",IF($F14="진행중","▶",IF($F14="제외",".",IF($F14="보류","◇","■")))),"") | U14: =IF(AND(14>=$D14,14<=$E14),IF($F14="완료","●",IF($F14="진행중","▶",IF($F14="제외",".",IF($F14="보류","◇","■")))),"") | V14: =IF(AND(15>=$D14,15<=$E14),IF($F14="완료","●",IF($F14="진행중","▶",IF($F14="제외",".",IF($F14="보류","◇","■")))),"")
A15: 스프린트 | B15: S3 계획+엔진 | C15: 기경현 | D15: 8 | E15: 8 | F15: 대기 | G15: Must 16SP | H15: =IF(AND(1>=$D15,1<=$E15),IF($F15="완료","●",IF($F15="진행중","▶",IF($F15="제외",".",IF($F15="보류","◇","■")))),"") | I15: =IF(AND(2>=$D15,2<=$E15),IF($F15="완료","●",IF($F15="진행중","▶",IF($F15="제외",".",IF($F15="보류","◇","■")))),"") | J15: =IF(AND(3>=$D15,3<=$E15),IF($F15="완료","●",IF($F15="진행중","▶",IF($F15="제외",".",IF($F15="보류","◇","■")))),"") | K15: =IF(AND(4>=$D15,4<=$E15),IF($F15="완료","●",IF($F15="진행중","▶",IF($F15="제외",".",IF($F15="보류","◇","■")))),"") | L15: =IF(AND(5>=$D15,5<=$E15),IF($F15="완료","●",IF($F15="진행중","▶",IF($F15="제외",".",IF($F15="보류","◇","■")))),"") | M15: =IF(AND(6>=$D15,6<=$E15),IF($F15="완료","●",IF($F15="진행중","▶",IF($F15="제외",".",IF($F15="보류","◇","■")))),"") | N15: =IF(AND(7>=$D15,7<=$E15),IF($F15="완료","●",IF($F15="진행중","▶",IF($F15="제외",".",IF($F15="보류","◇","■")))),"") | O15: =IF(AND(8>=$D15,8<=$E15),IF($F15="완료","●",IF($F15="진행중","▶",IF($F15="제외",".",IF($F15="보류","◇","■")))),"") | P15: =IF(AND(9>=$D15,9<=$E15),IF($F15="완료","●",IF($F15="진행중","▶",IF($F15="제외",".",IF($F15="보류","◇","■")))),"") | Q15: =IF(AND(10>=$D15,10<=$E15),IF($F15="완료","●",IF($F15="진행중","▶",IF($F15="제외",".",IF($F15="보류","◇","■")))),"") | R15: =IF(AND(11>=$D15,11<=$E15),IF($F15="완료","●",IF($F15="진행중","▶",IF($F15="제외",".",IF($F15="보류","◇","■")))),"") | S15: =IF(AND(12>=$D15,12<=$E15),IF($F15="완료","●",IF($F15="진행중","▶",IF($F15="제외",".",IF($F15="보류","◇","■")))),"") | T15: =IF(AND(13>=$D15,13<=$E15),IF($F15="완료","●",IF($F15="진행중","▶",IF($F15="제외",".",IF($F15="보류","◇","■")))),"") | U15: =IF(AND(14>=$D15,14<=$E15),IF($F15="완료","●",IF($F15="진행중","▶",IF($F15="제외",".",IF($F15="보류","◇","■")))),"") | V15: =IF(AND(15>=$D15,15<=$E15),IF($F15="완료","●",IF($F15="진행중","▶",IF($F15="제외",".",IF($F15="보류","◇","■")))),"")
A16: 스프린트 | B16: S4 검지 분기 | C16: 기경현 | D16: 9 | E16: 9 | F16: 대기 | G16: Must 15SP | H16: =IF(AND(1>=$D16,1<=$E16),IF($F16="완료","●",IF($F16="진행중","▶",IF($F16="제외",".",IF($F16="보류","◇","■")))),"") | I16: =IF(AND(2>=$D16,2<=$E16),IF($F16="완료","●",IF($F16="진행중","▶",IF($F16="제외",".",IF($F16="보류","◇","■")))),"") | J16: =IF(AND(3>=$D16,3<=$E16),IF($F16="완료","●",IF($F16="진행중","▶",IF($F16="제외",".",IF($F16="보류","◇","■")))),"") | K16: =IF(AND(4>=$D16,4<=$E16),IF($F16="완료","●",IF($F16="진행중","▶",IF($F16="제외",".",IF($F16="보류","◇","■")))),"") | L16: =IF(AND(5>=$D16,5<=$E16),IF($F16="완료","●",IF($F16="진행중","▶",IF($F16="제외",".",IF($F16="보류","◇","■")))),"") | M16: =IF(AND(6>=$D16,6<=$E16),IF($F16="완료","●",IF($F16="진행중","▶",IF($F16="제외",".",IF($F16="보류","◇","■")))),"") | N16: =IF(AND(7>=$D16,7<=$E16),IF($F16="완료","●",IF($F16="진행중","▶",IF($F16="제외",".",IF($F16="보류","◇","■")))),"") | O16: =IF(AND(8>=$D16,8<=$E16),IF($F16="완료","●",IF($F16="진행중","▶",IF($F16="제외",".",IF($F16="보류","◇","■")))),"") | P16: =IF(AND(9>=$D16,9<=$E16),IF($F16="완료","●",IF($F16="진행중","▶",IF($F16="제외",".",IF($F16="보류","◇","■")))),"") | Q16: =IF(AND(10>=$D16,10<=$E16),IF($F16="완료","●",IF($F16="진행중","▶",IF($F16="제외",".",IF($F16="보류","◇","■")))),"") | R16: =IF(AND(11>=$D16,11<=$E16),IF($F16="완료","●",IF($F16="진행중","▶",IF($F16="제외",".",IF($F16="보류","◇","■")))),"") | S16: =IF(AND(12>=$D16,12<=$E16),IF($F16="완료","●",IF($F16="진행중","▶",IF($F16="제외",".",IF($F16="보류","◇","■")))),"") | T16: =IF(AND(13>=$D16,13<=$E16),IF($F16="완료","●",IF($F16="진행중","▶",IF($F16="제외",".",IF($F16="보류","◇","■")))),"") | U16: =IF(AND(14>=$D16,14<=$E16),IF($F16="완료","●",IF($F16="진행중","▶",IF($F16="제외",".",IF($F16="보류","◇","■")))),"") | V16: =IF(AND(15>=$D16,15<=$E16),IF($F16="완료","●",IF($F16="진행중","▶",IF($F16="제외",".",IF($F16="보류","◇","■")))),"")
A17: 스프린트 | B17: S5 대시보드·이슈 | C17: 조찬희 | D17: 10 | E17: 10 | F17: 대기 | G17: Must 17SP | H17: =IF(AND(1>=$D17,1<=$E17),IF($F17="완료","●",IF($F17="진행중","▶",IF($F17="제외",".",IF($F17="보류","◇","■")))),"") | I17: =IF(AND(2>=$D17,2<=$E17),IF($F17="완료","●",IF($F17="진행중","▶",IF($F17="제외",".",IF($F17="보류","◇","■")))),"") | J17: =IF(AND(3>=$D17,3<=$E17),IF($F17="완료","●",IF($F17="진행중","▶",IF($F17="제외",".",IF($F17="보류","◇","■")))),"") | K17: =IF(AND(4>=$D17,4<=$E17),IF($F17="완료","●",IF($F17="진행중","▶",IF($F17="제외",".",IF($F17="보류","◇","■")))),"") | L17: =IF(AND(5>=$D17,5<=$E17),IF($F17="완료","●",IF($F17="진행중","▶",IF($F17="제외",".",IF($F17="보류","◇","■")))),"") | M17: =IF(AND(6>=$D17,6<=$E17),IF($F17="완료","●",IF($F17="진행중","▶",IF($F17="제외",".",IF($F17="보류","◇","■")))),"") | N17: =IF(AND(7>=$D17,7<=$E17),IF($F17="완료","●",IF($F17="진행중","▶",IF($F17="제외",".",IF($F17="보류","◇","■")))),"") | O17: =IF(AND(8>=$D17,8<=$E17),IF($F17="완료","●",IF($F17="진행중","▶",IF($F17="제외",".",IF($F17="보류","◇","■")))),"") | P17: =IF(AND(9>=$D17,9<=$E17),IF($F17="완료","●",IF($F17="진행중","▶",IF($F17="제외",".",IF($F17="보류","◇","■")))),"") | Q17: =IF(AND(10>=$D17,10<=$E17),IF($F17="완료","●",IF($F17="진행중","▶",IF($F17="제외",".",IF($F17="보류","◇","■")))),"") | R17: =IF(AND(11>=$D17,11<=$E17),IF($F17="완료","●",IF($F17="진행중","▶",IF($F17="제외",".",IF($F17="보류","◇","■")))),"") | S17: =IF(AND(12>=$D17,12<=$E17),IF($F17="완료","●",IF($F17="진행중","▶",IF($F17="제외",".",IF($F17="보류","◇","■")))),"") | T17: =IF(AND(13>=$D17,13<=$E17),IF($F17="완료","●",IF($F17="진행중","▶",IF($F17="제외",".",IF($F17="보류","◇","■")))),"") | U17: =IF(AND(14>=$D17,14<=$E17),IF($F17="완료","●",IF($F17="진행중","▶",IF($F17="제외",".",IF($F17="보류","◇","■")))),"") | V17: =IF(AND(15>=$D17,15<=$E17),IF($F17="완료","●",IF($F17="진행중","▶",IF($F17="제외",".",IF($F17="보류","◇","■")))),"")
A18: 스프린트 | B18: S6 통제·동결 | C18: 공동 | D18: 11 | E18: 11 | F18: 대기 | G18: 29SP → 커트 | H18: =IF(AND(1>=$D18,1<=$E18),IF($F18="완료","●",IF($F18="진행중","▶",IF($F18="제외",".",IF($F18="보류","◇","■")))),"") | I18: =IF(AND(2>=$D18,2<=$E18),IF($F18="완료","●",IF($F18="진행중","▶",IF($F18="제외",".",IF($F18="보류","◇","■")))),"") | J18: =IF(AND(3>=$D18,3<=$E18),IF($F18="완료","●",IF($F18="진행중","▶",IF($F18="제외",".",IF($F18="보류","◇","■")))),"") | K18: =IF(AND(4>=$D18,4<=$E18),IF($F18="완료","●",IF($F18="진행중","▶",IF($F18="제외",".",IF($F18="보류","◇","■")))),"") | L18: =IF(AND(5>=$D18,5<=$E18),IF($F18="완료","●",IF($F18="진행중","▶",IF($F18="제외",".",IF($F18="보류","◇","■")))),"") | M18: =IF(AND(6>=$D18,6<=$E18),IF($F18="완료","●",IF($F18="진행중","▶",IF($F18="제외",".",IF($F18="보류","◇","■")))),"") | N18: =IF(AND(7>=$D18,7<=$E18),IF($F18="완료","●",IF($F18="진행중","▶",IF($F18="제외",".",IF($F18="보류","◇","■")))),"") | O18: =IF(AND(8>=$D18,8<=$E18),IF($F18="완료","●",IF($F18="진행중","▶",IF($F18="제외",".",IF($F18="보류","◇","■")))),"") | P18: =IF(AND(9>=$D18,9<=$E18),IF($F18="완료","●",IF($F18="진행중","▶",IF($F18="제외",".",IF($F18="보류","◇","■")))),"") | Q18: =IF(AND(10>=$D18,10<=$E18),IF($F18="완료","●",IF($F18="진행중","▶",IF($F18="제외",".",IF($F18="보류","◇","■")))),"") | R18: =IF(AND(11>=$D18,11<=$E18),IF($F18="완료","●",IF($F18="진행중","▶",IF($F18="제외",".",IF($F18="보류","◇","■")))),"") | S18: =IF(AND(12>=$D18,12<=$E18),IF($F18="완료","●",IF($F18="진행중","▶",IF($F18="제외",".",IF($F18="보류","◇","■")))),"") | T18: =IF(AND(13>=$D18,13<=$E18),IF($F18="완료","●",IF($F18="진행중","▶",IF($F18="제외",".",IF($F18="보류","◇","■")))),"") | U18: =IF(AND(14>=$D18,14<=$E18),IF($F18="완료","●",IF($F18="진행중","▶",IF($F18="제외",".",IF($F18="보류","◇","■")))),"") | V18: =IF(AND(15>=$D18,15<=$E18),IF($F18="완료","●",IF($F18="진행중","▶",IF($F18="제외",".",IF($F18="보류","◇","■")))),"")
A19: 스프린트 | B19: S-T1 케이스 실행 | C19: 공동 | D19: 12 | E19: 12 | F19: 대기 | H19: =IF(AND(1>=$D19,1<=$E19),IF($F19="완료","●",IF($F19="진행중","▶",IF($F19="제외",".",IF($F19="보류","◇","■")))),"") | I19: =IF(AND(2>=$D19,2<=$E19),IF($F19="완료","●",IF($F19="진행중","▶",IF($F19="제외",".",IF($F19="보류","◇","■")))),"") | J19: =IF(AND(3>=$D19,3<=$E19),IF($F19="완료","●",IF($F19="진행중","▶",IF($F19="제외",".",IF($F19="보류","◇","■")))),"") | K19: =IF(AND(4>=$D19,4<=$E19),IF($F19="완료","●",IF($F19="진행중","▶",IF($F19="제외",".",IF($F19="보류","◇","■")))),"") | L19: =IF(AND(5>=$D19,5<=$E19),IF($F19="완료","●",IF($F19="진행중","▶",IF($F19="제외",".",IF($F19="보류","◇","■")))),"") | M19: =IF(AND(6>=$D19,6<=$E19),IF($F19="완료","●",IF($F19="진행중","▶",IF($F19="제외",".",IF($F19="보류","◇","■")))),"") | N19: =IF(AND(7>=$D19,7<=$E19),IF($F19="완료","●",IF($F19="진행중","▶",IF($F19="제외",".",IF($F19="보류","◇","■")))),"") | O19: =IF(AND(8>=$D19,8<=$E19),IF($F19="완료","●",IF($F19="진행중","▶",IF($F19="제외",".",IF($F19="보류","◇","■")))),"") | P19: =IF(AND(9>=$D19,9<=$E19),IF($F19="완료","●",IF($F19="진행중","▶",IF($F19="제외",".",IF($F19="보류","◇","■")))),"") | Q19: =IF(AND(10>=$D19,10<=$E19),IF($F19="완료","●",IF($F19="진행중","▶",IF($F19="제외",".",IF($F19="보류","◇","■")))),"") | R19: =IF(AND(11>=$D19,11<=$E19),IF($F19="완료","●",IF($F19="진행중","▶",IF($F19="제외",".",IF($F19="보류","◇","■")))),"") | S19: =IF(AND(12>=$D19,12<=$E19),IF($F19="완료","●",IF($F19="진행중","▶",IF($F19="제외",".",IF($F19="보류","◇","■")))),"") | T19: =IF(AND(13>=$D19,13<=$E19),IF($F19="완료","●",IF($F19="진행중","▶",IF($F19="제외",".",IF($F19="보류","◇","■")))),"") | U19: =IF(AND(14>=$D19,14<=$E19),IF($F19="완료","●",IF($F19="진행중","▶",IF($F19="제외",".",IF($F19="보류","◇","■")))),"") | V19: =IF(AND(15>=$D19,15<=$E19),IF($F19="완료","●",IF($F19="진행중","▶",IF($F19="제외",".",IF($F19="보류","◇","■")))),"")
A20: 스프린트 | B20: S-T2 성능·보안 | C20: 공동 | D20: 13 | E20: 13 | F20: 대기 | H20: =IF(AND(1>=$D20,1<=$E20),IF($F20="완료","●",IF($F20="진행중","▶",IF($F20="제외",".",IF($F20="보류","◇","■")))),"") | I20: =IF(AND(2>=$D20,2<=$E20),IF($F20="완료","●",IF($F20="진행중","▶",IF($F20="제외",".",IF($F20="보류","◇","■")))),"") | J20: =IF(AND(3>=$D20,3<=$E20),IF($F20="완료","●",IF($F20="진행중","▶",IF($F20="제외",".",IF($F20="보류","◇","■")))),"") | K20: =IF(AND(4>=$D20,4<=$E20),IF($F20="완료","●",IF($F20="진행중","▶",IF($F20="제외",".",IF($F20="보류","◇","■")))),"") | L20: =IF(AND(5>=$D20,5<=$E20),IF($F20="완료","●",IF($F20="진행중","▶",IF($F20="제외",".",IF($F20="보류","◇","■")))),"") | M20: =IF(AND(6>=$D20,6<=$E20),IF($F20="완료","●",IF($F20="진행중","▶",IF($F20="제외",".",IF($F20="보류","◇","■")))),"") | N20: =IF(AND(7>=$D20,7<=$E20),IF($F20="완료","●",IF($F20="진행중","▶",IF($F20="제외",".",IF($F20="보류","◇","■")))),"") | O20: =IF(AND(8>=$D20,8<=$E20),IF($F20="완료","●",IF($F20="진행중","▶",IF($F20="제외",".",IF($F20="보류","◇","■")))),"") | P20: =IF(AND(9>=$D20,9<=$E20),IF($F20="완료","●",IF($F20="진행중","▶",IF($F20="제외",".",IF($F20="보류","◇","■")))),"") | Q20: =IF(AND(10>=$D20,10<=$E20),IF($F20="완료","●",IF($F20="진행중","▶",IF($F20="제외",".",IF($F20="보류","◇","■")))),"") | R20: =IF(AND(11>=$D20,11<=$E20),IF($F20="완료","●",IF($F20="진행중","▶",IF($F20="제외",".",IF($F20="보류","◇","■")))),"") | S20: =IF(AND(12>=$D20,12<=$E20),IF($F20="완료","●",IF($F20="진행중","▶",IF($F20="제외",".",IF($F20="보류","◇","■")))),"") | T20: =IF(AND(13>=$D20,13<=$E20),IF($F20="완료","●",IF($F20="진행중","▶",IF($F20="제외",".",IF($F20="보류","◇","■")))),"") | U20: =IF(AND(14>=$D20,14<=$E20),IF($F20="완료","●",IF($F20="진행중","▶",IF($F20="제외",".",IF($F20="보류","◇","■")))),"") | V20: =IF(AND(15>=$D20,15<=$E20),IF($F20="완료","●",IF($F20="진행중","▶",IF($F20="제외",".",IF($F20="보류","◇","■")))),"")
A21: 스프린트 | B21: S-R1 매뉴얼·설치 | C21: 공동 | D21: 14 | E21: 14 | F21: 대기 | H21: =IF(AND(1>=$D21,1<=$E21),IF($F21="완료","●",IF($F21="진행중","▶",IF($F21="제외",".",IF($F21="보류","◇","■")))),"") | I21: =IF(AND(2>=$D21,2<=$E21),IF($F21="완료","●",IF($F21="진행중","▶",IF($F21="제외",".",IF($F21="보류","◇","■")))),"") | J21: =IF(AND(3>=$D21,3<=$E21),IF($F21="완료","●",IF($F21="진행중","▶",IF($F21="제외",".",IF($F21="보류","◇","■")))),"") | K21: =IF(AND(4>=$D21,4<=$E21),IF($F21="완료","●",IF($F21="진행중","▶",IF($F21="제외",".",IF($F21="보류","◇","■")))),"") | L21: =IF(AND(5>=$D21,5<=$E21),IF($F21="완료","●",IF($F21="진행중","▶",IF($F21="제외",".",IF($F21="보류","◇","■")))),"") | M21: =IF(AND(6>=$D21,6<=$E21),IF($F21="완료","●",IF($F21="진행중","▶",IF($F21="제외",".",IF($F21="보류","◇","■")))),"") | N21: =IF(AND(7>=$D21,7<=$E21),IF($F21="완료","●",IF($F21="진행중","▶",IF($F21="제외",".",IF($F21="보류","◇","■")))),"") | O21: =IF(AND(8>=$D21,8<=$E21),IF($F21="완료","●",IF($F21="진행중","▶",IF($F21="제외",".",IF($F21="보류","◇","■")))),"") | P21: =IF(AND(9>=$D21,9<=$E21),IF($F21="완료","●",IF($F21="진행중","▶",IF($F21="제외",".",IF($F21="보류","◇","■")))),"") | Q21: =IF(AND(10>=$D21,10<=$E21),IF($F21="완료","●",IF($F21="진행중","▶",IF($F21="제외",".",IF($F21="보류","◇","■")))),"") | R21: =IF(AND(11>=$D21,11<=$E21),IF($F21="완료","●",IF($F21="진행중","▶",IF($F21="제외",".",IF($F21="보류","◇","■")))),"") | S21: =IF(AND(12>=$D21,12<=$E21),IF($F21="완료","●",IF($F21="진행중","▶",IF($F21="제외",".",IF($F21="보류","◇","■")))),"") | T21: =IF(AND(13>=$D21,13<=$E21),IF($F21="완료","●",IF($F21="진행중","▶",IF($F21="제외",".",IF($F21="보류","◇","■")))),"") | U21: =IF(AND(14>=$D21,14<=$E21),IF($F21="완료","●",IF($F21="진행중","▶",IF($F21="제외",".",IF($F21="보류","◇","■")))),"") | V21: =IF(AND(15>=$D21,15<=$E21),IF($F21="완료","●",IF($F21="진행중","▶",IF($F21="제외",".",IF($F21="보류","◇","■")))),"")
A22: 스프린트 | B22: S-R2 시연·발표 | C22: 조찬희 | D22: 15 | E22: 15 | F22: 대기 | H22: =IF(AND(1>=$D22,1<=$E22),IF($F22="완료","●",IF($F22="진행중","▶",IF($F22="제외",".",IF($F22="보류","◇","■")))),"") | I22: =IF(AND(2>=$D22,2<=$E22),IF($F22="완료","●",IF($F22="진행중","▶",IF($F22="제외",".",IF($F22="보류","◇","■")))),"") | J22: =IF(AND(3>=$D22,3<=$E22),IF($F22="완료","●",IF($F22="진행중","▶",IF($F22="제외",".",IF($F22="보류","◇","■")))),"") | K22: =IF(AND(4>=$D22,4<=$E22),IF($F22="완료","●",IF($F22="진행중","▶",IF($F22="제외",".",IF($F22="보류","◇","■")))),"") | L22: =IF(AND(5>=$D22,5<=$E22),IF($F22="완료","●",IF($F22="진행중","▶",IF($F22="제외",".",IF($F22="보류","◇","■")))),"") | M22: =IF(AND(6>=$D22,6<=$E22),IF($F22="완료","●",IF($F22="진행중","▶",IF($F22="제외",".",IF($F22="보류","◇","■")))),"") | N22: =IF(AND(7>=$D22,7<=$E22),IF($F22="완료","●",IF($F22="진행중","▶",IF($F22="제외",".",IF($F22="보류","◇","■")))),"") | O22: =IF(AND(8>=$D22,8<=$E22),IF($F22="완료","●",IF($F22="진행중","▶",IF($F22="제외",".",IF($F22="보류","◇","■")))),"") | P22: =IF(AND(9>=$D22,9<=$E22),IF($F22="완료","●",IF($F22="진행중","▶",IF($F22="제외",".",IF($F22="보류","◇","■")))),"") | Q22: =IF(AND(10>=$D22,10<=$E22),IF($F22="완료","●",IF($F22="진행중","▶",IF($F22="제외",".",IF($F22="보류","◇","■")))),"") | R22: =IF(AND(11>=$D22,11<=$E22),IF($F22="완료","●",IF($F22="진행중","▶",IF($F22="제외",".",IF($F22="보류","◇","■")))),"") | S22: =IF(AND(12>=$D22,12<=$E22),IF($F22="완료","●",IF($F22="진행중","▶",IF($F22="제외",".",IF($F22="보류","◇","■")))),"") | T22: =IF(AND(13>=$D22,13<=$E22),IF($F22="완료","●",IF($F22="진행중","▶",IF($F22="제외",".",IF($F22="보류","◇","■")))),"") | U22: =IF(AND(14>=$D22,14<=$E22),IF($F22="완료","●",IF($F22="진행중","▶",IF($F22="제외",".",IF($F22="보류","◇","■")))),"") | V22: =IF(AND(15>=$D22,15<=$E22),IF($F22="완료","●",IF($F22="진행중","▶",IF($F22="제외",".",IF($F22="보류","◇","■")))),"")
A23: 마일스톤 | B23: M1 분석 완료 | C23: 조찬희 | D23: 3 | E23: 3 | F23: 완료 | H23: =IF(AND(1>=$D23,1<=$E23),IF($F23="완료","●",IF($F23="진행중","▶",IF($F23="제외",".",IF($F23="보류","◇","■")))),"") | I23: =IF(AND(2>=$D23,2<=$E23),IF($F23="완료","●",IF($F23="진행중","▶",IF($F23="제외",".",IF($F23="보류","◇","■")))),"") | J23: =IF(AND(3>=$D23,3<=$E23),IF($F23="완료","●",IF($F23="진행중","▶",IF($F23="제외",".",IF($F23="보류","◇","■")))),"") | K23: =IF(AND(4>=$D23,4<=$E23),IF($F23="완료","●",IF($F23="진행중","▶",IF($F23="제외",".",IF($F23="보류","◇","■")))),"") | L23: =IF(AND(5>=$D23,5<=$E23),IF($F23="완료","●",IF($F23="진행중","▶",IF($F23="제외",".",IF($F23="보류","◇","■")))),"") | M23: =IF(AND(6>=$D23,6<=$E23),IF($F23="완료","●",IF($F23="진행중","▶",IF($F23="제외",".",IF($F23="보류","◇","■")))),"") | N23: =IF(AND(7>=$D23,7<=$E23),IF($F23="완료","●",IF($F23="진행중","▶",IF($F23="제외",".",IF($F23="보류","◇","■")))),"") | O23: =IF(AND(8>=$D23,8<=$E23),IF($F23="완료","●",IF($F23="진행중","▶",IF($F23="제외",".",IF($F23="보류","◇","■")))),"") | P23: =IF(AND(9>=$D23,9<=$E23),IF($F23="완료","●",IF($F23="진행중","▶",IF($F23="제외",".",IF($F23="보류","◇","■")))),"") | Q23: =IF(AND(10>=$D23,10<=$E23),IF($F23="완료","●",IF($F23="진행중","▶",IF($F23="제외",".",IF($F23="보류","◇","■")))),"") | R23: =IF(AND(11>=$D23,11<=$E23),IF($F23="완료","●",IF($F23="진행중","▶",IF($F23="제외",".",IF($F23="보류","◇","■")))),"") | S23: =IF(AND(12>=$D23,12<=$E23),IF($F23="완료","●",IF($F23="진행중","▶",IF($F23="제외",".",IF($F23="보류","◇","■")))),"") | T23: =IF(AND(13>=$D23,13<=$E23),IF($F23="완료","●",IF($F23="진행중","▶",IF($F23="제외",".",IF($F23="보류","◇","■")))),"") | U23: =IF(AND(14>=$D23,14<=$E23),IF($F23="완료","●",IF($F23="진행중","▶",IF($F23="제외",".",IF($F23="보류","◇","■")))),"") | V23: =IF(AND(15>=$D23,15<=$E23),IF($F23="완료","●",IF($F23="진행중","▶",IF($F23="제외",".",IF($F23="보류","◇","■")))),"")
A24: 마일스톤 | B24: M2 설계 완료 | C24: 공동 | D24: 5 | E24: 5 | F24: 대기 | G24: S1 게이트 | H24: =IF(AND(1>=$D24,1<=$E24),IF($F24="완료","●",IF($F24="진행중","▶",IF($F24="제외",".",IF($F24="보류","◇","■")))),"") | I24: =IF(AND(2>=$D24,2<=$E24),IF($F24="완료","●",IF($F24="진행중","▶",IF($F24="제외",".",IF($F24="보류","◇","■")))),"") | J24: =IF(AND(3>=$D24,3<=$E24),IF($F24="완료","●",IF($F24="진행중","▶",IF($F24="제외",".",IF($F24="보류","◇","■")))),"") | K24: =IF(AND(4>=$D24,4<=$E24),IF($F24="완료","●",IF($F24="진행중","▶",IF($F24="제외",".",IF($F24="보류","◇","■")))),"") | L24: =IF(AND(5>=$D24,5<=$E24),IF($F24="완료","●",IF($F24="진행중","▶",IF($F24="제외",".",IF($F24="보류","◇","■")))),"") | M24: =IF(AND(6>=$D24,6<=$E24),IF($F24="완료","●",IF($F24="진행중","▶",IF($F24="제외",".",IF($F24="보류","◇","■")))),"") | N24: =IF(AND(7>=$D24,7<=$E24),IF($F24="완료","●",IF($F24="진행중","▶",IF($F24="제외",".",IF($F24="보류","◇","■")))),"") | O24: =IF(AND(8>=$D24,8<=$E24),IF($F24="완료","●",IF($F24="진행중","▶",IF($F24="제외",".",IF($F24="보류","◇","■")))),"") | P24: =IF(AND(9>=$D24,9<=$E24),IF($F24="완료","●",IF($F24="진행중","▶",IF($F24="제외",".",IF($F24="보류","◇","■")))),"") | Q24: =IF(AND(10>=$D24,10<=$E24),IF($F24="완료","●",IF($F24="진행중","▶",IF($F24="제외",".",IF($F24="보류","◇","■")))),"") | R24: =IF(AND(11>=$D24,11<=$E24),IF($F24="완료","●",IF($F24="진행중","▶",IF($F24="제외",".",IF($F24="보류","◇","■")))),"") | S24: =IF(AND(12>=$D24,12<=$E24),IF($F24="완료","●",IF($F24="진행중","▶",IF($F24="제외",".",IF($F24="보류","◇","■")))),"") | T24: =IF(AND(13>=$D24,13<=$E24),IF($F24="완료","●",IF($F24="진행중","▶",IF($F24="제외",".",IF($F24="보류","◇","■")))),"") | U24: =IF(AND(14>=$D24,14<=$E24),IF($F24="완료","●",IF($F24="진행중","▶",IF($F24="제외",".",IF($F24="보류","◇","■")))),"") | V24: =IF(AND(15>=$D24,15<=$E24),IF($F24="완료","●",IF($F24="진행중","▶",IF($F24="제외",".",IF($F24="보류","◇","■")))),"")
A25: 마일스톤 | B25: M3 수집 슬라이스 | C25: 기경현 | D25: 7 | E25: 7 | F25: 대기 | H25: =IF(AND(1>=$D25,1<=$E25),IF($F25="완료","●",IF($F25="진행중","▶",IF($F25="제외",".",IF($F25="보류","◇","■")))),"") | I25: =IF(AND(2>=$D25,2<=$E25),IF($F25="완료","●",IF($F25="진행중","▶",IF($F25="제외",".",IF($F25="보류","◇","■")))),"") | J25: =IF(AND(3>=$D25,3<=$E25),IF($F25="완료","●",IF($F25="진행중","▶",IF($F25="제외",".",IF($F25="보류","◇","■")))),"") | K25: =IF(AND(4>=$D25,4<=$E25),IF($F25="완료","●",IF($F25="진행중","▶",IF($F25="제외",".",IF($F25="보류","◇","■")))),"") | L25: =IF(AND(5>=$D25,5<=$E25),IF($F25="완료","●",IF($F25="진행중","▶",IF($F25="제외",".",IF($F25="보류","◇","■")))),"") | M25: =IF(AND(6>=$D25,6<=$E25),IF($F25="완료","●",IF($F25="진행중","▶",IF($F25="제외",".",IF($F25="보류","◇","■")))),"") | N25: =IF(AND(7>=$D25,7<=$E25),IF($F25="완료","●",IF($F25="진행중","▶",IF($F25="제외",".",IF($F25="보류","◇","■")))),"") | O25: =IF(AND(8>=$D25,8<=$E25),IF($F25="완료","●",IF($F25="진행중","▶",IF($F25="제외",".",IF($F25="보류","◇","■")))),"") | P25: =IF(AND(9>=$D25,9<=$E25),IF($F25="완료","●",IF($F25="진행중","▶",IF($F25="제외",".",IF($F25="보류","◇","■")))),"") | Q25: =IF(AND(10>=$D25,10<=$E25),IF($F25="완료","●",IF($F25="진행중","▶",IF($F25="제외",".",IF($F25="보류","◇","■")))),"") | R25: =IF(AND(11>=$D25,11<=$E25),IF($F25="완료","●",IF($F25="진행중","▶",IF($F25="제외",".",IF($F25="보류","◇","■")))),"") | S25: =IF(AND(12>=$D25,12<=$E25),IF($F25="완료","●",IF($F25="진행중","▶",IF($F25="제외",".",IF($F25="보류","◇","■")))),"") | T25: =IF(AND(13>=$D25,13<=$E25),IF($F25="완료","●",IF($F25="진행중","▶",IF($F25="제외",".",IF($F25="보류","◇","■")))),"") | U25: =IF(AND(14>=$D25,14<=$E25),IF($F25="완료","●",IF($F25="진행중","▶",IF($F25="제외",".",IF($F25="보류","◇","■")))),"") | V25: =IF(AND(15>=$D25,15<=$E25),IF($F25="완료","●",IF($F25="진행중","▶",IF($F25="제외",".",IF($F25="보류","◇","■")))),"")
A26: 마일스톤 | B26: M4 검지 데모 | C26: 기경현 | D26: 9 | E26: 9 | F26: 대기 | H26: =IF(AND(1>=$D26,1<=$E26),IF($F26="완료","●",IF($F26="진행중","▶",IF($F26="제외",".",IF($F26="보류","◇","■")))),"") | I26: =IF(AND(2>=$D26,2<=$E26),IF($F26="완료","●",IF($F26="진행중","▶",IF($F26="제외",".",IF($F26="보류","◇","■")))),"") | J26: =IF(AND(3>=$D26,3<=$E26),IF($F26="완료","●",IF($F26="진행중","▶",IF($F26="제외",".",IF($F26="보류","◇","■")))),"") | K26: =IF(AND(4>=$D26,4<=$E26),IF($F26="완료","●",IF($F26="진행중","▶",IF($F26="제외",".",IF($F26="보류","◇","■")))),"") | L26: =IF(AND(5>=$D26,5<=$E26),IF($F26="완료","●",IF($F26="진행중","▶",IF($F26="제외",".",IF($F26="보류","◇","■")))),"") | M26: =IF(AND(6>=$D26,6<=$E26),IF($F26="완료","●",IF($F26="진행중","▶",IF($F26="제외",".",IF($F26="보류","◇","■")))),"") | N26: =IF(AND(7>=$D26,7<=$E26),IF($F26="완료","●",IF($F26="진행중","▶",IF($F26="제외",".",IF($F26="보류","◇","■")))),"") | O26: =IF(AND(8>=$D26,8<=$E26),IF($F26="완료","●",IF($F26="진행중","▶",IF($F26="제외",".",IF($F26="보류","◇","■")))),"") | P26: =IF(AND(9>=$D26,9<=$E26),IF($F26="완료","●",IF($F26="진행중","▶",IF($F26="제외",".",IF($F26="보류","◇","■")))),"") | Q26: =IF(AND(10>=$D26,10<=$E26),IF($F26="완료","●",IF($F26="진행중","▶",IF($F26="제외",".",IF($F26="보류","◇","■")))),"") | R26: =IF(AND(11>=$D26,11<=$E26),IF($F26="완료","●",IF($F26="진행중","▶",IF($F26="제외",".",IF($F26="보류","◇","■")))),"") | S26: =IF(AND(12>=$D26,12<=$E26),IF($F26="완료","●",IF($F26="진행중","▶",IF($F26="제외",".",IF($F26="보류","◇","■")))),"") | T26: =IF(AND(13>=$D26,13<=$E26),IF($F26="완료","●",IF($F26="진행중","▶",IF($F26="제외",".",IF($F26="보류","◇","■")))),"") | U26: =IF(AND(14>=$D26,14<=$E26),IF($F26="완료","●",IF($F26="진행중","▶",IF($F26="제외",".",IF($F26="보류","◇","■")))),"") | V26: =IF(AND(15>=$D26,15<=$E26),IF($F26="완료","●",IF($F26="진행중","▶",IF($F26="제외",".",IF($F26="보류","◇","■")))),"")
A27: 마일스톤 | B27: M5 MVP 기능 동결 | C27: 공동 | D27: 11 | E27: 11 | F27: 대기 | H27: =IF(AND(1>=$D27,1<=$E27),IF($F27="완료","●",IF($F27="진행중","▶",IF($F27="제외",".",IF($F27="보류","◇","■")))),"") | I27: =IF(AND(2>=$D27,2<=$E27),IF($F27="완료","●",IF($F27="진행중","▶",IF($F27="제외",".",IF($F27="보류","◇","■")))),"") | J27: =IF(AND(3>=$D27,3<=$E27),IF($F27="완료","●",IF($F27="진행중","▶",IF($F27="제외",".",IF($F27="보류","◇","■")))),"") | K27: =IF(AND(4>=$D27,4<=$E27),IF($F27="완료","●",IF($F27="진행중","▶",IF($F27="제외",".",IF($F27="보류","◇","■")))),"") | L27: =IF(AND(5>=$D27,5<=$E27),IF($F27="완료","●",IF($F27="진행중","▶",IF($F27="제외",".",IF($F27="보류","◇","■")))),"") | M27: =IF(AND(6>=$D27,6<=$E27),IF($F27="완료","●",IF($F27="진행중","▶",IF($F27="제외",".",IF($F27="보류","◇","■")))),"") | N27: =IF(AND(7>=$D27,7<=$E27),IF($F27="완료","●",IF($F27="진행중","▶",IF($F27="제외",".",IF($F27="보류","◇","■")))),"") | O27: =IF(AND(8>=$D27,8<=$E27),IF($F27="완료","●",IF($F27="진행중","▶",IF($F27="제외",".",IF($F27="보류","◇","■")))),"") | P27: =IF(AND(9>=$D27,9<=$E27),IF($F27="완료","●",IF($F27="진행중","▶",IF($F27="제외",".",IF($F27="보류","◇","■")))),"") | Q27: =IF(AND(10>=$D27,10<=$E27),IF($F27="완료","●",IF($F27="진행중","▶",IF($F27="제외",".",IF($F27="보류","◇","■")))),"") | R27: =IF(AND(11>=$D27,11<=$E27),IF($F27="완료","●",IF($F27="진행중","▶",IF($F27="제외",".",IF($F27="보류","◇","■")))),"") | S27: =IF(AND(12>=$D27,12<=$E27),IF($F27="완료","●",IF($F27="진행중","▶",IF($F27="제외",".",IF($F27="보류","◇","■")))),"") | T27: =IF(AND(13>=$D27,13<=$E27),IF($F27="완료","●",IF($F27="진행중","▶",IF($F27="제외",".",IF($F27="보류","◇","■")))),"") | U27: =IF(AND(14>=$D27,14<=$E27),IF($F27="완료","●",IF($F27="진행중","▶",IF($F27="제외",".",IF($F27="보류","◇","■")))),"") | V27: =IF(AND(15>=$D27,15<=$E27),IF($F27="완료","●",IF($F27="진행중","▶",IF($F27="제외",".",IF($F27="보류","◇","■")))),"")
A28: 마일스톤 | B28: M6 시험 완료 | C28: 공동 | D28: 13 | E28: 13 | F28: 대기 | H28: =IF(AND(1>=$D28,1<=$E28),IF($F28="완료","●",IF($F28="진행중","▶",IF($F28="제외",".",IF($F28="보류","◇","■")))),"") | I28: =IF(AND(2>=$D28,2<=$E28),IF($F28="완료","●",IF($F28="진행중","▶",IF($F28="제외",".",IF($F28="보류","◇","■")))),"") | J28: =IF(AND(3>=$D28,3<=$E28),IF($F28="완료","●",IF($F28="진행중","▶",IF($F28="제외",".",IF($F28="보류","◇","■")))),"") | K28: =IF(AND(4>=$D28,4<=$E28),IF($F28="완료","●",IF($F28="진행중","▶",IF($F28="제외",".",IF($F28="보류","◇","■")))),"") | L28: =IF(AND(5>=$D28,5<=$E28),IF($F28="완료","●",IF($F28="진행중","▶",IF($F28="제외",".",IF($F28="보류","◇","■")))),"") | M28: =IF(AND(6>=$D28,6<=$E28),IF($F28="완료","●",IF($F28="진행중","▶",IF($F28="제외",".",IF($F28="보류","◇","■")))),"") | N28: =IF(AND(7>=$D28,7<=$E28),IF($F28="완료","●",IF($F28="진행중","▶",IF($F28="제외",".",IF($F28="보류","◇","■")))),"") | O28: =IF(AND(8>=$D28,8<=$E28),IF($F28="완료","●",IF($F28="진행중","▶",IF($F28="제외",".",IF($F28="보류","◇","■")))),"") | P28: =IF(AND(9>=$D28,9<=$E28),IF($F28="완료","●",IF($F28="진행중","▶",IF($F28="제외",".",IF($F28="보류","◇","■")))),"") | Q28: =IF(AND(10>=$D28,10<=$E28),IF($F28="완료","●",IF($F28="진행중","▶",IF($F28="제외",".",IF($F28="보류","◇","■")))),"") | R28: =IF(AND(11>=$D28,11<=$E28),IF($F28="완료","●",IF($F28="진행중","▶",IF($F28="제외",".",IF($F28="보류","◇","■")))),"") | S28: =IF(AND(12>=$D28,12<=$E28),IF($F28="완료","●",IF($F28="진행중","▶",IF($F28="제외",".",IF($F28="보류","◇","■")))),"") | T28: =IF(AND(13>=$D28,13<=$E28),IF($F28="완료","●",IF($F28="진행중","▶",IF($F28="제외",".",IF($F28="보류","◇","■")))),"") | U28: =IF(AND(14>=$D28,14<=$E28),IF($F28="완료","●",IF($F28="진행중","▶",IF($F28="제외",".",IF($F28="보류","◇","■")))),"") | V28: =IF(AND(15>=$D28,15<=$E28),IF($F28="완료","●",IF($F28="진행중","▶",IF($F28="제외",".",IF($F28="보류","◇","■")))),"")
A29: 마일스톤 | B29: M7 인도 | C29: 조찬희 | D29: 15 | E29: 15 | F29: 대기 | H29: =IF(AND(1>=$D29,1<=$E29),IF($F29="완료","●",IF($F29="진행중","▶",IF($F29="제외",".",IF($F29="보류","◇","■")))),"") | I29: =IF(AND(2>=$D29,2<=$E29),IF($F29="완료","●",IF($F29="진행중","▶",IF($F29="제외",".",IF($F29="보류","◇","■")))),"") | J29: =IF(AND(3>=$D29,3<=$E29),IF($F29="완료","●",IF($F29="진행중","▶",IF($F29="제외",".",IF($F29="보류","◇","■")))),"") | K29: =IF(AND(4>=$D29,4<=$E29),IF($F29="완료","●",IF($F29="진행중","▶",IF($F29="제외",".",IF($F29="보류","◇","■")))),"") | L29: =IF(AND(5>=$D29,5<=$E29),IF($F29="완료","●",IF($F29="진행중","▶",IF($F29="제외",".",IF($F29="보류","◇","■")))),"") | M29: =IF(AND(6>=$D29,6<=$E29),IF($F29="완료","●",IF($F29="진행중","▶",IF($F29="제외",".",IF($F29="보류","◇","■")))),"") | N29: =IF(AND(7>=$D29,7<=$E29),IF($F29="완료","●",IF($F29="진행중","▶",IF($F29="제외",".",IF($F29="보류","◇","■")))),"") | O29: =IF(AND(8>=$D29,8<=$E29),IF($F29="완료","●",IF($F29="진행중","▶",IF($F29="제외",".",IF($F29="보류","◇","■")))),"") | P29: =IF(AND(9>=$D29,9<=$E29),IF($F29="완료","●",IF($F29="진행중","▶",IF($F29="제외",".",IF($F29="보류","◇","■")))),"") | Q29: =IF(AND(10>=$D29,10<=$E29),IF($F29="완료","●",IF($F29="진행중","▶",IF($F29="제외",".",IF($F29="보류","◇","■")))),"") | R29: =IF(AND(11>=$D29,11<=$E29),IF($F29="완료","●",IF($F29="진행중","▶",IF($F29="제외",".",IF($F29="보류","◇","■")))),"") | S29: =IF(AND(12>=$D29,12<=$E29),IF($F29="완료","●",IF($F29="진행중","▶",IF($F29="제외",".",IF($F29="보류","◇","■")))),"") | T29: =IF(AND(13>=$D29,13<=$E29),IF($F29="완료","●",IF($F29="진행중","▶",IF($F29="제외",".",IF($F29="보류","◇","■")))),"") | U29: =IF(AND(14>=$D29,14<=$E29),IF($F29="완료","●",IF($F29="진행중","▶",IF($F29="제외",".",IF($F29="보류","◇","■")))),"") | V29: =IF(AND(15>=$D29,15<=$E29),IF($F29="완료","●",IF($F29="진행중","▶",IF($F29="제외",".",IF($F29="보류","◇","■")))),"")
A31: 범례 ● 완료 ▶ 진행중 ■ 계획(대기) ◇ 보류 · 제외 | 노란 세로띠 = 대시보드의 현재 주차. 상태(F열)만 바꾸면 막대가 바뀝니다.

Sheet WBS
A1: WBS ID | B1: 단계 | C1: 분류 | D1: 패키지 | E1: 인일 | F1: 시작주 | G1: 종료주 | H1: 담당 | I1: 백로그 | J1: 산출물 | K1: 상태 | L1: 진행률 | M1: 실적종료 | N1: 비고
A2: 1.1 | B2: 프로젝트 관리 | C2: 관리 | D2: 주간 스프린트(목표·리뷰·보드) | E2: 1.5 | F2: 1 | G2: 15 | H2: 조찬희 | J2: 주간 기록 | K2: 진행중 | L2: 0.1 | N2: 15주 분산. 주 1회 리뷰
A3: 1.2 | B3: 프로젝트 관리 | C3: 관리 | D3: 저장소·PR 규칙, 이슈 트래킹 | E3: 0.5 | F3: 4 | G3: 6 | H3: 공동 | J3: CONTRIBUTING 또는 README | K3: 대기 | L3: 0
A4: 1.3 | B4: 프로젝트 관리 | C4: 관리 | D4: 위험·이슈(UTIC, 쿼터, API 장애) | E4: 0.5 | F4: 1 | G4: 15 | H4: 조찬희 | J4: 백로그WBS 7장 갱신 | K4: 진행중 | L4: 0.1 | N4: 전 기간 분산
A5: 1.4 | B5: 프로젝트 관리 | C5: 관리 | D5: 단계 산출물 취합 | E5: 1 | F5: 3 | G5: 15 | H5: 조찬희 | J5: 제출 묶음 | K5: 대기 | L5: 0 | N5: 주 3, 5, 11, 13, 15
A6: 2.1 | B6: 분석 | C6: 분석 | D6: RFP 39건 대응 | E6: 2 | F6: 1 | G6: 2 | H6: 공동 | J6: 제안요청서요구사항대응표.md | K6: 완료 | L6: 1 | M6: 46277
A7: 2.2 | B7: 분석 | C7: 분석 | D7: 범위·목표·데이터 정의 | E7: 2 | F7: 1 | G7: 2 | H7: 공동 | J7: 프로젝트정의서.md | K7: 완료 | L7: 1 | M7: 46277
A8: 2.3 | B8: 분석 | C8: 분석 | D8: 기능/비기능 요구 ID | E8: 2.5 | F8: 2 | G8: 3 | H8: 공동 | J8: 요구사항정의서.md | K8: 완료 | L8: 1 | M8: 46277
A9: 2.4 | B9: 분석 | C9: 분석 | D9: 유스케이스·사용자 스토리 | E9: 2 | F9: 3 | G9: 3 | H9: 조찬희 | J9: 유스케이스사용자스토리.md | K9: 완료 | L9: 1 | M9: 46277
A10: 2.5 | B10: 분석 | C10: 분석 | D10: 제품 백로그·WBS | E10: 1.5 | F10: 3 | G10: 3 | H10: 조찬희 | J10: 백로그WBS.md | K10: 완료 | L10: 1 | M10: 46277 | N10: 본 진행표의 근거
A11: 3.1 | B11: 설계 | C11: 설계 | D11: 스택 확정, 논리 구성도 | E11: 1 | F11: 4 | G11: 4 | H11: 공동 | J11: 아키텍처 1장 | K11: 대기 | L11: 0 | N11: SFR-001, 미결 1. 주 5 말 게이트
A12: 3.2 | B12: 설계 | C12: 설계 | D12: 용량 산정 (표본×주기×보관) | E12: 0.5 | F12: 4 | G12: 4 | H12: 기경현 | J12: 구성도 부록 | K12: 대기 | L12: 0 | N12: FR-SYS-002, NFR-PER-003
A13: 3.3 | B13: 설계 | C13: 설계 | D13: 화면 IA·와이어 (6개 필수 화면) | E13: 2 | F13: 4 | G13: 4 | H13: 조찬희 | J13: 화면설계 | K13: 대기 | L13: 0 | N13: FR-MON, 요구사항 12장
A14: 3.4 | B14: 설계 | C14: 설계 | D14: 개념·논리 ERD, 원본/제공 분리 | E14: 2 | F14: 4 | G14: 5 | H14: 기경현 | J14: ERD | K14: 대기 | L14: 0 | N14: FR-STO-001, FR-CTL-001
A15: 3.5 | B15: 설계 | C15: 설계 | D15: REST API 명세서 (권한 포함) | E15: 1.5 | F15: 5 | G15: 5 | H15: 기경현 | J15: API 명세 | K15: 대기 | L15: 0 | N15: IF-INT-001
A16: 3.6 | B16: 설계 | C16: 설계 | D16: 검증 규칙 명세서 (R01–R12) | E16: 1.5 | F16: 5 | G16: 5 | H16: 기경현 | J16: 규칙 명세 | K16: 대기 | L16: 0 | N16: FR-VAL, 미결 6
A17: 3.7 | B17: 설계 | C17: 설계 | D17: 클릭 가능한 프로토타입 (핵심 3화면) | E17: 1.5 | F17: 5 | G17: 5 | H17: 조찬희 | J17: 프로토타입 | K17: 대기 | L17: 0 | N17: 용량 초과 시 정적 와이어로 축소
A18: 3.8 | B18: 설계 | C18: 설계 | D18: 설계 리뷰·미결 1~7 확정 | E18: 1 | F18: 5 | G18: 5 | H18: 공동 | J18: 리뷰 기록 | K18: 대기 | L18: 0 | N18: 요구사항 13장. S1 시작 조건
A19: 4.1.1 | B19: 구현 | C19: 4.1 기반 환경 | D19: 저장소·실행 환경 | E19: 1 | F19: 6 | G19: 6 | H19: 기경현 | I19: EN-ENV-01 | J19: README 기동 절차 | K19: 대기 | L19: 0 | N19: S1
A20: 4.1.2 | B20: 구현 | C20: 4.1 기반 환경 | D20: 스키마·마이그레이션 | E20: 2 | F20: 6 | G20: 6 | H20: 기경현 | I20: EN-DB-01 | J20: 원본/제공/계획/이슈 테이블 | K20: 대기 | L20: 0 | N20: S1 · 설계 ERD 선행
A21: 4.1.3 | B21: 구현 | C21: 4.1 기반 환경 | D21: API 골격·인증 미들웨어 | E21: 1 | F21: 6 | G21: 6 | H21: 기경현 | I21: EN-API-01 | J21: 헬스체크, 401/403 | K21: 대기 | L21: 0 | N21: S1
A22: 4.1.4 | B22: 구현 | C22: 4.1 기반 환경 | D22: 시드 계정·교차로·계획 | E22: 1 | F22: 6 | G22: 6 | H22: 기경현 | I22: EN-SEED-01 | J22: 시연용 데이터 | K22: 대기 | L22: 0 | N22: S1
A23: 4.1.5 | B23: 구현 | C23: 4.1 기반 환경 | D23: 프론트 셸·라우팅·메뉴 | E23: 1.5 | F23: 6 | G23: 6 | H23: 조찬희 | I23: EN-FE-01 | J23: 로그인 후 빈 대시보드 골격 | K23: 대기 | L23: 0 | N23: S1
A24: 4.1.6 | B24: 구현 | C24: 4.1 기반 환경 | D24: 로그인·RBAC 연동 | E24: 1.5 | F24: 6 | G24: 6 | H24: 공동 | I24: US-ADM-01 | J24: 역할별 메뉴 | K24: 대기 | L24: 0 | N24: S1 Must 3SP
A25: 4.2.1 | B25: 구현 | C25: 4.2 수집 | D25: 맵 수집·인천 마스터 | E25: 1 | F25: 7 | G25: 7 | H25: 기경현 | I25: US-COL-01 | J25: 교차로 마스터 | K25: 대기 | L25: 0 | N25: S2
A26: 4.2.2 | B26: 구현 | C26: 4.2 수집 | D26: 상태 배치 수집·수신 시각 | E26: 2 | F26: 7 | G26: 7 | H26: 기경현 | I26: US-COL-02 | J26: 원본 수신 | K26: 대기 | L26: 0 | N26: S2
A27: 4.2.3 | B27: 구현 | C27: 4.2 수집 | D27: 센티초→초, 점등 코드 정규화 | E27: 0.5 | F27: 7 | G27: 7 | H27: 기경현 | I27: US-COL-04 | J27: 정규화 상태 | K27: 대기 | L27: 0 | N27: S2
A28: 4.2.4 | B28: 구현 | C28: 4.2 수집 | D28: 쿼터 가드·사용량 API | E28: 1 | F28: 7 | G28: 7 | H28: 기경현 | I28: US-COL-05 | J28: 일 5,000 한도 | K28: 대기 | L28: 0 | N28: S2
A29: 4.2.5 | B29: 구현 | C29: 4.2 수집 | D29: 재시도·부분 실패 우선 | E29: 1 | F29: 8 | G29: 8 | H29: 기경현 | I29: US-COL-03 | J29: 실패 큐 | K29: 대기 | L29: 0 | N29: S3
A30: 4.2.6 | B30: 구현 | C30: 4.2 수집 | D30: 수집 대상·주기 설정 UI | E30: 1 | F30: 7 | G30: 7 | H30: 조찬희 | I30: US-ADM-03 | J30: 최소 목록 추가·제외 | K30: 대기 | L30: 0 | N30: S2. 화면은 S6에서 다듬을 수 있음
... A60: 4.8.3 | B60: 구현 | C60: 4.8 계정·설정 | D60: 쿼터 사용량 표시 | E60: 0.5 | F60: 7 | G60: 7 | H60: 조찬희 | I60: US-COL-05 | J60: 설정 화면 숫자 | K60: 대기 | L60: 0 | N60: S2
A61: 5.1 | B61: 테스트 | C61: 시험 | D61: 테스트 계획·케이스 (UC/US/FR) | E61: 1.5 | F61: 12 | G61: 12 | H61: 조찬희 | J61: 테스트 계획서 | K61: 대기 | L61: 0 | N61: S-T1
A62: 5.2 | B62: 테스트 | C62: 시험 | D62: 규칙 단위·경계값 | E62: 1.5 | F62: 12 | G62: 12 | H62: 기경현 | J62: 규칙 결과 | K62: 대기 | L62: 0 | N62: 원본 불변·R06 0건 포함
A63: 5.3 | B63: 테스트 | C63: 시험 | D63: API·권한(403)·원본 불변 | E63: 1.5 | F63: 12 | G63: 12 | H63: 기경현 | J63: API 결과 | K63: 대기 | L63: 0
A64: 5.4 | B64: 테스트 | C64: 시험 | D64: E2E (시나리오 5.1~5.4) | E64: 1.5 | F64: 12 | G64: 13 | H64: 조찬희 | J64: E2E 결과 | K64: 대기 | L64: 0
A65: 5.5 | B65: 테스트 | C65: 시험 | D65: 성능 3초 (대시보드·목록·상세·통계) | E65: 0.5 | F65: 13 | G65: 13 | H65: 공동 | J65: NFR-PER-001 | K65: 대기 | L65: 0 | N65: S-T2
A66: 5.6 | B66: 테스트 | C66: 시험 | D66: 보안 점검표 (해시, 시크릿, 입력) | E66: 0.5 | F66: 13 | G66: 13 | H66: 기경현 | J66: NFR-SEC | K66: 대기 | L66: 0
A67: 5.7 | B67: 테스트 | C67: 시험 | D67: 결함 등록·수정·회귀 | E67: 1 | F67: 13 | G67: 13 | H67: 공동 | J67: 결함 목록 | K67: 대기 | L67: 0 | N67: 치명/주요 0
A68: 6.1 | B68: 안정화·인도 | C68: 인도 | D68: 잔여 결함·Should 여유분 | E68: 2 | F68: 14 | G68: 14 | H68: 공동 | J68: 동결 빌드 | K68: 대기 | L68: 0 | N68: S-R1. 신규 Must 없음
A69: 6.2 | B69: 안정화·인도 | C69: 인도 | D69: 사용자·운영 매뉴얼, 복구 절차 | E69: 1.5 | F69: 14 | G69: 14 | H69: 조찬희 | J69: 매뉴얼 | K69: 대기 | L69: 0
...

Sheet 제품백로그
A1: P | B1: ID | C1: 구분 | D1: 에픽 | E1: 항목 | F1: SP | G1: 목표스프린트 | H1: 주담당 | I1: 부담당 | J1: 선행 | K1: 상태 | L1: 진행률 | M1: 비고
A2: 1 | B2: EN-ENV-01 | C2: EN | D2: 기반 | E2: Git 저장소, 브랜치 규칙, 로컬/Docker 기동 | F2: 3 | G2: S1 | H2: 기경현 | J2: — | K2: 대기 | L2: 0 | M2: README 기동 절차
A3: 1 | B3: EN-DB-01 | C3: EN | D3: 기반 | E3: 논리 엔터티 스키마·마이그레이션 | F3: 5 | G3: S1 | H3: 기경현 | J3: 설계 ERD | K3: 대기 | L3: 0 | M3: 원본/제공/계획/이슈 테이블
A4: 1 | B4: EN-API-01 | C4: EN | D4: 기반 | E4: REST 골격, 인증 미들웨어, 오류 형식 | F4: 3 | G4: S1 | H4: 기경현 | J4: EN-ENV-01 | K4: 대기 | L4: 0 | M4: 헬스체크, 401/403
A5: 1 | B5: EN-SEED-01 | C5: EN | D5: 기반 | E5: 인천 표본 시드, 계획 시드, 관리자/운영자 계정 | F5: 3 | G5: S1 | H5: 기경현 | J5: EN-DB-01 | K5: 대기 | L5: 0 | M5: 시연용 데이터
A6: 1 | B6: EN-FE-01 | C6: EN | D6: 기반 | E6: 앱 셸, 라우팅, 역할별 메뉴, 공통 레이아웃 | F6: 3 | G6: S1 | H6: 조찬희 | J6: EN-API-01 | K6: 대기 | L6: 0 | M6: 로그인 후 빈 대시보드 골격
A7: 10 | B7: US-ADM-01 | C7: Must | D7: E7 계정·설정 | E7: 로그인·RBAC | F7: 3 | G7: S1 | H7: 공동 | J7: EN-API-01, EN-FE-01 | K7: 대기 | L7: 0 | M7: 운영자는 설정 메뉴 없음
