Workbook

Sheet WBS
A1: 작업분류체계 (WBS) — 단계 · 활동 · 작업패키지
A2: =" 확정 계획 "&TEXT(요약!D14,"0.0")&"인일 | 작업패키지 "&TEXT(COUNTIFS($B$5:$B$90,"작업"),"0")&"개 | 진척 "&TEXT(요약!F14,"0%")&" | 현재 "&TEXT(표지!C16,"0")&"주차 | 주 최대 부하 "&TEXT(MAX(요약!C36:C50),"0.0")&"인일 | 파란 배경 행은 수식(합계)이므로 직접 고치지 마세요."
A4: WBS ID | B4: 구분 | C4: 작업 항목 | D4: 단계 | E4: 활동 | F4: 인일 | G4: 시작주 | H4: 종료주 | I4: 시작일 | J4: 종료일 | K4: 담당 | L4: 선행 작업 | M4: 산출물 | N4: 관련 백로그 | O4: 상태 | P4: 진행률 | Q4: 획득인일 | R4: 비고
A5: 1 | B5: 단계 | C5: 프로젝트 관리 | D5: 프로젝트 관리 | F5: =SUMIFS($F$5:$F$90,$B$5:$B$90,"작업",$D$5:$D$90,$D5,$O$5:$O$90,"<>제외",$O$5:$O$90,"<>보류") | G5: =MIN(G6:G9) | H5: =MAX(H6:H9) | I5: =표지!$C$15+7*(G5-1) | J5: =표지!$C$15+7*(H5-1)+6 | K5: 공동 | O5: =IF($F5=0,"-",IF($Q5>=$F5,"완료",IF($Q5>0,"진행중","대기"))) | P5: =IF($F5=0,0,$Q5/$F5) | Q5: =SUMIFS($Q$5:$Q$90,$B$5:$B$90,"작업",$D$5:$D$90,$D5,$O$5:$O$90,"<>제외",$O$5:$O$90,"<>보류") | R5: =TEXT(COUNTIFS($B$5:$B$90,"작업",$D$5:$D$90,$D5),"0")&"개 작업패키지 합계"
A6: 1.1 | B6: 작업 | C6: 주간 스프린트 운영(목표·리뷰·보드) | D6: 프로젝트 관리 | F6: 1.5 | G6: 1 | H6: 15 | I6: =표지!$C$15+7*(G6-1) | J6: =표지!$C$15+7*(H6-1)+6 | K6: 조찬희 | L6: - | M6: 주간 기록 | O6: 진행중 | P6: 0.1 | Q6: =IF(OR($O6="제외",$O6="보류"),0,$F6*$P6) | R6: 15주 분산, 주 1회 리뷰
A7: 1.2 | B7: 작업 | C7: 저장소·PR 규칙, 이슈 트래킹 | D7: 프로젝트 관리 | F7: 0.5 | G7: 4 | H7: 6 | I7: =표지!$C$15+7*(G7-1) | J7: =표지!$C$15+7*(H7-1)+6 | K7: 공동 | L7: 1.1 | M7: CONTRIBUTING/README | O7: 대기 | P7: 0 | Q7: =IF(OR($O7="제외",$O7="보류"),0,$F7*$P7) | R7: 3주 분산
A8: 1.3 | B8: 작업 | C8: 위험·이슈 추적(UTIC, 쿼터, API 장애) | D8: 프로젝트 관리 | F8: 0.5 | G8: 1 | H8: 15 | I8: =표지!$C$15+7*(G8-1) | J8: =표지!$C$15+7*(H8-1)+6 | K8: 조찬희 | L8: - | M8: 위험 대장 | O8: 진행중 | P8: 0.1 | Q8: =IF(OR($O8="제외",$O8="보류"),0,$F8*$P8) | R8: 전 기간 분산
A9: 1.4 | B9: 작업 | C9: 단계 산출물 취합·제출 | D9: 프로젝트 관리 | F9: 1 | G9: 3 | H9: 15 | I9: =표지!$C$15+7*(G9-1) | J9: =표지!$C$15+7*(H9-1)+6 | K9: 조찬희 | L9: 2.5 | M9: 제출 묶음 | O9: 대기 | P9: 0 | Q9: =IF(OR($O9="제외",$O9="보류"),0,$F9*$P9) | R9: 주 3·5·11·13·15
A10: 2 | B10: 단계 | C10: 분석 | D10: 분석 | F10: =SUMIFS($F$5:$F$90,$B$5:$B$90,"작업",$D$5:$D$90,$D10,$O$5:$O$90,"<>제외",$O$5:$O$90,"<>보류") | G10: =MIN(G11:G15) | H10: =MAX(H11:H15) | I10: =표지!$C$15+7*(G10-1) | J10: =표지!$C$15+7*(H10-1)+6 | K10: 공동 | O10: =IF($F10=0,"-",IF($Q10>=$F10,"완료",IF($Q10>0,"진행중","대기"))) | P10: =IF($F10=0,0,$Q10/$F10) | Q10: =SUMIFS($Q$5:$Q$90,$B$5:$B$90,"작업",$D$5:$D$90,$D10,$O$5:$O$90,"<>제외",$O$5:$O$90,"<>보류") | R10: =TEXT(COUNTIFS($B$5:$B$90,"작업",$D$5:$D$90,$D10),"0")&"개 작업패키지 합계"
A11: 2.1 | B11: 작업 | C11: RFP 39건 요구사항 대응 | D11: 분석 | F11: 2 | G11: 1 | H11: 2 | I11: =표지!$C$15+7*(G11-1) | J11: =표지!$C$15+7*(H11-1)+6 | K11: 공동 | L11: - | M11: 제안요청서요구사항대응표.md | O11: 완료 | P11: 1 | Q11: =IF(OR($O11="제외",$O11="보류"),0,$F11*$P11)
A12: 2.2 | B12: 작업 | C12: 범위·목표·데이터 정의 | D12: 분석 | F12: 2 | G12: 1 | H12: 1 | I12: =표지!$C$15+7*(G12-1) | J12: =표지!$C$15+7*(H12-1)+6 | K12: 공동 | L12: - | M12: 프로젝트정의서.md | O12: 완료 | P12: 1 | Q12: =IF(OR($O12="제외",$O12="보류"),0,$F12*$P12)
A13: 2.3 | B13: 작업 | C13: 기능/비기능 요구 ID 정의 | D13: 분석 | F13: 2.5 | G13: 2 | H13: 3 | I13: =표지!$C$15+7*(G13-1) | J13: =표지!$C$15+7*(H13-1)+6 | K13: 공동 | L13: 2.1, 2.2 | M13: 요구사항정의서.md | N13: FR/NFR | O13: 완료 | P13: 1 | Q13: =IF(OR($O13="제외",$O13="보류"),0,$F13*$P13)
A14: 2.4 | B14: 작업 | C14: 유스케이스·사용자 스토리 | D14: 분석 | F14: 2 | G14: 2 | H14: 3 | I14: =표지!$C$15+7*(G14-1) | J14: =표지!$C$15+7*(H14-1)+6 | K14: 조찬희 | L14: 2.3 | M14: 유스케이스사용자스토리.md | N14: UC/US | O14: 완료 | P14: 1 | Q14: =IF(OR($O14="제외",$O14="보류"),0,$F14*$P14) | R14: 수용 기준 정본
A15: 2.5 | B15: 작업 | C15: 제품 백로그·WBS 수립 | D15: 분석 | F15: 1.5 | G15: 3 | H15: 3 | I15: =표지!$C$15+7*(G15-1) | J15: =표지!$C$15+7*(H15-1)+6 | K15: 조찬희 | L15: 2.4 | M15: 백로그WBS.md | O15: 완료 | P15: 1 | Q15: =IF(OR($O15="제외",$O15="보류"),0,$F15*$P15) | R15: 본 WBS의 근거
A16: 3 | B16: 단계 | C16: 설계 | D16: 설계 | F16: =SUMIFS($F$5:$F$90,$B$5:$B$90,"작업",$D$5:$D$90,$D16,$O$5:$O$90,"<>제외",$O$5:$O$90,"<>보류") | G16: =MIN(G17:G24) | H16: =MAX(H17:H24) | I16: =표지!$C$15+7*(G16-1) | J16: =표지!$C$15+7*(H16-1)+6 | K16: 공동 | O16: =IF($F16=0,"-",IF($Q16>=$F16,"완료",IF($Q16>0,"진행중","대기"))) | P16: =IF($F16=0,0,$Q16/$F16) | Q16: =SUMIFS($Q$5:$Q$90,$B$5:$B$90,"작업",$D$5:$D$90,$D16,$O$5:$O$90,"<>제외",$O$5:$O$90,"<>보류") | R16: =TEXT(COUNTIFS($B$5:$B$90,"작업",$D$5:$D$90,$D16),"0")&"개 작업패키지 합계"
A17: 3.1 | B17: 작업 | C17: 스택 확정, 논리 구성도 | D17: 설계 | F17: 1 | G17: 4 | H17: 4 | I17: =표지!$C$15+7*(G17-1) | J17: =표지!$C$15+7*(H17-1)+6 | K17: 공동 | L17: 2.5 | M17: 아키텍처 1장 | N17: SFR-001 | O17: 대기 | P17: 0 | Q17: =IF(OR($O17="제외",$O17="보류"),0,$F17*$P17) | R17: 미결 1
A18: 3.2 | B18: 작업 | C18: 용량 산정(표본×주기×보관) | D18: 설계 | F18: 0.5 | G18: 4 | H18: 4 | I18: =표지!$C$15+7*(G18-1) | J18: =표지!$C$15+7*(H18-1)+6 | K18: 기경현 | L18: 3.1 | M18: 구성도 부록 | N18: FR-SYS-002 | O18: 대기 | P18: 0 | Q18: =IF(OR($O18="제외",$O18="보류"),0,$F18*$P18) | R18: NFR-PER-003
A19: 3.3 | B19: 작업 | C19: 화면 IA·와이어(필수 6화면) | D19: 설계 | F19: 1 | G19: 4 | H19: 5 | I19: =표지!$C$15+7*(G19-1) | J19: =표지!$C$15+7*(H19-1)+6 | K19: 조찬희 | L19: 2.4 | M19: 화면설계 | N19: FR-MON | O19: 대기 | P19: 0 | Q19: =IF(OR($O19="제외",$O19="보류"),0,$F19*$P19) | R19: 재추정 2.0→1.0, 2주 분산
A20: 3.4 | B20: 작업 | C20: 개념·논리 ERD, 원본/제공 분리 | D20: 설계 | F20: 1.5 | G20: 4 | H20: 5 | I20: =표지!$C$15+7*(G20-1) | J20: =표지!$C$15+7*(H20-1)+6 | K20: 기경현 | L20: 3.1 | M20: ERD | N20: FR-STO-001 | O20: 대기 | P20: 0 | Q20: =IF(OR($O20="제외",$O20="보류"),0,$F20*$P20) | R20: 재추정 2.0→1.5, 2주 분산
A21: 3.5 | B21: 작업 | C21: REST API 명세서(권한 포함) | D21: 설계 | F21: 1 | G21: 4 | H21: 5 | I21: =표지!$C$15+7*(G21-1) | J21: =표지!$C$15+7*(H21-1)+6 | K21: 기경현 | L21: 3.4 | M21: API 명세 | N21: IF-INT-001 | O21: 대기 | P21: 0 | Q21: =IF(OR($O21="제외",$O21="보류"),0,$F21*$P21) | R21: 재추정 1.5→1.0, 2주 분산
A22: 3.6 | B22: 작업 | C22: 검증 규칙 임계 기본값 표(R01–R12) | D22: 설계 | F22: 0.5 | G22: 5 | H22: 5 | I22: =표지!$C$15+7*(G22-1) | J22: =표지!$C$15+7*(H22-1)+6 | K22: 기경현 | L22: 2.3 | M22: 규칙 명세 | N22: FR-VAL | O22: 대기 | P22: 0 | Q22: =IF(OR($O22="제외",$O22="보류"),0,$F22*$P22) | R22: 재추정 1.5→0.5. 판정 로직은 4.4.1
A23: 3.7 | B23: 작업 | C23: 정적 와이어(핵심 3화면) | D23: 설계 | F23: 0.5 | G23: 5 | H23: 5 | I23: =표지!$C$15+7*(G23-1) | J23: =표지!$C$15+7*(H23-1)+6 | K23: 조찬희 | L23: 3.3 | M23: 와이어 | N23: UC06, UC07 | O23: 대기 | P23: 0 | Q23: =IF(OR($O23="제외",$O23="보류"),0,$F23*$P23) | R23: 재추정 1.5→0.5. 클릭 프로토타입 축소
A24: 3.8 | B24: 작업 | C24: 설계 리뷰·미결 1~7 확정 | D24: 설계 | F24: 0.5 | G24: 5 | H24: 5 | I24: =표지!$C$15+7*(G24-1) | J24: =표지!$C$15+7*(H24-1)+6 | K24: 공동 | L24: 3.1, 3.5, 3.6, 3.7 | M24: 리뷰 기록 | O24: 대기 | P24: 0 | Q24: =IF(OR($O24="제외",$O24="보류"),0,$F24*$P24) | R24: 재추정 1.0→0.5. M2 게이트
A25: 4 | B25: 단계 | C25: 구현 | D25: 구현 | F25: =SUMIFS($F$5:$F$90,$B$5:$B$90,"작업",$D$5:$D$90,$D25,$O$5:$O$90,"<>제외",$O$5:$O$90,"<>보류") | G25: =MIN(G26:G75) | H25: =MAX(H26:H75) | I25: =표지!$C$15+7*(G25-1) | J25: =표지!$C$15+7*(H25-1)+6 | K25: 공동 | O25: =IF($F25=0,"-",IF($Q25>=$F25,"완료",IF($Q25>0,"진행중","대기"))) | P25: =IF($F25=0,0,$Q25/$F25) | Q25: =SUMIFS($Q$5:$Q$90,$B$5:$B$90,"작업",$D$5:$D$90,$D25,$O$5:$O$90,"<>제외",$O$5:$O$90,"<>보류") | R25: =TEXT(COUNTIFS($B$5:$B$90,"작업",$D$5:$D$90,$D25),"0")&"개 작업패키지 합계"
A26: 4.1 | B26: 활동 | C26: 기반 환경 (S1–S2) | D26: 구현 | E26: 기반 환경 (S1–S2) | F26: =SUMIFS($F$5:$F$90,$B$5:$B$90,"작업",$E$5:$E$90,$E26,$O$5:$O$90,"<>제외",$O$5:$O$90,"<>보류") | G26: =MIN(G27:G32) | H26: =MAX(H27:H32) | I26: =표지!$C$15+7*(G26-1) | J26: =표지!$C$15+7*(H26-1)+6 | O26: =IF($F26=0,"-",IF($Q26>=$F26,"완료",IF($Q26>0,"진행중","대기"))) | P26: =IF($F26=0,0,$Q26/$F26) | Q26: =SUMIFS($Q$5:$Q$90,$B$5:$B$90,"작업",$E$5:$E$90,$E26,$O$5:$O$90,"<>제외",$O$5:$O$90,"<>보류") | R26: =TEXT(COUNTIFS($B$5:$B$90,"작업",$E$5:$E$90,$E26),"0")&"개 작업패키지 합계"
A27: 4.1.1 | B27: 작업 | C27: 저장소·실행 환경(로컬/Docker) | D27: 구현 | E27: 기반 환경 (S1–S2) | F27: 0.5 | G27: 6 | H27: 6 | I27: =표지!$C$15+7*(G27-1) | J27: =표지!$C$15+7*(H27-1)+6 | K27: 기경현 | L27: 3.1 | M27: README 기동 절차 | N27: EN-ENV-01 | O27: 대기 | P27: 0 | Q27: =IF(OR($O27="제외",$O27="보류"),0,$F27*$P27) | R27: 재추정 1.0→0.5
A28: 4.1.2 | B28: 작업 | C28: 스키마·마이그레이션 | D28: 구현 | E28: 기반 환경 (S1–S2) | F28: 1.5 | G28: 6 | H28: 6 | I28: =표지!$C$15+7*(G28-1) | J28: =표지!$C$15+7*(H28-1)+6 | K28: 기경현 | L28: 3.4 | M28: 원본/제공/계획/이슈 테이블 | N28: EN-DB-01 | O28: 대기 | P28: 0 | Q28: =IF(OR($O28="제외",$O28="보류"),0,$F28*$P28) | R28: 재추정 2.0→1.5
A29: 4.1.3 | B29: 작업 | C29: API 골격·인증 미들웨어 | D29: 구현 | E29: 기반 환경 (S1–S2) | F29: 1 | G29: 6 | H29: 6 | I29: =표지!$C$15+7*(G29-1) | J29: =표지!$C$15+7*(H29-1)+6 | K29: 기경현 | L29: 4.1.1, 3.5 | M29: 헬스체크, 401/403 | N29: EN-API-01 | O29: 대기 | P29: 0 | Q29: =IF(OR($O29="제외",$O29="보류"),0,$F29*$P29)
A30: 4.1.4 | B30: 작업 | C30: 시드(계정·교차로·계획) | D30: 구현 | E30: 기반 환경 (S1–S2) | F30: 0.5 | G30: 6 | H30: 7 | I30: =표지!$C$15+7*(G30-1) | J30: =표지!$C$15+7*(H30-1)+6 | K30: 기경현 | L30: 4.1.2 | M30: 시연용 데이터 | N30: EN-SEED-01 | O30: 대기 | P30: 0 | Q30: =IF(OR($O30="제외",$O30="보류"),0,$F30*$P30) | R30: 재추정 1.0→0.5, 2주 분산
A31: 4.1.5 | B31: 작업 | C31: 프론트 셸·라우팅·역할별 메뉴 | D31: 구현 | E31: 기반 환경 (S1–S2) | F31: 1.5 | G31: 6 | H31: 6 | I31: =표지!$C$15+7*(G31-1) | J31: =표지!$C$15+7*(H31-1)+6 | K31: 조찬희 | L31: 4.1.3, 3.3 | M31: 빈 대시보드 골격 | N31: EN-FE-01 | O31: 대기 | P31: 0 | Q31: =IF(OR($O31="제외",$O31="보류"),0,$F31*$P31)
A32: 4.1.6 | B32: 작업 | C32: 로그인·RBAC 연동 | D32: 구현 | E32: 기반 환경 (S1–S2) | F32: 1 | G32: 6 | H32: 7 | I32: =표지!$C$15+7*(G32-1) | J32: =표지!$C$15+7*(H32-1)+6 | K32: 공동 | L32: 4.1.3, 4.1.5 | M32: 역할별 접근 제어 | N32: US-ADM-01 | O32: 대기 | P32: 0 | Q32: =IF(OR($O32="제외",$O32="보류"),0,$F32*$P32) | R32: 재추정 1.5→1.0, S1–S2 분산
A33: 4.2 | B33: 활동 | C33: 수집 (S2–S3) | D33: 구현 | E33: 수집 (S2–S3) | F33: =SUMIFS($F$5:$F$90,$B$5:$B$90,"작업",$E$5:$E$90,$E33,$O$5:$O$90,"<>제외",$O$5:$O$90,"<>보류") | G33: =MIN(G34:G39) | H33: =MAX(H34:H39) | I33: =표지!$C$15+7*(G33-1) | J33: =표지!$C$15+7*(H33-1)+6 | O33: =IF($F33=0,"-",IF($Q33>=$F33,"완료",IF($Q33>0,"진행중","대기"))) | P33: =IF($F33=0,0,$Q33/$F33) | Q33: =SUMIFS($Q$5:$Q$90,$B$5:$B$90,"작업",$E$5:$E$90,$E33,$O$5:$O$90,"<>제외",$O$5:$O$90,"<>보류") | R33: =TEXT(COUNTIFS($B$5:$B$90,"작업",$E$5:$E$90,$E33),"0")&"개 작업패키지 합계"
A34: 4.2.1 | B34: 작업 | C34: 교차로 맵 수집·인천 마스터 | D34: 구현 | E34: 수집 (S2–S3) | F34: 0.5 | G34: 7 | H34: 7 | I34: =표지!$C$15+7*(G34-1) | J34: =표지!$C$15+7*(H34-1)+6 | K34: 기경현 | L34: 4.1.2, 4.2.6 | M34: 교차로 마스터 | N34: US-COL-01 | O34: 대기 | P34: 0 | Q34: =IF(OR($O34="제외",$O34="보류"),0,$F34*$P34) | R34: 재추정 1.0→0.5
A35: 4.2.2 | B35: 작업 | C35: 실시간 상태 배치 수집·수신 시각 | D35: 구현 | E35: 수집 (S2–S3) | F35: 1 | G35: 7 | H35: 7 | I35: =표지!$C$15+7*(G35-1) | J35: =표지!$C$15+7*(H35-1)+6 | K35: 기경현 | L35: 4.2.1 | M35: 원본 수신 적재 | N35: US-COL-02 | O35: 대기 | P35: 0 | Q35: =IF(OR($O35="제외",$O35="보류"),0,$F35*$P35) | R35: 재추정 2.0→1.0. 원본 불변
A36: 4.2.3 | B36: 작업 | C36: 수신 정규화(센티초→초, 점등 코드) | D36: 구현 | E36: 수집 (S2–S3) | F36: 0.5 | G36: 7 | H36: 7 | I36: =표지!$C$15+7*(G36-1) | J36: =표지!$C$15+7*(H36-1)+6 | K36: 기경현 | L36: 4.2.2 | M36: 정규화 상태 | N36: US-COL-04 | O36: 대기 | P36: 0 | Q36: =IF(OR($O36="제외",$O36="보류"),0,$F36*$P36)
A37: 4.2.4 | B37: 작업 | C37: 쿼터 가드·사용량 API | D37: 구현 | E37: 수집 (S2–S3) | F37: 0.5 | G37: 7 | H37: 7 | I37: =표지!$C$15+7*(G37-1) | J37: =표지!$C$15+7*(H37-1)+6 | K37: 기경현 | L37: 4.2.2 | M37: 일 5,000 한도 준수 | N37: US-COL-05 | O37: 대기 | P37: 0 | Q37: =IF(OR($O37="제외",$O37="보류"),0,$F37*$P37) | R37: 재추정 1.0→0.5. 자르지 않음
A38: 4.2.5 | B38: 작업 | C38: 실패 재시도·부분 실패 우선 | D38: 구현 | E38: 수집 (S2–S3) | F38: 0.5 | G38: 8 | H38: 8 | I38: =표지!$C$15+7*(G38-1) | J38: =표지!$C$15+7*(H38-1)+6 | K38: 기경현 | L38: 4.2.2 | M38: 실패 큐 | N38: US-COL-03 | O38: 대기 | P38: 0 | Q38: =IF(OR($O38="제외",$O38="보류"),0,$F38*$P38) | R38: 재추정 1.0→0.5
A39: 4.2.6 | B39: 작업 | C39: 수집 대상·주기 설정 UI | D39: 구현 | E39: 수집 (S2–S3) | F39: 1 | G39: 7 | H39: 7 | I39: =표지!$C$15+7*(G39-1) | J39: =표지!$C$15+7*(H39-1)+6 | K39: 조찬희 | L39: 4.1.6 | M39: 최소 목록 추가·제외 | N39: US-ADM-03 | O39: 대기 | P39: 0 | Q39: =IF(OR($O39="제외",$O39="보류"),0,$F39*$P39)
A40: 4.3 | B40: 활동 | C40: 계획 (S2–S3, S5) | D40: 구현 | E40: 계획 (S2–S3, S5) | F40: =SUMIFS($F$5:$F$90,$B$5:$B$90,"작업",$E$5:$E$90,$E40,$O$5:$O$90,"<>제외",$O$5:$O$90,"<>보류") | G40: =MIN(G41:G45) | H40: =MAX(H41:H45) | I40: =표지!$C$15+7*(G40-1) | J40: =표지!$C$15+7*(H40-1)+6 | O40: =IF($F40=0,"-",IF($Q40>=$F40,"완료",IF($Q40>0,"진행중","대기"))) | P40: =IF($F40=0,0,$Q40/$F40) | Q40: =SUMIFS($Q$5:$Q$90,$B$5:$B$90,"작업",$E$5:$E$90,$E40,$O$5:$O$90,"<>제외",$O$5:$O$90,"<>보류") | R40: =TEXT(COUNTIFS($B$5:$B$90,"작업",$E$5:$E$90,$E40),"0")&"개 작업패키지 합계"
A41: 4.3.1 | B41: 작업 | C41: 정규화 계획 스키마·적재 | D41: 구현 | E41: 계획 (S2–S3, S5) | F41: 0.5 | G41: 7 | H41: 7 | I41: =표지!$C$15+7*(G41-1) | J41: =표지!$C$15+7*(H41-1)+6 | K41: 기경현 | L41: 4.1.2 | M41: signal_plan | N41: US-PLN-01 | O41: 대기 | P41: 0 | Q41: =IF(OR($O41="제외",$O41="보류"),0,$F41*$P41) | R41: 재추정 1.0→0.5. S3→S2 선행
...

Sheet 간트
A1: 주차별 일정 (15주)
A2: 범례 ● 완료 ▶ 진행중 ■ 계획 ◇ 보류 · 제외 노란 세로 띠 = 현재 주차 (표지 기준일 기준)
A3: WBS ID | B3: 작업 항목 | C3: 담당 | D3: 시작주 | E3: 종료주 | F3: 상태 | G3: 진행률 | H3: 1 | I3: 2 | J3: 3 | K3: 4 | L3: 5 | M3: 6 | N3: 7 | O3: 8 | P3: 9 | Q3: 10 | R3: 11 | S3: 12 | T3: 13 | U3: 14 | V3: 15
A4: 주 시작일 → | H4: =표지!$C$15+7*(1-1) | I4: =표지!$C$15+7*(2-1) | J4: =표지!$C$15+7*(3-1) | K4: =표지!$C$15+7*(4-1) | L4: =표지!$C$15+7*(5-1) | M4: =표지!$C$15+7*(6-1) | N4: =표지!$C$15+7*(7-1) | O4: =표지!$C$15+7*(8-1) | P4: =표지!$C$15+7*(9-1) | Q4: =표지!$C$15+7*(10-1) | R4: =표지!$C$15+7*(11-1) | S4: =표지!$C$15+7*(12-1) | T4: =표지!$C$15+7*(13-1) | U4: =표지!$C$15+7*(14-1) | V4: =표지!$C$15+7*(15-1)
A5: =WBS!A5 | B5: =WBS!C5 | C5: =WBS!K5 | D5: =WBS!G5 | E5: =WBS!H5 | F5: =WBS!O5 | G5: =WBS!P5 | H5: =IF(AND(1>=$D5,1<=$E5),IF($F5="완료","●",IF($F5="진행중","▶",IF($F5="제외",".",IF($F5="보류","◇","■")))),"") | I5: =IF(AND(2>=$D5,2<=$E5),IF($F5="완료","●",IF($F5="진행중","▶",IF($F5="제외",".",IF($F5="보류","◇","■")))),"") | J5: =IF(AND(3>=$D5,3<=$E5),IF($F5="완료","●",IF($F5="진행중","▶",IF($F5="제외",".",IF($F5="보류","◇","■")))),"") | K5: =IF(AND(4>=$D5,4<=$E5),IF($F5="완료","●",IF($F5="진행중","▶",IF($F5="제외",".",IF($F5="보류","◇","■")))),"") | L5: =IF(AND(5>=$D5,5<=$E5),IF($F5="완료","●",IF($F5="진행중","▶",IF($F5="제외",".",IF($F5="보류","◇","■")))),"") | M5: =IF(AND(6>=$D5,6<=$E5),IF($F5="완료","●",IF($F5="진행중","▶",IF($F5="제외",".",IF($F5="보류","◇","■")))),"") | N5: =IF(AND(7>=$D5,7<=$E5),IF($F5="완료","●",IF($F5="진행중","▶",IF($F5="제외",".",IF($F5="보류","◇","■")))),"") | O5: =IF(AND(8>=$D5,8<=$E5),IF($F5="완료","●",IF($F5="진행중","▶",IF($F5="제외",".",IF($F5="보류","◇","■")))),"") | P5: =IF(AND(9>=$D5,9<=$E5),IF($F5="완료","●",IF($F5="진행중","▶",IF($F5="제외",".",IF($F5="보류","◇","■")))),"") | Q5: =IF(AND(10>=$D5,10<=$E5),IF($F5="완료","●",IF($F5="진행중","▶",IF($F5="제외",".",IF($F5="보류","◇","■")))),"") | R5: =IF(AND(11>=$D5,11<=$E5),IF($F5="완료","●",IF($F5="진행중","▶",IF($F5="제외",".",IF($F5="보류","◇","■")))),"") | S5: =IF(AND(12>=$D5,12<=$E5),IF($F5="완료","●",IF($F5="진행중","▶",IF($F5="제외",".",IF($F5="보류","◇","■")))),"") | T5: =IF(AND(13>=$D5,13<=$E5),IF($F5="완료","●",IF($F5="진행중","▶",IF($F5="제외",".",IF($F5="보류","◇","■")))),"") | U5: =IF(AND(14>=$D5,14<=$E5),IF($F5="완료","●",IF($F5="진행중","▶",IF($F5="제외",".",IF($F5="보류","◇","■")))),"") | V5: =IF(AND(15>=$D5,15<=$E5),IF($F5="완료","●",IF($F5="진행중","▶",IF($F5="제외",".",IF($F5="보류","◇","■")))),"")
A6: =WBS!A6 | B6: =WBS!C6 | C6: =WBS!K6 | D6: =WBS!G6 | E6: =WBS!H6 | F6: =WBS!O6 | G6: =WBS!P6 | H6: =IF(AND(1>=$D6,1<=$E6),IF($F6="완료","●",IF($F6="진행중","▶",IF($F6="제외",".",IF($F6="보류","◇","■")))),"") | I6: =IF(AND(2>=$D6,2<=$E6),IF($F6="완료","●",IF($F6="진행중","▶",IF($F6="제외",".",IF($F6="보류","◇","■")))),"") | J6: =IF(AND(3>=$D6,3<=$E6),IF($F6="완료","●",IF($F6="진행중","▶",IF($F6="제외",".",IF($F6="보류","◇","■")))),"") | K6: =IF(AND(4>=$D6,4<=$E6),IF($F6="완료","●",IF($F6="진행중","▶",IF($F6="제외",".",IF($F6="보류","◇","■")))),"") | L6: =IF(AND(5>=$D6,5<=$E6),IF($F6="완료","●",IF($F6="진행중","▶",IF($F6="제외",".",IF($F6="보류","◇","■")))),"") | M6: =IF(AND(6>=$D6,6<=$E6),IF($F6="완료","●",IF($F6="진행중","▶",IF($F6="제외",".",IF($F6="보류","◇","■")))),"") | N6: =IF(AND(7>=$D6,7<=$E6),IF($F6="완료","●",IF($F6="진행중","▶",IF($F6="제외",".",IF($F6="보류","◇","■")))),"") | O6: =IF(AND(8>=$D6,8<=$E6),IF($F6="완료","●",IF($F6="진행중","▶",IF($F6="제외",".",IF($F6="보류","◇","■")))),"") | P6: =IF(AND(9>=$D6,9<=$E6),IF($F6="완료","●",IF($F6="진행중","▶",IF($F6="제외",".",IF($F6="보류","◇","■")))),"") | Q6: =IF(AND(10>=$D6,10<=$E6),IF($F6="완료","●",IF($F6="진행중","▶",IF($F6="제외",".",IF($F6="보류","◇","■")))),"") | R6: =IF(AND(11>=$D6,11<=$E6),IF($F6="완료","●",IF($F6="진행중","▶",IF($F6="제외",".",IF($F6="보류","◇","■")))),"") | S6: =IF(AND(12>=$D6,12<=$E6),IF($F6="완료","●",IF($F6="진행중","▶",IF($F6="제외",".",IF($F6="보류","◇","■")))),"") | T6: =IF(AND(13>=$D6,13<=$E6),IF($F6="완료","●",IF($F6="진행중","▶",IF($F6="제외",".",IF($F6="보류","◇","■")))),"") | U6: =IF(AND(14>=$D6,14<=$E6),IF($F6="완료","●",IF($F6="진행중","▶",IF($F6="제외",".",IF($F6="보류","◇","■")))),"") | V6: =IF(AND(15>=$D6,15<=$E6),IF($F6="완료","●",IF($F6="진행중","▶",IF($F6="제외",".",IF($F6="보류","◇","■")))),"")
A7: =WBS!A7 | B7: =WBS!C7 | C7: =WBS!K7 | D7: =WBS!G7 | E7: =WBS!H7 | F7: =WBS!O7 | G7: =WBS!P7 | H7: =IF(AND(1>=$D7,1<=$E7),IF($F7="완료","●",IF($F7="진행중","▶",IF($F7="제외",".",IF($F7="보류","◇","■")))),"") | I7: =IF(AND(2>=$D7,2<=$E7),IF($F7="완료","●",IF($F7="진행중","▶",IF($F7="제외",".",IF($F7="보류","◇","■")))),"") | J7: =IF(AND(3>=$D7,3<=$E7),IF($F7="완료","●",IF($F7="진행중","▶",IF($F7="제외",".",IF($F7="보류","◇","■")))),"") | K7: =IF(AND(4>=$D7,4<=$E7),IF($F7="완료","●",IF($F7="진행중","▶",IF($F7="제외",".",IF($F7="보류","◇","■")))),"") | L7: =IF(AND(5>=$D7,5<=$E7),IF($F7="완료","●",IF($F7="진행중","▶",IF($F7="제외",".",IF($F7="보류","◇","■")))),"") | M7: =IF(AND(6>=$D7,6<=$E7),IF($F7="완료","●",IF($F7="진행중","▶",IF($F7="제외",".",IF($F7="보류","◇","■")))),"") | N7: =IF(AND(7>=$D7,7<=$E7),IF($F7="완료","●",IF($F7="진행중","▶",IF($F7="제외",".",IF($F7="보류","◇","■")))),"") | O7: =IF(AND(8>=$D7,8<=$E7),IF($F7="완료","●",IF($F7="진행중","▶",IF($F7="제외",".",IF($F7="보류","◇","■")))),"") | P7: =IF(AND(9>=$D7,9<=$E7),IF($F7="완료","●",IF($F7="진행중","▶",IF($F7="제외",".",IF($F7="보류","◇","■")))),"") | Q7: =IF(AND(10>=$D7,10<=$E7),IF($F7="완료","●",IF($F7="진행중","▶",IF($F7="제외",".",IF($F7="보류","◇","■")))),"") | R7: =IF(AND(11>=$D7,11<=$E7),IF($F7="완료","●",IF($F7="진행중","▶",IF($F7="제외",".",IF($F7="보류","◇","■")))),"") | S7: =IF(AND(12>=$D7,12<=$E7),IF($F7="완료","●",IF($F7="진행중","▶",IF($F7="제외",".",IF($F7="보류","◇","■")))),"") | T7: =IF(AND(13>=$D7,13<=$E7),IF($F7="완료","●",IF($F7="진행중","▶",IF($F7="제외",".",IF($F7="보류","◇","■")))),"") | U7: =IF(AND(14>=$D7,14<=$E7),IF($F7="완료","●",IF($F7="진행중","▶",IF($F7="제외",".",IF($F7="보류","◇","■")))),"") | V7: =IF(AND(15>=$D7,15<=$E7),IF($F7="완료","●",IF($F7="진행중","▶",IF($F7="제외",".",IF($F7="보류","◇","■")))),"")
A8: =WBS!A8 | B8: =WBS!C8 | C8: =WBS!K8 | D8: =WBS!G8 | E8: =WBS!H8 | F8: =WBS!O8 | G8: =WBS!P8 | H8: =IF(AND(1>=$D8,1<=$E8),IF($F8="완료","●",IF($F8="진행중","▶",IF($F8="제외",".",IF($F8="보류","◇","■")))),"") | I8: =IF(AND(2>=$D8,2<=$E8),IF($F8="완료","●",IF($F8="진행중","▶",IF($F8="제외",".",IF($F8="보류","◇","■")))),"") | J8: =IF(AND(3>=$D8,3<=$E8),IF($F8="완료","●",IF($F8="진행중","▶",IF($F8="제외",".",IF($F8="보류","◇","■")))),"") | K8: =IF(AND(4>=$D8,4<=$E8),IF($F8="완료","●",IF($F8="진행중","▶",IF($F8="제외",".",IF($F8="보류","◇","■")))),"") | L8: =IF(AND(5>=$D8,5<=$E8),IF($F8="완료","●",IF($F8="진행중","▶",IF($F8="제외",".",IF($F8="보류","◇","■")))),"") | M8: =IF(AND(6>=$D8,6<=$E8),IF($F8="완료","●",IF($F8="진행중","▶",IF($F8="제외",".",IF($F8="보류","◇","■")))),"") | N8: =IF(AND(7>=$D8,7<=$E8),IF($F8="완료","●",IF($F8="진행중","▶",IF($F8="제외",".",IF($F8="보류","◇","■")))),"") | O8: =IF(AND(8>=$D8,8<=$E8),IF($F8="완료","●",IF($F8="진행중","▶",IF($F8="제외",".",IF($F8="보류","◇","■")))),"") | P8: =IF(AND(9>=$D8,9<=$E8),IF($F8="완료","●",IF($F8="진행중","▶",IF($F8="제외",".",IF($F8="보류","◇","■")))),"") | Q8: =IF(AND(10>=$D8,10<=$E8),IF($F8="완료","●",IF($F8="진행중","▶",IF($F8="제외",".",IF($F8="보류","◇","■")))),"") | R8: =IF(AND(11>=$D8,11<=$E8),IF($F8="완료","●",IF($F8="진행중","▶",IF($F8="제외",".",IF($F8="보류","◇","■")))),"") | S8: =IF(AND(12>=$D8,12<=$E8),IF($F8="완료","●",IF($F8="진행중","▶",IF($F8="제외",".",IF($F8="보류","◇","■")))),"") | T8: =IF(AND(13>=$D8,13<=$E8),IF($F8="완료","●",IF($F8="진행중","▶",IF($F8="제외",".",IF($F8="보류","◇","■")))),"") | U8: =IF(AND(14>=$D8,14<=$E8),IF($F8="완료","●",IF($F8="진행중","▶",IF($F8="제외",".",IF($F8="보류","◇","■")))),"") | V8: =IF(AND(15>=$D8,15<=$E8),IF($F8="완료","●",IF($F8="진행중","▶",IF($F8="제외",".",IF($F8="보류","◇","■")))),"")
A9: =WBS!A9 | B9: =WBS!C9 | C9: =WBS!K9 | D9: =WBS!G9 | E9: =WBS!H9 | F9: =WBS!O9 | G9: =WBS!P9 | H9: =IF(AND(1>=$D9,1<=$E9),IF($F9="완료","●",IF($F9="진행중","▶",IF($F9="제외",".",IF($F9="보류","◇","■")))),"") | I9: =IF(AND(2>=$D9,2<=$E9),IF($F9="완료","●",IF($F9="진행중","▶",IF($F9="제외",".",IF($F9="보류","◇","■")))),"") | J9: =IF(AND(3>=$D9,3<=$E9),IF($F9="완료","●",IF($F9="진행중","▶",IF($F9="제외",".",IF($F9="보류","◇","■")))),"") | K9: =IF(AND(4>=$D9,4<=$E9),IF($F9="완료","●",IF($F9="진행중","▶",IF($F9="제외",".",IF($F9="보류","◇","■")))),"") | L9: =IF(AND(5>=$D9,5<=$E9),IF($F9="완료","●",IF($F9="진행중","▶",IF($F9="제외",".",IF($F9="보류","◇","■")))),"") | M9: =IF(AND(6>=$D9,6<=$E9),IF($F9="완료","●",IF($F9="진행중","▶",IF($F9="제외",".",IF($F9="보류","◇","■")))),"") | N9: =IF(AND(7>=$D9,7<=$E9),IF($F9="완료","●",IF($F9="진행중","▶",IF($F9="제외",".",IF($F9="보류","◇","■")))),"") | O9: =IF(AND(8>=$D9,8<=$E9),IF($F9="완료","●",IF($F9="진행중","▶",IF($F9="제외",".",IF($F9="보류","◇","■")))),"") | P9: =IF(AND(9>=$D9,9<=$E9),IF($F9="완료","●",IF($F9="진행중","▶",IF($F9="제외",".",IF($F9="보류","◇","■")))),"") | Q9: =IF(AND(10>=$D9,10<=$E9),IF($F9="완료","●",IF($F9="진행중","▶",IF($F9="제외",".",IF($F9="보류","◇","■")))),"") | R9: =IF(AND(11>=$D9,11<=$E9),IF($F9="완료","●",IF($F9="진행중","▶",IF($F9="제외",".",IF($F9="보류","◇","■")))),"") | S9: =IF(AND(12>=$D9,12<=$E9),IF($F9="완료","●",IF($F9="진행중","▶",IF($F9="제외",".",IF($F9="보류","◇","■")))),"") | T9: =IF(AND(13>=$D9,13<=$E9),IF($F9="완료","●",IF($F9="진행중","▶",IF($F9="제외",".",IF($F9="보류","◇","■")))),"") | U9: =IF(AND(14>=$D9,14<=$E9),IF($F9="완료","●",IF($F9="진행중","▶",IF($F9="제외",".",IF($F9="보류","◇","■")))),"") | V9: =IF(AND(15>=$D9,15<=$E9),IF($F9="완료","●",IF($F9="진행중","▶",IF($F9="제외",".",IF($F9="보류","◇","■")))),"")
A10: =WBS!A10 | B10: =WBS!C10 | C10: =WBS!K10 | D10: =WBS!G10 | E10: =WBS!H10 | F10: =WBS!O10 | G10: =WBS!P10 | H10: =IF(AND(1>=$D10,1<=$E10),IF($F10="완료","●",IF($F10="진행중","▶",IF($F10="제외",".",IF($F10="보류","◇","■")))),"") | I10: =IF(AND(2>=$D10,2<=$E10),IF($F10="완료","●",IF($F10="진행중","▶",IF($F10="제외",".",IF($F10="보류","◇","■")))),"") | J10: =IF(AND(3>=$D10,3<=$E10),IF($F10="완료","●",IF($F10="진행중","▶",IF($F10="제외",".",IF($F10="보류","◇","■")))),"") | K10: =IF(AND(4>=$D10,4<=$E10),IF($F10="완료","●",IF($F10="진행중","▶",IF($F10="제외",".",IF($F10="보류","◇","■")))),"") | L10: =IF(AND(5>=$D10,5<=$E10),IF($F10="완료","●",IF($F10="진행중","▶",IF($F10="제외",".",IF($F10="보류","◇","■")))),"") | M10: =IF(AND(6>=$D10,6<=$E10),IF($F10="완료","●",IF($F10="진행중","▶",IF($F10="제외",".",IF($F10="보류","◇","■")))),"") | N10: =IF(AND(7>=$D10,7<=$E10),IF($F10="완료","●",IF($F10="진행중","▶",IF($F10="제외",".",IF($F10="보류","◇","■")))),"") | O10: =IF(AND(8>=$D10,8<=$E10),IF($F10="완료","●",IF($F10="진행중","▶",IF($F10="제외",".",IF($F10="보류","◇","■")))),"") | P10: =IF(AND(9>=$D10,9<=$E10),IF($F10="완료","●",IF($F10="진행중","▶",IF($F10="제외",".",IF($F10="보류","◇","■")))),"") | Q10: =IF(AND(10>=$D10,10<=$E10),IF($F10="완료","●",IF($F10="진행중","▶",IF($F10="제외",".",IF($F10="보류","◇","■")))),"") | R10: =IF(AND(11>=$D10,11<=$E10),IF($F10="완료","●",IF($F10="진행중","▶",IF($F10="제외",".",IF($F10="보류","◇","■")))),"") | S10: =IF(AND(12>=$D10,12<=$E10),IF($F10="완료","●",IF($F10="진행중","▶",IF($F10="제외",".",IF($F10="보류","◇","■")))),"") | T10: =IF(AND(13>=$D10,13<=$E10),IF($F10="완료","●",IF($F10="진행중","▶",IF($F10="제외",".",IF($F10="보류","◇","■")))),"") | U10: =IF(AND(14>=$D10,14<=$E10),IF($F10="완료","●",IF($F10="진행중","▶",IF($F10="제외",".",IF($F10="보류","◇","■")))),"") | V10: =IF(AND(15>=$D10,15<=$E10),IF($F10="완료","●",IF($F10="진행중","▶",IF($F10="제외",".",IF($F10="보류","◇","■")))),"")
A11: =WBS!A11 | B11: =WBS!C11 | C11: =WBS!K11 | D11: =WBS!G11 | E11: =WBS!H11 | F11: =WBS!O11 | G11: =WBS!P11 | H11: =IF(AND(1>=$D11,1<=$E11),IF($F11="완료","●",IF($F11="진행중","▶",IF($F11="제외",".",IF($F11="보류","◇","■")))),"") | I11: =IF(AND(2>=$D11,2<=$E11),IF($F11="완료","●",IF($F11="진행중","▶",IF($F11="제외",".",IF($F11="보류","◇","■")))),"") | J11: =IF(AND(3>=$D11,3<=$E11),IF($F11="완료","●",IF($F11="진행중","▶",IF($F11="제외",".",IF($F11="보류","◇","■")))),"") | K11: =IF(AND(4>=$D11,4<=$E11),IF($F11="완료","●",IF($F11="진행중","▶",IF($F11="제외",".",IF($F11="보류","◇","■")))),"") | L11: =IF(AND(5>=$D11,5<=$E11),IF($F11="완료","●",IF($F11="진행중","▶",IF($F11="제외",".",IF($F11="보류","◇","■")))),"") | M11: =IF(AND(6>=$D11,6<=$E11),IF($F11="완료","●",IF($F11="진행중","▶",IF($F11="제외",".",IF($F11="보류","◇","■")))),"") | N11: =IF(AND(7>=$D11,7<=$E11),IF($F11="완료","●",IF($F11="진행중","▶",IF($F11="제외",".",IF($F11="보류","◇","■")))),"") | O11: =IF(AND(8>=$D11,8<=$E11),IF($F11="완료","●",IF($F11="진행중","▶",IF($F11="제외",".",IF($F11="보류","◇","■")))),"") | P11: =IF(AND(9>=$D11,9<=$E11),IF($F11="완료","●",IF($F11="진행중","▶",IF($F11="제외",".",IF($F11="보류","◇","■")))),"") | Q11: =IF(AND(10>=$D11,10<=$E11),IF($F11="완료","●",IF($F11="진행중","▶",IF($F11="제외",".",IF($F11="보류","◇","■")))),"") | R11: =IF(AND(11>=$D11,11<=$E11),IF($F11="완료","●",IF($F11="진행중","▶",IF($F11="제외",".",IF($F11="보류","◇","■")))),"") | S11: =IF(AND(12>=$D11,12<=$E11),IF($F11="완료","●",IF($F11="진행중","▶",IF($F11="제외",".",IF($F11="보류","◇","■")))),"") | T11: =IF(AND(13>=$D11,13<=$E11),IF($F11="완료","●",IF($F11="진행중","▶",IF($F11="제외",".",IF($F11="보류","◇","■")))),"") | U11: =IF(AND(14>=$D11,14<=$E11),IF($F11="완료","●",IF($F11="진행중","▶",IF($F11="제외",".",IF($F11="보류","◇","■")))),"") | V11: =IF(AND(15>=$D11,15<=$E11),IF($F11="완료","●",IF($F11="진행중","▶",IF($F11="제외",".",IF($F11="보류","◇","■")))),"")
A12: =WBS!A12 | B12: =WBS!C12 | C12: =WBS!K12 | D12: =WBS!G12 | E12: =WBS!H12 | F12: =WBS!O12 | G12: =WBS!P12 | H12: =IF(AND(1>=$D12,1<=$E12),IF($F12="완료","●",IF($F12="진행중","▶",IF($F12="제외",".",IF($F12="보류","◇","■")))),"") | I12: =IF(AND(2>=$D12,2<=$E12),IF($F12="완료","●",IF($F12="진행중","▶",IF($F12="제외",".",IF($F12="보류","◇","■")))),"") | J12: =IF(AND(3>=$D12,3<=$E12),IF($F12="완료","●",IF($F12="진행중","▶",IF($F12="제외",".",IF($F12="보류","◇","■")))),"") | K12: =IF(AND(4>=$D12,4<=$E12),IF($F12="완료","●",IF($F12="진행중","▶",IF($F12="제외",".",IF($F12="보류","◇","■")))),"") | L12: =IF(AND(5>=$D12,5<=$E12),IF($F12="완료","●",IF($F12="진행중","▶",IF($F12="제외",".",IF($F12="보류","◇","■")))),"") | M12: =IF(AND(6>=$D12,6<=$E12),IF($F12="완료","●",IF($F12="진행중","▶",IF($F12="제외",".",IF($F12="보류","◇","■")))),"") | N12: =IF(AND(7>=$D12,7<=$E12),IF($F12="완료","●",IF($F12="진행중","▶",IF($F12="제외",".",IF($F12="보류","◇","■")))),"") | O12: =IF(AND(8>=$D12,8<=$E12),IF($F12="완료","●",IF($F12="진행중","▶",IF($F12="제외",".",IF($F12="보류","◇","■")))),"") | P12: =IF(AND(9>=$D12,9<=$E12),IF($F12="완료","●",IF($F12="진행중","▶",IF($F12="제외",".",IF($F12="보류","◇","■")))),"") | Q12: =IF(AND(10>=$D12,10<=$E12),IF($F12="완료","●",IF($F12="진행중","▶",IF($F12="제외",".",IF($F12="보류","◇","■")))),"") | R12: =IF(AND(11>=$D12,11<=$E12),IF($F12="완료","●",IF($F12="진행중","▶",IF($F12="제외",".",IF($F12="보류","◇","■")))),"") | S12: =IF(AND(12>=$D12,12<=$E12),IF($F12="완료","●",IF($F12="진행중","▶",IF($F12="제외",".",IF($F12="보류","◇","■")))),"") | T12: =IF(AND(13>=$D12,13<=$E12),IF($F12="완료","●",IF($F12="진행중","▶",IF($F12="제외",".",IF($F12="보류","◇","■")))),"") | U12: =IF(AND(14>=$D12,14<=$E12),IF($F12="완료","●",IF($F12="진행중","▶",IF($F12="제외",".",IF($F12="보류","◇","■")))),"") | V12: =IF(AND(15>=$D12,15<=$E12),IF($F12="완료","●",IF($F12="진행중","▶",IF($F12="제외",".",IF($F12="보류","◇","■")))),"")
A13: =WBS!A13 | B13: =WBS!C13 | C13: =WBS!K13 | D13: =WBS!G13 | E13: =WBS!H13 | F13: =WBS!O13 | G13: =WBS!P13 | H13: =IF(AND(1>=$D13,1<=$E13),IF($F13="완료","●",IF($F13="진행중","▶",IF($F13="제외",".",IF($F13="보류","◇","■")))),"") | I13: =IF(AND(2>=$D13,2<=$E13),IF($F13="완료","●",IF($F13="진행중","▶",IF($F13="제외",".",IF($F13="보류","◇","■")))),"") | J13: =IF(AND(3>=$D13,3<=$E13),IF($F13="완료","●",IF($F13="진행중","▶",IF($F13="제외",".",IF($F13="보류","◇","■")))),"") | K13: =IF(AND(4>=$D13,4<=$E13),IF($F13="완료","●",IF($F13="진행중","▶",IF($F13="제외",".",IF($F13="보류","◇","■")))),"") | L13: =IF(AND(5>=$D13,5<=$E13),IF($F13="완료","●",IF($F13="진행중","▶",IF($F13="제외",".",IF($F13="보류","◇","■")))),"") | M13: =IF(AND(6>=$D13,6<=$E13),IF($F13="완료","●",IF($F13="진행중","▶",IF($F13="제외",".",IF($F13="보류","◇","■")))),"") | N13: =IF(AND(7>=$D13,7<=$E13),IF($F13="완료","●",IF($F13="진행중","▶",IF($F13="제외",".",IF($F13="보류","◇","■")))),"") | O13: =IF(AND(8>=$D13,8<=$E13),IF($F13="완료","●",IF($F13="진행중","▶",IF($F13="제외",".",IF($F13="보류","◇","■")))),"") | P13: =IF(AND(9>=$D13,9<=$E13),IF($F13="완료","●",IF($F13="진행중","▶",IF($F13="제외",".",IF($F13="보류","◇","■")))),"") | Q13: =IF(AND(10>=$D13,10<=$E13),IF($F13="완료","●",IF($F13="진행중","▶",IF($F13="제외",".",IF($F13="보류","◇","■")))),"") | R13: =IF(AND(11>=$D13,11<=$E13),IF($F13="완료","●",IF($F13="진행중","▶",IF($F13="제외",".",IF($F13="보류","◇","■")))),"") | S13: =IF(AND(12>=$D13,12<=$E13),IF($F13="완료","●",IF($F13="진행중","▶",IF($F13="제외",".",IF($F13="보류","◇","■")))),"") | T13: =IF(AND(13>=$D13,13<=$E13),IF($F13="완료","●",IF($F13="진행중","▶",IF($F13="제외",".",IF($F13="보류","◇","■")))),"") | U13: =IF(AND(14>=$D13,14<=$E13),IF($F13="완료","●",IF($F13="진행중","▶",IF($F13="제외",".",IF($F13="보류","◇","■")))),"") | V13: =IF(AND(15>=$D13,15<=$E13),IF($F13="완료","●",IF($F13="진행중","▶",IF($F13="제외",".",IF($F13="보류","◇","■")))),"")
A14: =WBS!A14 | B14: =WBS!C14 | C14: =WBS!K14 | D14: =WBS!G14 | E14: =WBS!H14 | F14: =WBS!O14 | G14: =WBS!P14 | H14: =IF(AND(1>=$D14,1<=$E14),IF($F14="완료","●",IF($F14="진행중","▶",IF($F14="제외",".",IF($F14="보류","◇","■")))),"") | I14: =IF(AND(2>=$D14,2<=$E14),IF($F14="완료","●",IF($F14="진행중","▶",IF($F14="제외",".",IF($F14="보류","◇","■")))),"") | J14: =IF(AND(3>=$D14,3<=$E14),IF($F14="완료","●",IF($F14="진행중","▶",IF($F14="제외",".",IF($F14="보류","◇","■")))),"") | K14: =IF(AND(4>=$D14,4<=$E14),IF($F14="완료","●",IF($F14="진행중","▶",IF($F14="제외",".",IF($F14="보류","◇","■")))),"") | L14: =IF(AND(5>=$D14,5<=$E14),IF($F14="완료","●",IF($F14="진행중","▶",IF($F14="제외",".",IF($F14="보류","◇","■")))),"") | M14: =IF(AND(6>=$D14,6<=$E14),IF($F14="완료","●",IF($F14="진행중","▶",IF($F14="제외",".",IF($F14="보류","◇","■")))),"") | N14: =IF(AND(7>=$D14,7<=$E14),IF($F14="완료","●",IF($F14="진행중","▶",IF($F14="제외",".",IF($F14="보류","◇","■")))),"") | O14: =IF(AND(8>=$D14,8<=$E14),IF($F14="완료","●",IF($F14="진행중","▶",IF($F14="제외",".",IF($F14="보류","◇","■")))),"") | P14: =IF(AND(9>=$D14,9<=$E14),IF($F14="완료","●",IF($F14="진행중","▶",IF($F14="제외",".",IF($F14="보류","◇","■")))),"") | Q14: =IF(AND(10>=$D14,10<=$E14),IF($F14="완료","●",IF($F14="진행중","▶",IF($F14="제외",".",IF($F14="보류","◇","■")))),"") | R14: =IF(AND(11>=$D14,11<=$E14),IF($F14="완료","●",IF($F14="진행중","▶",IF($F14="제외",".",IF($F14="보류","◇","■")))),"") | S14: =IF(AND(12>=$D14,12<=$E14),IF($F14="완료","●",IF($F14="진행중","▶",IF($F14="제외",".",IF($F14="보류","◇","■")))),"") | T14: =IF(AND(13>=$D14,13<=$E14),IF($F14="완료","●",IF($F14="진행중","▶",IF($F14="제외",".",IF($F14="보류","◇","■")))),"") | U14: =IF(AND(14>=$D14,14<=$E14),IF($F14="완료","●",IF($F14="진행중","▶",IF($F14="제외",".",IF($F14="보류","◇","■")))),"") | V14: =IF(AND(15>=$D14,15<=$E14),IF($F14="완료","●",IF($F14="진행중","▶",IF($F14="제외",".",IF($F14="보류","◇","■")))),"")
A15: =WBS!A15 | B15: =WBS!C15 | C15: =WBS!K15 | D15: =WBS!G15 | E15: =WBS!H15 | F15: =WBS!O15 | G15: =WBS!P15 | H15: =IF(AND(1>=$D15,1<=$E15),IF($F15="완료","●",IF($F15="진행중","▶",IF($F15="제외",".",IF($F15="보류","◇","■")))),"") | I15: =IF(AND(2>=$D15,2<=$E15),IF($F15="완료","●",IF($F15="진행중","▶",IF($F15="제외",".",IF($F15="보류","◇","■")))),"") | J15: =IF(AND(3>=$D15,3<=$E15),IF($F15="완료","●",IF($F15="진행중","▶",IF($F15="제외",".",IF($F15="보류","◇","■")))),"") | K15: =IF(AND(4>=$D15,4<=$E15),IF($F15="완료","●",IF($F15="진행중","▶",IF($F15="제외",".",IF($F15="보류","◇","■")))),"") | L15: =IF(AND(5>=$D15,5<=$E15),IF($F15="완료","●",IF($F15="진행중","▶",IF($F15="제외",".",IF($F15="보류","◇","■")))),"") | M15: =IF(AND(6>=$D15,6<=$E15),IF($F15="완료","●",IF($F15="진행중","▶",IF($F15="제외",".",IF($F15="보류","◇","■")))),"") | N15: =IF(AND(7>=$D15,7<=$E15),IF($F15="완료","●",IF($F15="진행중","▶",IF($F15="제외",".",IF($F15="보류","◇","■")))),"") | O15: =IF(AND(8>=$D15,8<=$E15),IF($F15="완료","●",IF($F15="진행중","▶",IF($F15="제외",".",IF($F15="보류","◇","■")))),"") | P15: =IF(AND(9>=$D15,9<=$E15),IF($F15="완료","●",IF($F15="진행중","▶",IF($F15="제외",".",IF($F15="보류","◇","■")))),"") | Q15: =IF(AND(10>=$D15,10<=$E15),IF($F15="완료","●",IF($F15="진행중","▶",IF($F15="제외",".",IF($F15="보류","◇","■")))),"") | R15: =IF(AND(11>=$D15,11<=$E15),IF($F15="완료","●",IF($F15="진행중","▶",IF($F15="제외",".",IF($F15="보류","◇","■")))),"") | S15: =IF(AND(12>=$D15,12<=$E15),IF($F15="완료","●",IF($F15="진행중","▶",IF($F15="제외",".",IF($F15="보류","◇","■")))),"") | T15: =IF(AND(13>=$D15,13<=$E15),IF($F15="완료","●",IF($F15="진행중","▶",IF($F15="제외",".",IF($F15="보류","◇","■")))),"") | U15: =IF(AND(14>=$D15,14<=$E15),IF($F15="완료","●",IF($F15="진행중","▶",IF($F15="제외",".",IF($F15="보류","◇","■")))),"") | V15: =IF(AND(15>=$D15,15<=$E15),IF($F15="완료","●",IF($F15="진행중","▶",IF($F15="제외",".",IF($F15="보류","◇","■")))),"")
A16: =WBS!A16 | B16: =WBS!C16 | C16: =WBS!K16 | D16: =WBS!G16 | E16: =WBS!H16 | F16: =WBS!O16 | G16: =WBS!P16 | H16: =IF(AND(1>=$D16,1<=$E16),IF($F16="완료","●",IF($F16="진행중","▶",IF($F16="제외",".",IF($F16="보류","◇","■")))),"") | I16: =IF(AND(2>=$D16,2<=$E16),IF($F16="완료","●",IF($F16="진행중","▶",IF($F16="제외",".",IF($F16="보류","◇","■")))),"") | J16: =IF(AND(3>=$D16,3<=$E16),IF($F16="완료","●",IF($F16="진행중","▶",IF($F16="제외",".",IF($F16="보류","◇","■")))),"") | K16: =IF(AND(4>=$D16,4<=$E16),IF($F16="완료","●",IF($F16="진행중","▶",IF($F16="제외",".",IF($F16="보류","◇","■")))),"") | L16: =IF(AND(5>=$D16,5<=$E16),IF($F16="완료","●",IF($F16="진행중","▶",IF($F16="제외",".",IF($F16="보류","◇","■")))),"") | M16: =IF(AND(6>=$D16,6<=$E16),IF($F16="완료","●",IF($F16="진행중","▶",IF($F16="제외",".",IF($F16="보류","◇","■")))),"") | N16: =IF(AND(7>=$D16,7<=$E16),IF($F16="완료","●",IF($F16="진행중","▶",IF($F16="제외",".",IF($F16="보류","◇","■")))),"") | O16: =IF(AND(8>=$D16,8<=$E16),IF($F16="완료","●",IF($F16="진행중","▶",IF($F16="제외",".",IF($F16="보류","◇","■")))),"") | P16: =IF(AND(9>=$D16,9<=$E16),IF($F16="완료","●",IF($F16="진행중","▶",IF($F16="제외",".",IF($F16="보류","◇","■")))),"") | Q16: =IF(AND(10>=$D16,10<=$E16),IF($F16="완료","●",IF($F16="진행중","▶",IF($F16="제외",".",IF($F16="보류","◇","■")))),"") | R16: =IF(AND(11>=$D16,11<=$E16),IF($F16="완료","●",IF($F16="진행중","▶",IF($F16="제외",".",IF($F16="보류","◇","■")))),"") | S16: =IF(AND(12>=$D16,12<=$E16),IF($F16="완료","●",IF($F16="진행중","▶",IF($F16="제외",".",IF($F16="보류","◇","■")))),"") | T16: =IF(AND(13>=$D16,13<=$E16),IF($F16="완료","●",IF($F16="진행중","▶",IF($F16="제외",".",IF($F16="보류","◇","■")))),"") | U16: =IF(AND(14>=$D16,14<=$E16),IF($F16="완료","●",IF($F16="진행중","▶",IF($F16="제외",".",IF($F16="보류","◇","■")))),"") | V16: =IF(AND(15>=$D16,15<=$E16),IF($F16="완료","●",IF($F16="진행중","▶",IF($F16="제외",".",IF($F16="보류","◇","■")))),"")
... A90: =WBS!A90 | B90: =WBS!C90 | C90: =WBS!K90 | D90: =WBS!G90 | E90: =WBS!H90 | F90: =WBS!O90 | G90: =WBS!P90 | H90: =IF(AND(1>=$D90,1<=$E90),IF($F90="완료","●",IF($F90="진행중","▶",IF($F90="제외",".",IF($F90="보류","◇","■")))),"") | I90: =IF(AND(2>=$D90,2<=$E90),IF($F90="완료","●",IF($F90="진행중","▶",IF($F90="제외",".",IF($F90="보류","◇","■")))),"") | J90: =IF(AND(3>=$D90,3<=$E90),IF($F90="완료","●",IF($F90="진행중","▶",IF($F90="제외",".",IF($F90="보류","◇","■")))),"") | K90: =IF(AND(4>=$D90,4<=$E90),IF($F90="완료","●",IF($F90="진행중","▶",IF($F90="제외",".",IF($F90="보류","◇","■")))),"") | L90: =IF(AND(5>=$D90,5<=$E90),IF($F90="완료","●",IF($F90="진행중","▶",IF($F90="제외",".",IF($F90="보류","◇","■")))),"") | M90: =IF(AND(6>=$D90,6<=$E90),IF($F90="완료","●",IF($F90="진행중","▶",IF($F90="제외",".",IF($F90="보류","◇","■")))),"") | N90: =IF(AND(7>=$D90,7<=$E90),IF($F90="완료","●",IF($F90="진행중","▶",IF($F90="제외",".",IF($F90="보류","◇","■")))),"") | O90: =IF(AND(8>=$D90,8<=$E90),IF($F90="완료","●",IF($F90="진행중","▶",IF($F90="제외",".",IF($F90="보류","◇","■")))),"") | P90: =IF(AND(9>=$D90,9<=$E90),IF($F90="완료","●",IF($F90="진행중","▶",IF($F90="제외",".",IF($F90="보류","◇","■")))),"") | Q90: =IF(AND(10>=$D90,10<=$E90),IF($F90="완료","●",IF($F90="진행중","▶",IF($F90="제외",".",IF($F90="보류","◇","■")))),"") | R90: =IF(AND(11>=$D90,11<=$E90),IF($F90="완료","●",IF($F90="진행중","▶",IF($F90="제외",".",IF($F90="보류","◇","■")))),"") | S90: =IF(AND(12>=$D90,12<=$E90),IF($F90="완료","●",IF($F90="진행중","▶",IF($F90="제외",".",IF($F90="보류","◇","■")))),"") | T90: =IF(AND(13>=$D90,13<=$E90),IF($F90="완료","●",IF($F90="진행중","▶",IF($F90="제외",".",IF($F90="보류","◇","■")))),"") | U90: =IF(AND(14>=$D90,14<=$E90),IF($F90="완료","●",IF($F90="진행중","▶",IF($F90="제외",".",IF($F90="보류","◇","■")))),"") | V90: =IF(AND(15>=$D90,15<=$E90),IF($F90="완료","●",IF($F90="진행중","▶",IF($F90="제외",".",IF($F90="보류","◇","■")))),"")
A92: 마일스톤
A93: M1 | B93: 분석 완료 — 정의서 4종 + 백로그·WBS | C93: WBS 2.5 | D93: 3 | E93: 3 | F93: 완료 | H93: =IF(1=$D93,IF($F93="완료","◆","◇"),"") | I93: =IF(2=$D93,IF($F93="완료","◆","◇"),"") | J93: =IF(3=$D93,IF($F93="완료","◆","◇"),"") | K93: =IF(4=$D93,IF($F93="완료","◆","◇"),"") | L93: =IF(5=$D93,IF($F93="완료","◆","◇"),"") | M93: =IF(6=$D93,IF($F93="완료","◆","◇"),"") | N93: =IF(7=$D93,IF($F93="완료","◆","◇"),"") | O93: =IF(8=$D93,IF($F93="완료","◆","◇"),"") | P93: =IF(9=$D93,IF($F93="완료","◆","◇"),"") | Q93: =IF(10=$D93,IF($F93="완료","◆","◇"),"") | R93: =IF(11=$D93,IF($F93="완료","◆","◇"),"") | S93: =IF(12=$D93,IF($F93="완료","◆","◇"),"") | T93: =IF(13=$D93,IF($F93="완료","◆","◇"),"") | U93: =IF(14=$D93,IF($F93="완료","◆","◇"),"") | V93: =IF(15=$D93,IF($F93="완료","◆","◇"),"")
A94: M2 | B94: 설계 완료 — 스택·ERD·API·규칙·화면, 미결 확정 | C94: WBS 3.8 | D94: 5 | E94: 5 | F94: 대기 | H94: =IF(1=$D94,IF($F94="완료","◆","◇"),"") | I94: =IF(2=$D94,IF($F94="완료","◆","◇"),"") | J94: =IF(3=$D94,IF($F94="완료","◆","◇"),"") | K94: =IF(4=$D94,IF($F94="완료","◆","◇"),"") | L94: =IF(5=$D94,IF($F94="완료","◆","◇"),"") | M94: =IF(6=$D94,IF($F94="완료","◆","◇"),"") | N94: =IF(7=$D94,IF($F94="완료","◆","◇"),"") | O94: =IF(8=$D94,IF($F94="완료","◆","◇"),"") | P94: =IF(9=$D94,IF($F94="완료","◆","◇"),"") | Q94: =IF(10=$D94,IF($F94="완료","◆","◇"),"") | R94: =IF(11=$D94,IF($F94="완료","◆","◇"),"") | S94: =IF(12=$D94,IF($F94="완료","◆","◇"),"") | T94: =IF(13=$D94,IF($F94="완료","◆","◇"),"") | U94: =IF(14=$D94,IF($F94="완료","◆","◇"),"") | V94: =IF(15=$D94,IF($F94="완료","◆","◇"),"")
A95: M3 | B95: 수집 수직 슬라이스 — 원본/정규화가 주기적으로 쌓임 | C95: WBS 4.2.4 | D95: 7 | E95: 7 | F95: 대기 | H95: =IF(1=$D95,IF($F95="완료","◆","◇"),"") | I95: =IF(2=$D95,IF($F95="완료","◆","◇"),"") | J95: =IF(3=$D95,IF($F95="완료","◆","◇"),"") | K95: =IF(4=$D95,IF($F95="완료","◆","◇"),"") | L95: =IF(5=$D95,IF($F95="완료","◆","◇"),"") | M95: =IF(6=$D95,IF($F95="완료","◆","◇"),"") | N95: =IF(7=$D95,IF($F95="완료","◆","◇"),"") | O95: =IF(8=$D95,IF($F95="완료","◆","◇"),"") | P95: =IF(9=$D95,IF($F95="완료","◆","◇"),"") | Q95: =IF(10=$D95,IF($F95="완료","◆","◇"),"") | R95: =IF(11=$D95,IF($F95="완료","◆","◇"),"") | S95: =IF(12=$D95,IF($F95="완료","◆","◇"),"") | T95: =IF(13=$D95,IF($F95="완료","◆","◇"),"") | U95: =IF(14=$D95,IF($F95="완료","◆","◇"),"") | V95: =IF(15=$D95,IF($F95="완료","◆","◇"),"")
A96: M4 | B96: 검지 데모 — 규칙 다수 + 자동보정/이슈 분기, 원본 불변 | C96: WBS 4.4.5 | D96: 9 | E96: 9 | F96: 대기 | H96: =IF(1=$D96,IF($F96="완료","◆","◇"),"") | I96: =IF(2=$D96,IF($F96="완료","◆","◇"),"") | J96: =IF(3=$D96,IF($F96="완료","◆","◇"),"") | K96: =IF(4=$D96,IF($F96="완료","◆","◇"),"") | L96: =IF(5=$D96,IF($F96="완료","◆","◇"),"") | M96: =IF(6=$D96,IF($F96="완료","◆","◇"),"") | N96: =IF(7=$D96,IF($F96="완료","◆","◇"),"") | O96: =IF(8=$D96,IF($F96="완료","◆","◇"),"") | P96: =IF(9=$D96,IF($F96="완료","◆","◇"),"") | Q96: =IF(10=$D96,IF($F96="완료","◆","◇"),"") | R96: =IF(11=$D96,IF($F96="완료","◆","◇"),"") | S96: =IF(12=$D96,IF($F96="완료","◆","◇"),"") | T96: =IF(13=$D96,IF($F96="완료","◆","◇"),"") | U96: =IF(14=$D96,IF($F96="완료","◆","◇"),"") | V96: =IF(15=$D96,IF($F96="완료","◆","◇"),"")
A97: M5 | B97: MVP 기능 동결 — 시연 Must 스토리 Done, 신규 Must 없음 | C97: WBS 4.6.5 | D97: 11 | E97: 11 | F97: 대기 | H97: =IF(1=$D97,IF($F97="완료","◆","◇"),"") | I97: =IF(2=$D97,IF($F97="완료","◆","◇"),"") | J97: =IF(3=$D97,IF($F97="완료","◆","◇"),"") | K97: =IF(4=$D97,IF($F97="완료","◆","◇"),"") | L97: =IF(5=$D97,IF($F97="완료","◆","◇"),"") | M97: =IF(6=$D97,IF($F97="완료","◆","◇"),"") | N97: =IF(7=$D97,IF($F97="완료","◆","◇"),"") | O97: =IF(8=$D97,IF($F97="완료","◆","◇"),"") | P97: =IF(9=$D97,IF($F97="완료","◆","◇"),"") | Q97: =IF(10=$D97,IF($F97="완료","◆","◇"),"") | R97: =IF(11=$D97,IF($F97="완료","◆","◇"),"") | S97: =IF(12=$D97,IF($F97="완료","◆","◇"),"") | T97: =IF(13=$D97,IF($F97="완료","◆","◇"),"") | U97: =IF(14=$D97,IF($F97="완료","◆","◇"),"") | V97: =IF(15=$D97,IF($F97="완료","◆","◇"),"")
A98: M6 | B98: 시험 완료 — 필수 테스트 100%, 치명/주요 0 | C98: WBS 5.7 | D98: 13 | E98: 13 | F98: 대기 | H98: =IF(1=$D98,IF($F98="완료","◆","◇"),"") | I98: =IF(2=$D98,IF($F98="완료","◆","◇"),"") | J98: =IF(3=$D98,IF($F98="완료","◆","◇"),"") | K98: =IF(4=$D98,IF($F98="완료","◆","◇"),"") | L98: =IF(5=$D98,IF($F98="완료","◆","◇"),"") | M98: =IF(6=$D98,IF($F98="완료","◆","◇"),"") | N98: =IF(7=$D98,IF($F98="완료","◆","◇"),"") | O98: =IF(8=$D98,IF($F98="완료","◆","◇"),"") | P98: =IF(9=$D98,IF($F98="완료","◆","◇"),"") | Q98: =IF(10=$D98,IF($F98="완료","◆","◇"),"") | R98: =IF(11=$D98,IF($F98="완료","◆","◇"),"") | S98: =IF(12=$D98,IF($F98="완료","◆","◇"),"") | T98: =IF(13=$D98,IF($F98="완료","◆","◇"),"") | U98: =IF(14=$D98,IF($F98="완료","◆","◇"),"") | V98: =IF(15=$D98,IF($F98="완료","◆","◇"),"")
A99: M7 | B99: 인도 — 재설치·시연·발표 | C99: WBS 6.6 | D99: 15 | E99: 15 | F99: 대기 | H99: =IF(1=$D99,IF($F99="완료","◆","◇"),"") | I99: =IF(2=$D99,IF($F99="완료","◆","◇"),"") | J99: =IF(3=$D99,IF($F99="완료","◆","◇"),"") | K99: =IF(4=$D99,IF($F99="완료","◆","◇"),"") | L99: =IF(5=$D99,IF($F99="완료","◆","◇"),"") | M99: =IF(6=$D99,IF($F99="완료","◆","◇"),"") | N99: =IF(7=$D99,IF($F99="완료","◆","◇"),"") | O99: =IF(8=$D99,IF($F99="완료","◆","◇"),"") | P99: =IF(9=$D99,IF($F99="완료","◆","◇"),"") | Q99: =IF(10=$D99,IF($F99="완료","◆","◇"),"") | R99: =IF(11=$D99,IF($F99="완료","◆","◇"),"") | S99: =IF(12=$D99,IF($F99="완료","◆","◇"),"") | T99: =IF(13=$D99,IF($F99="완료","◆","◇"),"") | U99: =IF(14=$D99,IF($F99="완료","◆","◇"),"") | V99: =IF(15=$D99,IF($F99="완료","◆","◇"),"")

Sheet 요약
B1: WBS 요약 · 인일 집계
B3: 확정 계획 인일 | C3: 획득 인일 | D3: 진척률 | E3: 작업패키지 | F3: 완료 | G3: 현재 주차
B4: =D14 | C4: =E14 | D4: =F14 | E4: =COUNTIFS(WBS!$B$5:$B$90,"작업") | F4: =COUNTIFS(WBS!$B$5:$B$90,"작업",WBS!$O$5:$O$90,"완료") | G4: =표지!C16
B6: 단계별 집계
B7: 단계 | C7: 작업패키지 | D7: 계획 인일 | E7: 획득 인일 | F7: 진척률 | G7: 시작주 | H7: 종료주
B8: 프로젝트 관리 | C8: =COUNTIFS(WBS!$B$5:$B$90,"작업",WBS!$D$5:$D$90,$B8,WBS!$O$5:$O$90,"<>제외",WBS!$O$5:$O$90,"<>보류") | D8: =SUMIFS(WBS!$F$5:$F$90,WBS!$B$5:$B$90,"작업",WBS!$D$5:$D$90,$B8,WBS!$O$5:$O$90,"<>제외",WBS!$O$5:$O$90,"<>보류") | E8: =SUMIFS(WBS!$Q$5:$Q$90,WBS!$B$5:$B$90,"작업",WBS!$D$5:$D$90,$B8,WBS!$O$5:$O$90,"<>제외",WBS!$O$5:$O$90,"<>보류") | F8: =IF(D8=0,0,E8/D8) | G8: =WBS!G5 | H8: =WBS!H5
B9: 분석 | C9: =COUNTIFS(WBS!$B$5:$B$90,"작업",WBS!$D$5:$D$90,$B9,WBS!$O$5:$O$90,"<>제외",WBS!$O$5:$O$90,"<>보류") | D9: =SUMIFS(WBS!$F$5:$F$90,WBS!$B$5:$B$90,"작업",WBS!$D$5:$D$90,$B9,WBS!$O$5:$O$90,"<>제외",WBS!$O$5:$O$90,"<>보류") | E9: =SUMIFS(WBS!$Q$5:$Q$90,WBS!$B$5:$B$90,"작업",WBS!$D$5:$D$90,$B9,WBS!$O$5:$O$90,"<>제외",WBS!$O$5:$O$90,"<>보류") | F9: =IF(D9=0,0,E9/D9) | G9: =WBS!G10 | H9: =WBS!H10
B10: 설계 | C10: =COUNTIFS(WBS!$B$5:$B$90,"작업",WBS!$D$5:$D$90,$B10,WBS!$O$5:$O$90,"<>제외",WBS!$O$5:$O$90,"<>보류") | D10: =SUMIFS(WBS!$F$5:$F$90,WBS!$B$5:$B$90,"작업",WBS!$D$5:$D$90,$B10,WBS!$O$5:$O$90,"<>제외",WBS!$O$5:$O$90,"<>보류") | E10: =SUMIFS(WBS!$Q$5:$Q$90,WBS!$B$5:$B$90,"작업",WBS!$D$5:$D$90,$B10,WBS!$O$5:$O$90,"<>제외",WBS!$O$5:$O$90,"<>보류") | F10: =IF(D10=0,0,E10/D10) | G10: =WBS!G16 | H10: =WBS!H16
B11: 구현 | C11: =COUNTIFS(WBS!$B$5:$B$90,"작업",WBS!$D$5:$D$90,$B11,WBS!$O$5:$O$90,"<>제외",WBS!$O$5:$O$90,"<>보류") | D11: =SUMIFS(WBS!$F$5:$F$90,WBS!$B$5:$B$90,"작업",WBS!$D$5:$D$90,$B11,WBS!$O$5:$O$90,"<>제외",WBS!$O$5:$O$90,"<>보류") | E11: =SUMIFS(WBS!$Q$5:$Q$90,WBS!$B$5:$B$90,"작업",WBS!$D$5:$D$90,$B11,WBS!$O$5:$O$90,"<>제외",WBS!$O$5:$O$90,"<>보류") | F11: =IF(D11=0,0,E11/D11) | G11: =WBS!G25 | H11: =WBS!H25
B12: 테스트 | C12: =COUNTIFS(WBS!$B$5:$B$90,"작업",WBS!$D$5:$D$90,$B12,WBS!$O$5:$O$90,"<>제외",WBS!$O$5:$O$90,"<>보류") | D12: =SUMIFS(WBS!$F$5:$F$90,WBS!$B$5:$B$90,"작업",WBS!$D$5:$D$90,$B12,WBS!$O$5:$O$90,"<>제외",WBS!$O$5:$O$90,"<>보류") | E12: =SUMIFS(WBS!$Q$5:$Q$90,WBS!$B$5:$B$90,"작업",WBS!$D$5:$D$90,$B12,WBS!$O$5:$O$90,"<>제외",WBS!$O$5:$O$90,"<>보류") | F12: =IF(D12=0,0,E12/D12) | G12: =WBS!G76 | H12: =WBS!H76
B13: 안정화·인도 | C13: =COUNTIFS(WBS!$B$5:$B$90,"작업",WBS!$D$5:$D$90,$B13,WBS!$O$5:$O$90,"<>제외",WBS!$O$5:$O$90,"<>보류") | D13: =SUMIFS(WBS!$F$5:$F$90,WBS!$B$5:$B$90,"작업",WBS!$D$5:$D$90,$B13,WBS!$O$5:$O$90,"<>제외",WBS!$O$5:$O$90,"<>보류") | E13: =SUMIFS(WBS!$Q$5:$Q$90,WBS!$B$5:$B$90,"작업",WBS!$D$5:$D$90,$B13,WBS!$O$5:$O$90,"<>제외",WBS!$O$5:$O$90,"<>보류") | F13: =IF(D13=0,0,E13/D13) | G13: =WBS!G84 | H13: =WBS!H84
B14: 합계 | C14: =SUM(C8:C13) | D14: =SUM(D8:D13) | E14: =SUM(E8:E13) | F14: =IF(D14=0,0,E14/D14) | G14: 1 | H14: 15
B16: 담당별 부하 (작업패키지 인일)
B17: 담당 | C17: 작업패키지 | D17: 계획 인일 | E17: 획득 인일 | F17: 진척률 | G17: 비중
B18: 조찬희 | C18: =COUNTIFS(WBS!$B$5:$B$90,"작업",WBS!$K$5:$K$90,$B18,WBS!$O$5:$O$90,"<>제외",WBS!$O$5:$O$90,"<>보류") | D18: =SUMIFS(WBS!$F$5:$F$90,WBS!$B$5:$B$90,"작업",WBS!$K$5:$K$90,$B18,WBS!$O$5:$O$90,"<>제외",WBS!$O$5:$O$90,"<>보류") | E18: =SUMIFS(WBS!$Q$5:$Q$90,WBS!$B$5:$B$90,"작업",WBS!$K$5:$K$90,$B18,WBS!$O$5:$O$90,"<>제외",WBS!$O$5:$O$90,"<>보류") | F18: =IF(D18=0,0,E18/D18) | G18: =IF($D$21=0,0,D18/$D$21)
B19: 기경현 | C19: =COUNTIFS(WBS!$B$5:$B$90,"작업",WBS!$K$5:$K$90,$B19,WBS!$O$5:$O$90,"<>제외",WBS!$O$5:$O$90,"<>보류") | D19: =SUMIFS(WBS!$F$5:$F$90,WBS!$B$5:$B$90,"작업",WBS!$K$5:$K$90,$B19,WBS!$O$5:$O$90,"<>제외",WBS!$O$5:$O$90,"<>보류") | E19: =SUMIFS(WBS!$Q$5:$Q$90,WBS!$B$5:$B$90,"작업",WBS!$K$5:$K$90,$B19,WBS!$O$5:$O$90,"<>제외",WBS!$O$5:$O$90,"<>보류") | F19: =IF(D19=0,0,E19/D19) | G19: =IF($D$21=0,0,D19/$D$21)
B20: 공동 | C20: =COUNTIFS(WBS!$B$5:$B$90,"작업",WBS!$K$5:$K$90,$B20,WBS!$O$5:$O$90,"<>제외",WBS!$O$5:$O$90,"<>보류") | D20: =SUMIFS(WBS!$F$5:$F$90,WBS!$B$5:$B$90,"작업",WBS!$K$5:$K$90,$B20,WBS!$O$5:$O$90,"<>제외",WBS!$O$5:$O$90,"<>보류") | E20: =SUMIFS(WBS!$Q$5:$Q$90,WBS!$B$5:$B$90,"작업",WBS!$K$5:$K$90,$B20,WBS!$O$5:$O$90,"<>제외",WBS!$O$5:$O$90,"<>보류") | F20: =IF(D20=0,0,E20/D20) | G20: =IF($D$21=0,0,D20/$D$21)
B21: 합계 | C21: =SUM(C18:C20) | D21: =SUM(D18:D20) | E21: =SUM(E18:E20) | F21: =IF(D21=0,0,E21/D21) | G21: 1
B23: 구현 활동별 (4.1~4.8)
B24: 활동 | C24: 작업패키지 | D24: 계획 인일 | E24: 획득 인일 | F24: 진척률
B25: 기반 환경 (S1–S2) | C25: =COUNTIFS(WBS!$B$5:$B$90,"작업",WBS!$E$5:$E$90,$B25,WBS!$O$5:$O$90,"<>제외",WBS!$O$5:$O$90,"<>보류") | D25: =SUMIFS(WBS!$F$5:$F$90,WBS!$B$5:$B$90,"작업",WBS!$E$5:$E$90,$B25,WBS!$O$5:$O$90,"<>제외",WBS!$O$5:$O$90,"<>보류") | E25: =SUMIFS(WBS!$Q$5:$Q$90,WBS!$B$5:$B$90,"작업",WBS!$E$5:$E$90,$B25,WBS!$O$5:$O$90,"<>제외",WBS!$O$5:$O$90,"<>보류") | F25: =IF(D25=0,0,E25/D25)
B26: 수집 (S2–S3) | C26: =COUNTIFS(WBS!$B$5:$B$90,"작업",WBS!$E$5:$E$90,$B26,WBS!$O$5:$O$90,"<>제외",WBS!$O$5:$O$90,"<>보류") | D26: =SUMIFS(WBS!$F$5:$F$90,WBS!$B$5:$B$90,"작업",WBS!$E$5:$E$90,$B26,WBS!$O$5:$O$90,"<>제외",WBS!$O$5:$O$90,"<>보류") | E26: =SUMIFS(WBS!$Q$5:$Q$90,WBS!$B$5:$B$90,"작업",WBS!$E$5:$E$90,$B26,WBS!$O$5:$O$90,"<>제외",WBS!$O$5:$O$90,"<>보류") | F26: =IF(D26=0,0,E26/D26)
B27: 계획 (S2–S3, S5) | C27: =COUNTIFS(WBS!$B$5:$B$90,"작업",WBS!$E$5:$E$90,$B27,WBS!$O$5:$O$90,"<>제외",WBS!$O$5:$O$90,"<>보류") | D27: =SUMIFS(WBS!$F$5:$F$90,WBS!$B$5:$B$90,"작업",WBS!$E$5:$E$90,$B27,WBS!$O$5:$O$90,"<>제외",WBS!$O$5:$O$90,"<>보류") | E27: =SUMIFS(WBS!$Q$5:$Q$90,WBS!$B$5:$B$90,"작업",WBS!$E$5:$E$90,$B27,WBS!$O$5:$O$90,"<>제외",WBS!$O$5:$O$90,"<>보류") | F27: =IF(D27=0,0,E27/D27)
B28: 검지 (S3–S5) | C28: =COUNTIFS(WBS!$B$5:$B$90,"작업",WBS!$E$5:$E$90,$B28,WBS!$O$5:$O$90,"<>제외",WBS!$O$5:$O$90,"<>보류") | D28: =SUMIFS(WBS!$F$5:$F$90,WBS!$B$5:$B$90,"작업",WBS!$E$5:$E$90,$B28,WBS!$O$5:$O$90,"<>제외",WBS!$O$5:$O$90,"<>보류") | E28: =SUMIFS(WBS!$Q$5:$Q$90,WBS!$B$5:$B$90,"작업",WBS!$E$5:$E$90,$B28,WBS!$O$5:$O$90,"<>제외",WBS!$O$5:$O$90,"<>보류") | F28: =IF(D28=0,0,E28/D28)
B29: 관제 (S4–S6) | C29: =COUNTIFS(WBS!$B$5:$B$90,"작업",WBS!$E$5:$E$90,$B29,WBS!$O$5:$O$90,"<>제외",WBS!$O$5:$O$90,"<>보류") | D29: =SUMIFS(WBS!$F$5:$F$90,WBS!$B$5:$B$90,"작업",WBS!$E$5:$E$90,$B29,WBS!$O$5:$O$90,"<>제외",WBS!$O$5:$O$90,"<>보류") | E29: =SUMIFS(WBS!$Q$5:$Q$90,WBS!$B$5:$B$90,"작업",WBS!$E$5:$E$90,$B29,WBS!$O$5:$O$90,"<>제외",WBS!$O$5:$O$90,"<>보류") | F29: =IF(D29=0,0,E29/D29)
B30: 통제 (S5–S6) | C30: =COUNTIFS(WBS!$B$5:$B$90,"작업",WBS!$E$5:$E$90,$B30,WBS!$O$5:$O$90,"<>제외",WBS!$O$5:$O$90,"<>보류") | D30: =SUMIFS(WBS!$F$5:$F$90,WBS!$B$5:$B$90,"작업",WBS!$E$5:$E$90,$B30,WBS!$O$5:$O$90,"<>제외",WBS!$O$5:$O$90,"<>보류") | E30: =SUMIFS(WBS!$Q$5:$Q$90,WBS!$B$5:$B$90,"작업",WBS!$E$5:$E$90,$B30,WBS!$O$5:$O$90,"<>제외",WBS!$O$5:$O$90,"<>보류") | F30: =IF(D30=0,0,E30/D30)
B31: 통계 (S5–S6) | C31: =COUNTIFS(WBS!$B$5:$B$90,"작업",WBS!$E$5:$E$90,$B31,WBS!$O$5:$O$90,"<>제외",WBS!$O$5:$O$90,"<>보류") | D31: =SUMIFS(WBS!$F$5:$F$90,WBS!$B$5:$B$90,"작업",WBS!$E$5:$E$90,$B31,WBS!$O$5:$O$90,"<>제외",WBS!$O$5:$O$90,"<>보류") | E31: =SUMIFS(WBS!$Q$5:$Q$90,WBS!$B$5:$B$90,"작업",WBS!$E$5:$E$90,$B31,WBS!$O$5:$O$90,"<>제외",WBS!$O$5:$O$90,"<>보류") | F31: =IF(D31=0,0,E31/D31)
B32: 계정·설정 (S2, S4–S5) | C32: =COUNTIFS(WBS!$B$5:$B$90,"작업",WBS!$E$5:$E$90,$B32,WBS!$O$5:$O$90,"<>제외",WBS!$O$5:$O$90,"<>보류") | D32: =SUMIFS(WBS!$F$5:$F$90,WBS!$B$5:$B$90,"작업",WBS!$E$5:$E$90,$B32,WBS!$O$5:$O$90,"<>제외",WBS!$O$5:$O$90,"<>보류") | E32: =SUMIFS(WBS!$Q$5:$Q$90,WBS!$B$5:$B$90,"작업",WBS!$E$5:$E$90,$B32,WBS!$O$5:$O$90,"<>제외",WBS!$O$5:$O$90,"<>보류") | F32: =IF(D32=0,0,E32/D32)
B34: 주차별 인일 부하 (기간에 균등 배분)
B35: 주차 | C35: 계획 인일 | D35: 팀 가용 | E35: 여유 | F35: 판정
B36: 1 | C36: =SUMPRODUCT((WBS!$B$5:$B$90="작업")*(WBS!$O$5:$O$90<>"제외")*(WBS!$O$5:$O$90<>"보류")*(WBS!$G$5:$G$90<=$B36)*(WBS!$H$5:$H$90>=$B36)*WBS!$F$5:$F$90/(WBS!$H$5:$H$90-WBS!$G$5:$G$90+1)) | D36: 4 | E36: =D36-C36 | F36: =IF(C36>D36,"초과",IF(C36>D36*0.85,"빡빡","여유"))
B37: 2 | C37: =SUMPRODUCT((WBS!$B$5:$B$90="작업")*(WBS!$O$5:$O$90<>"제외")*(WBS!$O$5:$O$90<>"보류")*(WBS!$G$5:$G$90<=$B37)*(WBS!$H$5:$H$90>=$B37)*WBS!$F$5:$F$90/(WBS!$H$5:$H$90-WBS!$G$5:$G$90+1)) | D37: 4 | E37: =D37-C37 | F37: =IF(C37>D37,"초과",IF(C37>D37*0.85,"빡빡","여유"))
B38: 3 | C38: =SUMPRODUCT((WBS!$B$5:$B$90="작업")*(WBS!$O$5:$O$90<>"제외")*(WBS!$O$5:$O$90<>"보류")*(WBS!$G$5:$G$90<=$B38)*(WBS!$H$5:$H$90>=$B38)*WBS!$F$5:$F$90/(WBS!$H$5:$H$90-WBS!$G$5:$G$90+1)) | D38: 4 | E38: =D38-C38 | F38: =IF(C38>D38,"초과",IF(C38>D38*0.85,"빡빡","여유"))
B39: 4 | C39: =SUMPRODUCT((WBS!$B$5:$B$90="작업")*(WBS!$O$5:$O$90<>"제외")*(WBS!$O$5:$O$90<>"보류")*(WBS!$G$5:$G$90<=$B39)*(WBS!$H$5:$H$90>=$B39)*WBS!$F$5:$F$90/(WBS!$H$5:$H$90-WBS!$G$5:$G$90+1)) | D39: 4 | E39: =D39-C39 | F39: =IF(C39>D39,"초과",IF(C39>D39*0.85,"빡빡","여유"))
B40: 5 | C40: =SUMPRODUCT((WBS!$B$5:$B$90="작업")*(WBS!$O$5:$O$90<>"제외")*(WBS!$O$5:$O$90<>"보류")*(WBS!$G$5:$G$90<=$B40)*(WBS!$H$5:$H$90>=$B40)*WBS!$F$5:$F$90/(WBS!$H$5:$H$90-WBS!$G$5:$G$90+1)) | D40: 4 | E40: =D40-C40 | F40: =IF(C40>D40,"초과",IF(C40>D40*0.85,"빡빡","여유"))
B41: 6 | C41: =SUMPRODUCT((WBS!$B$5:$B$90="작업")*(WBS!$O$5:$O$90<>"제외")*(WBS!$O$5:$O$90<>"보류")*(WBS!$G$5:$G$90<=$B41)*(WBS!$H$5:$H$90>=$B41)*WBS!$F$5:$F$90/(WBS!$H$5:$H$90-WBS!$G$5:$G$90+1)) | D41: 6 | E41: =D41-C41 | F41: =IF(C41>D41,"초과",IF(C41>D41*0.85,"빡빡","여유"))
B42: 7 | C42: =SUMPRODUCT((WBS!$B$5:$B$90="작업")*(WBS!$O$5:$O$90<>"제외")*(WBS!$O$5:$O$90<>"보류")*(WBS!$G$5:$G$90<=$B42)*(WBS!$H$5:$H$90>=$B42)*WBS!$F$5:$F$90/(WBS!$H$5:$H$90-WBS!$G$5:$G$90+1)) | D42: 6 | E42: =D42-C42 | F42: =IF(C42>D42,"초과",IF(C42>D42*0.85,"빡빡","여유"))
B43: 8 | C43: =SUMPRODUCT((WBS!$B$5:$B$90="작업")*(WBS!$O$5:$O$90<>"제외")*(WBS!$O$5:$O$90<>"보류")*(WBS!$G$5:$G$90<=$B43)*(WBS!$H$5:$H$90>=$B43)*WBS!$F$5:$F$90/(WBS!$H$5:$H$90-WBS!$G$5:$G$90+1)) | D43: 6 | E43: =D43-C43 | F43: =IF(C43>D43,"초과",IF(C43>D43*0.85,"빡빡","여유"))
B44: 9 | C44: =SUMPRODUCT((WBS!$B$5:$B$90="작업")*(WBS!$O$5:$O$90<>"제외")*(WBS!$O$5:$O$90<>"보류")*(WBS!$G$5:$G$90<=$B44)*(WBS!$H$5:$H$90>=$B44)*WBS!$F$5:$F$90/(WBS!$H$5:$H$90-WBS!$G$5:$G$90+1)) | D44: 6 | E44: =D44-C44 | F44: =IF(C44>D44,"초과",IF(C44>D44*0.85,"빡빡","여유"))
B45: 10 | C45: =SUMPRODUCT((WBS!$B$5:$B$90="작업")*(WBS!$O$5:$O$90<>"제외")*(WBS!$O$5:$O$90<>"보류")*(WBS!$G$5:$G$90<=$B45)*(WBS!$H$5:$H$90>=$B45)*WBS!$F$5:$F$90/(WBS!$H$5:$H$90-WBS!$G$5:$G$90+1)) | D45: 6 | E45: =D45-C45 | F45: =IF(C45>D45,"초과",IF(C45>D45*0.85,"빡빡","여유"))
...

Sheet 표지
B2: 작업분류체계 (WBS)
B3: 실시간 교통신호 상태정보 오류검지 시스템 · Signal Guard · 15주 MVP
B5: 문서 정보
B6: 문서명 | C6: 실시간 교통신호 상태정보 오류검지 시스템 작업분류체계
B7: 프로젝트 | C7: Signal Guard (수업 프로젝트 · 15주 · 2인)
B8: 버전 / 작성일 | C8: 1.1 / 2026-09-12
B9: 작성 | C9: 조찬희 (기획·프론트엔드·PM), 기경현 (백엔드·데이터)
B10: 근거 문서 | C10: 백로그WBS.md v1.0 4장, 프로젝트정의서.md 12장, 요구사항정의서.md
B11: 범위 | C11: 6단계 / 활동 8개 / 작업패키지 72개 (확정 68 · 보류 2 · 제외 2)
B12: v1.1 변경 | C12: 주간 가용량을 넘지 않도록 인일 재추정 + 기간 분산 — 초과 10주 해소
B13: 기준값 (노란 칸만 고치면 날짜·간트·현재 주차가 따라갑니다)
B14: 기준일 | C14: 46277
B15: 1주차 시작일 | C15: 46266
B16: 현재 주차 | C16: =MAX(1,MIN(15,INT((C14-C15)/7)+1))
B17: 확정 계획 인일 / 팀 가용 | C17: =TEXT(요약!D14,"0.0")&"인일 / "&TEXT(SUM(요약!D36:D50),"0.0")&"인일 가용"
B18: 획득 인일 / 진척률 | C18: =TEXT(요약!E14,"0.0")&"인일 · "&TEXT(요약!F14,"0%")
B20: 시트 구성
B21: WBS | C21: 본체. 단계 → 활동 → 작업패키지 3계층. 상태·진행률만 입력하면 나머지는 수식.
B22: 간트 | C22: 15주 주차별 막대. WBS를 그대로 참조하므로 따로 고칠 것이 없습니다.
B23: 요약 | C23: 단계별·담당별·주차별 인일 집계와 차트, 마일스톤, 검증 결과.
B24: 표지 | C24: 문서 정보와 기준값. 1주차 시작일을 바꾸면 전체 날짜가 이동합니다.
B26: WBS 작성 규칙
B27: ① 100% 규칙 — 상위 단계의 인일은 하위 작업패키지 합계와 정확히 같다 (요약 시트에서 자동 검증).
B28: ② 최하위 단위는 작업패키지(Work Package)다. 0.5~2.5인일로 쪼개 한 주 안에 끝낼 수 있게 한다.
B29: ③ 작업패키지는 산출물 하나로 완료를 확인한다. 완료 판정은 백로그WBS.md 2.4 DoD를 따른다.
B30: ④ 구현 작업패키지는 제품 백로그(US/EN) 한 건과 연결한다 — 추적은 '관련 백로그' 열.
B31: ⑤ 인일은 수업일 기준. 분석·설계·테스트·안정화 주 4인일, 구현 주 6인일이 팀 가용량이다.
B32: ⑥ 제외(Could)·보류(Should) 항목은 확정 계획 합계와 주차별 부하에서 빠진다 — 여유 주에만 넣는다.
B33: ⑦ 어느 주도 팀 가용량을 넘지 않게 기간을 쪼갠다. v1.1에서 인일을 재추정하고 초과 10주를 해소했다.
B34: 상태 값 (WBS 시트 드롭다운)
B35: 완료 | C35: 산출물이 저장소에 있고 DoD를 만족. 진행률 100%.
B36: 진행중 | C36: 이번 주 작업 중. 진행률(0~100%)을 같이 적는다.
B37: 대기 | C37: 선행이 끝나지 않았거나 아직 착수 전.
B38: 보류 | C38: Should·조건부. 승인이나 여유 주가 생기면 대기로 바꾼다.
B39: 제외 | C39: Could 또는 범위 커트. 계획·진척 분모에서 빠진다.
B41: 주간 리뷰 절차: WBS 시트의 상태·진행률 두 열만 고친다 → 요약 시트의 단계별 진척과 주차별 부하가 갱신된다 → 초과(빨간 칸)가 보이면 백로그WBS.md 3.5 커트 순서를 적용한다.
